Workbook

Sheet Assumptions
A1: SPACEX MODEL — ASSUMPTIONS
A2: All inputs blue text. One source of truth.
A4: ═══ ALLOCATOR IN ═══
A6: Section I — From Central Allocator Module | B6: Placeholders pending live links. | C6: All values blue text.
A7: Parameter | B7: 2025 | C7: 2026 | D7: 2027 | E7: 2028 | F7: 2029 | G7: 2030 | H7: 2031 | I7: 2032 | J7: 2033 | K7: 2034 | L7: 2035 | M7: 2036 | N7: 2037 | O7: 2038 | P7: 2039 | Q7: 2040 | R7: 2041 | S7: 2042 | T7: 2043 | U7: 2044 | V7: 2045 | W7: 2046 | X7: 2047 | Y7: 2048 | Z7: 2049 | AA7: 2050
A8: Total Starlink Allocation ($mm) | B8: 10360 | C8: 15000 | D8: 15000 | E8: 20000 | F8: 60000 | G8: 75000 | H8: 90000 | I8: 105000 | J8: 120000 | K8: 120000 | L8: 120000 | M8: 120000 | N8: 120000 | O8: 120000 | P8: 120000 | Q8: 120000 | R8: 120000 | S8: 120000 | T8: 120000 | U8: 120000 | V8: 120000 | W8: 120000 | X8: 120000 | Y8: 120000 | Z8: 120000 | AA8: 120000
D11: 2025 | E11: 2026 | F11: 2027 | G11: 2028 | H11: 2029 | I11: 2030 | J11: 2031 | K11: 2032 | L11: 2033 | M11: 2034 | N11: 2035 | O11: 2036 | P11: 2037 | Q11: 2038 | R11: 2039 | S11: 2040 | T11: 2041 | U11: 2042 | V11: 2043 | W11: 2044 | X11: 2045 | Y11: 2046 | Z11: 2047 | AA11: 2048 | AB11: 2049 | AC11: 2050
C12: 2026 | D12: 2027 | E12: 2028 | F12: 2029 | G12: 2030 | H12: 2031 | I12: 2032 | J12: 2033 | K12: 2034 | L12: 2035 | M12: 2036 | N12: 2037 | O12: 2038 | P12: 2039 | Q12: 2040 | R12: 2041 | S12: 2042 | T12: 2043 | U12: 2044 | V12: 2045 | W12: 2046 | X12: 2047 | Y12: 2048 | Z12: 2049 | AA12: 2050
C13: =Starlink!E212 -> 5 | D13: =Starlink!F212 -> 5 | E13: =Starlink!G212 -> 5 | F13: =Starlink!H212 -> 5 | G13: =Starlink!I212 -> 5 | H13: =Starlink!J212 -> 5 | I13: =Starlink!K212 -> 5 | J13: =Starlink!L212 -> 5 | ... AA13: =Starlink!AC212 -> 5
C14: =Starlink!E213 -> 83.452381 | D14: =Starlink!F213 -> 78.90365 | E14: =Starlink!G213 -> 72.854036 | F14: =Starlink!H213 -> 63.267853 | G14: =Starlink!I213 -> 47.22347 | H14: =Starlink!J213 -> 45.7846 | I14: =Starlink!K213 -> 41.693873 | J14: =Starlink!L213 -> 41.979841 | ... AA14: =Starlink!AC213 -> 137.71368
C15: =Starlink!E214 -> 0 | D15: =Starlink!F214 -> 0 | E15: =Starlink!G214 -> 0 | F15: =Starlink!H214 -> 0 | G15: =Starlink!I214 -> 0 | H15: =Starlink!J214 -> 0 | I15: =Starlink!K214 -> 0 | J15: =Starlink!L214 -> 0 | ... AA15: =Starlink!AC214 -> 0
C16: =Starlink!E215 -> 1.7854563 | D16: =Starlink!F215 -> 1.9222834 | E16: =Starlink!G215 -> 2.0657765 | F16: =Starlink!H215 -> -1 | G16: =Starlink!I215 -> -1 | H16: =Starlink!J215 -> -1 | I16: =Starlink!K215 -> -1 | J16: =Starlink!L215 -> -1 | ... AA16: =Starlink!AC215 -> -1
C17: =Starlink!E209 -> 1409.7394 | D17: =Starlink!F209 -> 1212.4176 | E17: =Starlink!G209 -> 1166.8041 | F17: =Starlink!H209 -> 1135.9029 | G17: =Starlink!I209 -> 1112.0746 | H17: =Starlink!J209 -> 1098.9828 | I17: =Starlink!K209 -> 1102.9602 | J17: =Starlink!L209 -> 1115.1582 | ... AA17: =Starlink!AC209 -> 9856.3689
C18: =Starlink!E210 -> 1404.3658 | D18: =Starlink!F210 -> 1264.8119 | E18: =Starlink!G210 -> 1239.6847 | F18: =Starlink!H210 -> 1158.8573 | G18: =Starlink!I210 -> 1128.4935 | H18: =Starlink!J210 -> 1110.0588 | I18: =Starlink!K210 -> 1105.6945 | J18: =Starlink!L210 -> 1110.3056 | ... AA18: =Starlink!AC210 -> 9856.3689
C19: =Starlink!E211 -> 10000000 | D19: =Starlink!F211 -> 10000000 | E19: =Starlink!G211 -> 10000000 | F19: =Starlink!H211 -> 10000000 | G19: =Starlink!I211 -> 10000000 | H19: =Starlink!J211 -> 10000000 | I19: =Starlink!K211 -> 10000000 | J19: =Starlink!L211 -> 10000000 | ... AA19: =Starlink!AC211 -> 10000000
C20: =Starlink!E203 -> 8644.6203 | D20: =Starlink!F203 -> 8679.9282 | E20: =Starlink!G203 -> 9262.2478 | F20: =Starlink!H203 -> 10062.166 | G20: =Starlink!I203 -> 9215.8283 | H20: =Starlink!J203 -> 9410.2408 | I20: =Starlink!K203 -> 9736.0823 | J20: =Starlink!L203 -> 10103.842 | ... AA20: =Starlink!AC203 -> 51648.21
C21: =Starlink!E204 -> 0.78919331 | D21: =Starlink!F204 -> 0.76745194 | E21: =Starlink!G204 -> 0.7683031 | F21: =Starlink!H204 -> 0.78034255 | G21: =Starlink!I204 -> 0.84908134 | H21: =Starlink!J204 -> 0.81061709 | I21: =Starlink!K204 -> 0.81526255 | J21: =Starlink!L204 -> 0.81793572 | ... AA21: =Starlink!AC204 -> 0.86749494
A23: ═══ MODULE ASSUMPTIONS ═══
A24: Section B — Satellite Specifications
A25: Parameter | B25: Base Case | C25: Min | D25: Max | E25: Note
A26: V2 Mini Mass (kg) | B26: 575 | C26: 575 | D26: 575 | E26: Fixed — no meaningful variance. Source: SpaceX 2024 Progress Report
A27: V3 Mass (kg) | B27: 2000 | C27: 1800 | D27: 2200 | E27: Source: SpaceX 2024 Progress Report
A28: V2 Mini Bandwidth per Sat — BB (Gbps) | B28: 96 | C28: 96 | D28: 96 | E28: Fixed V2 Mini broadband bandwidth. Source: SpaceX 2024 Progress Report
A29: V2 Mini Bandwidth per Sat — DTC (Gbps) | B29: 0.2 | C29: 2 | D29: 4.5 | E29: From DTC Coverage Gap model — constrained by smartphone radio link budget
A30: V3 Bandwidth per Sat — BB base year (Gbps) | B30: 1000 | C30: 1000 | D30: 1000 | E30: Base year 2025; improves via Wright's Law. Source: SpaceX 2024 Progress Report
A31: V3 Bandwidth per Sat — DTC (Gbps) | B31: 2.75 | C31: 1 | D31: 5 | E31: Placeholder — update from DTC Coverage Gap model when V3 DTC specs available
A32: Satellite Useful Life — V2 Mini (Years) | B32: 5 | C32: 4 | D32: 6 | E32: Source: SpaceX constellation operations data
A33: Satellite Useful Life — V3 (Years) | B33: 5 | C33: 4 | D33: 7 | E33: V3 may have longer life — upper range extended
A34: Capex Lag (Years) | B34: 1 | C34: 1 | D34: 1 | E34: Budget deployed in Year N activates satellites in Year N+1. Fixed at 1 year.
A36: Section C — Wright's Law Parameters
A37: Parameter | B37: Base Case | C37: Min | D37: Max | E37: Note
A38: Satellite Cost per kg — base year ($/kg) | B38: 650 | C38: 600 | D38: 750 | E38: SpaceX 2024 baseline
A39: Satellite Cost per kg — learning rate | B39: 0.05 | C39: 0.07 | D39: 0.17 | E39: 12% reduction per cumulative doubling
A40: V3 Bandwidth per Sat — learning rate | B40: 0.05 | C40: 0.07 | D40: 0.17 | E40: 12% improvement per cumulative doubling
A41: Cumulative sats at base year | B41: 7486 | C41: 7486 | D41: 7486 | E41: From historical constellation data
A42: Satellite Cost floor ($/kg) | B42: 400 | C42: 300 | D42: 500
A43: V3 Bandwidth cap (Gbps) | B43: 5000 | C43: 3000 | D43: 7000
A44: V2 Mini Cost per kg — base year ($/kg) | B44: 650 | C44: 600 | D44: 750 | E44: Same baseline as V3. Source: SpaceX 2024
A45: V2 Mini Cost per kg — learning rate | B45: 0.05 | C45: 0.03 | D45: 0.1 | E45: Shared manufacturing learning curve with V3
A46: V2 Mini Cost floor ($/kg) | B46: 400 | C46: 300 | D46: 500 | E46: Same floor as V3
...

Sheet Allocator
A1: CENTRAL ALLOCATOR
A2: Three-layer engine: capital / Starship capacity / cash sweep
A4: Year | D4: 2025 | E4: 2026 | F4: 2027 | G4: 2028 | H4: 2029 | I4: 2030 | J4: 2031 | K4: 2032 | L4: 2033 | M4: 2034 | N4: 2035 | O4: 2036 | P4: 2037 | Q4: 2038 | R4: 2039 | S4: 2040 | T4: 2041 | U4: 2042 | V4: 2043 | W4: 2044 | X4: 2045 | Y4: 2046 | Z4: 2047 | AA4: 2048 | AB4: 2049 | AC4: 2050
A6: LAYER 1 — CAPITAL ALLOCATION
A8: [Legacy R8 — was hardcoded capital pool ramp; superseded by R117 BoY tracker]
A10: ▸ Outputs: Capital allocation per module ($mm)
A11: Launch | D11: =MIN(D128,D$117*D161) -> 240 | E11: =MIN(E128,E$117*E161) -> 236.45318 | F11: =MIN(F128,F$117*F161) -> 238.63025 | G11: =MIN(G128,G$117*G161) -> 208.55973 | H11: =MIN(H128,H$117*H161) -> 178.41674 | I11: =MIN(I128,I$117*I161) -> 148.88105 | J11: =MIN(J128,J$117*J161) -> 119.11335 | K11: =MIN(K128,K$117*K161) -> 89.619636 | ... AC11: =MIN(AC128,AC$117*AC161) -> 0.12138466
A12: Starlink | C12: V9 baseline hardcode — Total Starlink Allocation from Assumptions!B8:J8, held flat 2034+. Replaced by live Allocator output in Sprint 7. | D12: =MIN(D129,D$117*D162) -> 5060.5888 | E12: =MIN(E129,E$117*E162) -> 5517.4058 | F12: =MIN(F129,F$117*F162) -> 28516.757 | G12: =MIN(G129,G$117*G162) -> 28614.113 | H12: =MIN(H129,H$117*H162) -> 30063.004 | I12: =MIN(I129,I$117*I162) -> 27275.694 | J12: =MIN(J129,J$117*J162) -> 29960.392 | K12: =MIN(K129,K$117*K162) -> 31175.135 | ... AC12: =MIN(AC129,AC$117*AC162) -> 100000
A13: ODC | D13: =MIN(D130,D$117*D163) -> 0 | E13: =MIN(E130,E$117*E163) -> 0 | F13: =MIN(F130,F$117*F163) -> 0 | G13: =MIN(G130,G$117*G163) -> 0 | H13: =MIN(H130,H$117*H163) -> 0 | I13: =MIN(I130,I$117*I163) -> 0 | J13: =MIN(J130,J$117*J163) -> 0 | K13: =MIN(K130,K$117*K163) -> 0 | ... AC13: =MIN(AC130,AC$117*AC163) -> 0
A14: AI Stack | D14: =MIN(D131,D$117*D164) -> 0 | E14: =MIN(E131,E$117*E164) -> 0 | F14: =MIN(F131,F$117*F164) -> 0 | G14: =MIN(G131,G$117*G164) -> 0 | H14: =MIN(H131,H$117*H164) -> 0 | I14: =MIN(I131,I$117*I164) -> 0 | J14: =MIN(J131,J$117*J164) -> 0 | K14: =MIN(K131,K$117*K164) -> 0 | ... AC14: =MIN(AC131,AC$117*AC164) -> 0
A15: Lunar / Mars | D15: 0 | E15: 0 | F15: 0 | G15: 0 | H15: 0 | I15: 0 | J15: 0 | K15: 0 | L15: 0 | M15: 0 | N15: 0 | O15: 0 | P15: 0 | Q15: 0 | R15: 0 | S15: 0 | T15: 0 | U15: 0 | V15: 0 | W15: 0 | X15: 0 | Y15: 0 | Z15: 0 | AA15: 0 | AB15: 0 | AC15: 0
A16: Total allocated | D16: =SUM(D11:D15) -> 5300.5888 | E16: =SUM(E11:E15) -> 5753.859 | F16: =SUM(F11:F15) -> 28755.387 | G16: =SUM(G11:G15) -> 28822.673 | H16: =SUM(H11:H15) -> 30241.421 | I16: =SUM(I11:I15) -> 27424.575 | J16: =SUM(J11:J15) -> 30079.505 | K16: =SUM(K11:K15) -> 31264.755 | ... AC16: =SUM(AC11:AC15) -> 100000.12
A17: [Spec 09: sigmoid bounds queue at gate by construction; residual diagnostic only — Patch L second-term retired] | D17: =MAX(0, D117 - D16) -> 585.59866 | E17: =MAX(0, E117 - E16) -> 642.8614 | F17: =MAX(0, F117 - F16) -> 10843.263 | G17: =MAX(0, G117 - G16) -> 17403.54 | H17: =MAX(0, H117 - H16) -> 25142.047 | I17: =MAX(0, I117 - I16) -> 38345.228 | J17: =MAX(0, J117 - J16) -> 45646.356 | K17: =MAX(0, K117 - K16) -> 55002.324 | ... AC17: =MAX(0, AC117 - AC16) -> 220286.84
A19: ▸ Helper: Floor allocations ($mm) — Pass 1
A20: Launch floor
A21: Starlink floor
A22: ODC floor
A23: AI Stack floor
A24: Total floor allocated
A25: Remainder pool ($mm)
A26: Floor pro-rate scalar (≤1; <1 if floors > pool)
A27: ▸ Helper: Effective IRR for sigmoid (prior-year, floored at 0, masked)
A28: Launch effective IRR
A29: Starlink effective IRR
A30: ODC effective IRR
... A39: ▸ Inputs read: per-module Blended IRR
A40: Launch Blended IRR | D40: =INDEX('Customer Launch'!D:D,MATCH("Blended IRR",'Customer Launch'!$A:$A,0)) -> 2.2846788 | E40: =INDEX('Customer Launch'!E:E,MATCH("Blended IRR",'Customer Launch'!$A:$A,0)) -> 2.5252453 | F40: =INDEX('Customer Launch'!F:F,MATCH("Blended IRR",'Customer Launch'!$A:$A,0)) -> 4.1886093 | G40: =INDEX('Customer Launch'!G:G,MATCH("Blended IRR",'Customer Launch'!$A:$A,0)) -> 5.5958579 | H40: =INDEX('Customer Launch'!H:H,MATCH("Blended IRR",'Customer Launch'!$A:$A,0)) -> 6.9897191 | I40: =INDEX('Customer Launch'!I:I,MATCH("Blended IRR",'Customer Launch'!$A:$A,0)) -> 9.5937922 | J40: =INDEX('Customer Launch'!J:J,MATCH("Blended IRR",'Customer Launch'!$A:$A,0)) -> 10.603868 | K40: =INDEX('Customer Launch'!K:K,MATCH("Blended IRR",'Customer Launch'!$A:$A,0)) -> 12.082096 | L40: =INDEX('Customer Launch'!L:L,MATCH("Blended IRR",'Customer Launch'!$A:$A,0)) -> 13.037917 | M40: =INDEX('Customer Launch'!M:M,MATCH("Blended IRR",'Customer Launch'!$A:$A,0)) -> 13.10238 | N40: =INDEX('Customer Launch'!N:N,MATCH("Blended IRR",'Customer Launch'!$A:$A,0)) -> 13.151414 | O40: =INDEX('Customer Launch'!O:O,MATCH("Blended IRR",'Customer Launch'!$A:$A,0)) -> 12.75675 | P40: =INDEX('Customer Launch'!P:P,MATCH("Blended IRR",'Customer Launch'!$A:$A,0)) -> 12.297593 | Q40: =INDEX('Customer Launch'!Q:Q,MATCH("Blended IRR",'Customer Launch'!$A:$A,0)) -> 11.793723 | R40: =INDEX('Customer Launch'!R:R,MATCH("Blended IRR",'Customer Launch'!$A:$A,0)) -> 11.261072 | S40: =INDEX('Customer Launch'!S:S,MATCH("Blended IRR",'Customer Launch'!$A:$A,0)) -> 10.712369 | T40: =INDEX('Customer Launch'!T:T,MATCH("Blended IRR",'Customer Launch'!$A:$A,0)) -> 10.157698 | U40: =INDEX('Customer Launch'!U:U,MATCH("Blended IRR",'Customer Launch'!$A:$A,0)) -> 9.6049632 | V40: =INDEX('Customer Launch'!V:V,MATCH("Blended IRR",'Customer Launch'!$A:$A,0)) -> 9.0602807 | W40: =INDEX('Customer Launch'!W:W,MATCH("Blended IRR",'Customer Launch'!$A:$A,0)) -> 8.5283083 | X40: =INDEX('Customer Launch'!X:X,MATCH("Blended IRR",'Customer Launch'!$A:$A,0)) -> 8.0125157 | Y40: =INDEX('Customer Launch'!Y:Y,MATCH("Blended IRR",'Customer Launch'!$A:$A,0)) -> 7.5154103 | Z40: =INDEX('Customer Launch'!Z:Z,MATCH("Blended IRR",'Customer Launch'!$A:$A,0)) -> 7.0387224 | AA40: =INDEX('Customer Launch'!AA:AA,MATCH("Blended IRR",'Customer Launch'!$A:$A,0)) -> 6.5835594 | AB40: =INDEX('Customer Launch'!AB:AB,MATCH("Blended IRR",'Customer Launch'!$A:$A,0)) -> 2.0261287 | AC40: =INDEX('Customer Launch'!AC:AC,MATCH("Blended IRR",'Customer Launch'!$A:$A,0)) -> 1.8934966
A41: Starlink Blended IRR | D41: =INDEX(Starlink!D:D,MATCH("Aggregate Blended IRR for Allocator (market-mix-weighted vehicle-level)",Starlink!$A:$A,0)) -> 5.656414 | E41: =INDEX(Starlink!E:E,MATCH("Aggregate Blended IRR for Allocator (market-mix-weighted vehicle-level)",Starlink!$A:$A,0)) -> 6.3255587 | F41: =INDEX(Starlink!F:F,MATCH("Aggregate Blended IRR for Allocator (market-mix-weighted vehicle-level)",Starlink!$A:$A,0)) -> 6.7191285 | G41: =INDEX(Starlink!G:G,MATCH("Aggregate Blended IRR for Allocator (market-mix-weighted vehicle-level)",Starlink!$A:$A,0)) -> 7.1326555 | H41: =INDEX(Starlink!H:H,MATCH("Aggregate Blended IRR for Allocator (market-mix-weighted vehicle-level)",Starlink!$A:$A,0)) -> 7.6162306 | I41: =INDEX(Starlink!I:I,MATCH("Aggregate Blended IRR for Allocator (market-mix-weighted vehicle-level)",Starlink!$A:$A,0)) -> 8.0757167 | J41: =INDEX(Starlink!J:J,MATCH("Aggregate Blended IRR for Allocator (market-mix-weighted vehicle-level)",Starlink!$A:$A,0)) -> 8.5796406 | K41: =INDEX(Starlink!K:K,MATCH("Aggregate Blended IRR for Allocator (market-mix-weighted vehicle-level)",Starlink!$A:$A,0)) -> 9.0887138 | L41: =INDEX(Starlink!L:L,MATCH("Aggregate Blended IRR for Allocator (market-mix-weighted vehicle-level)",Starlink!$A:$A,0)) -> 9.62441 | M41: =INDEX(Starlink!M:M,MATCH("Aggregate Blended IRR for Allocator (market-mix-weighted vehicle-level)",Starlink!$A:$A,0)) -> 10.188468 | N41: =INDEX(Starlink!N:N,MATCH("Aggregate Blended IRR for Allocator (market-mix-weighted vehicle-level)",Starlink!$A:$A,0)) -> 10.782793 | O41: =INDEX(Starlink!O:O,MATCH("Aggregate Blended IRR for Allocator (market-mix-weighted vehicle-level)",Starlink!$A:$A,0)) -> 11.409169 | P41: =INDEX(Starlink!P:P,MATCH("Aggregate Blended IRR for Allocator (market-mix-weighted vehicle-level)",Starlink!$A:$A,0)) -> 11.991885 | Q41: =INDEX(Starlink!Q:Q,MATCH("Aggregate Blended IRR for Allocator (market-mix-weighted vehicle-level)",Starlink!$A:$A,0)) -> 12.684043 | R41: =INDEX(Starlink!R:R,MATCH("Aggregate Blended IRR for Allocator (market-mix-weighted vehicle-level)",Starlink!$A:$A,0)) -> 13.380837 | S41: =INDEX(Starlink!S:S,MATCH("Aggregate Blended IRR for Allocator (market-mix-weighted vehicle-level)",Starlink!$A:$A,0)) -> 14.148853 | T41: =INDEX(Starlink!T:T,MATCH("Aggregate Blended IRR for Allocator (market-mix-weighted vehicle-level)",Starlink!$A:$A,0)) -> 11.308869 | U41: =INDEX(Starlink!U:U,MATCH("Aggregate Blended IRR for Allocator (market-mix-weighted vehicle-level)",Starlink!$A:$A,0)) -> 15.815296 | V41: =INDEX(Starlink!V:V,MATCH("Aggregate Blended IRR for Allocator (market-mix-weighted vehicle-level)",Starlink!$A:$A,0)) -> 16.719556 | W41: =INDEX(Starlink!W:W,MATCH("Aggregate Blended IRR for Allocator (market-mix-weighted vehicle-level)",Starlink!$A:$A,0)) -> 17.674224 | X41: =INDEX(Starlink!X:X,MATCH("Aggregate Blended IRR for Allocator (market-mix-weighted vehicle-level)",Starlink!$A:$A,0)) -> 17.577168 | Y41: =INDEX(Starlink!Y:Y,MATCH("Aggregate Blended IRR for Allocator (market-mix-weighted vehicle-level)",Starlink!$A:$A,0)) -> 18.578387 | Z41: =INDEX(Starlink!Z:Z,MATCH("Aggregate Blended IRR for Allocator (market-mix-weighted vehicle-level)",Starlink!$A:$A,0)) -> 19.160798 | AA41: =INDEX(Starlink!AA:AA,MATCH("Aggregate Blended IRR for Allocator (market-mix-weighted vehicle-level)",Starlink!$A:$A,0)) -> 20.249816 | AB41: =INDEX(Starlink!AB:AB,MATCH("Aggregate Blended IRR for Allocator (market-mix-weighted vehicle-level)",Starlink!$A:$A,0)) -> 5.2449687 | AC41: =INDEX(Starlink!AC:AC,MATCH("Aggregate Blended IRR for Allocator (market-mix-weighted vehicle-level)",Starlink!$A:$A,0)) -> 5.5819986
A42: ODC Blended IRR | D42: =INDEX(ODC!D:D, MATCH("Blended IRR", ODC!$A:$A, 0)) -> 0 | E42: =INDEX(ODC!E:E, MATCH("Blended IRR", ODC!$A:$A, 0)) -> 0 | F42: =INDEX(ODC!F:F, MATCH("Blended IRR", ODC!$A:$A, 0)) -> 0 | G42: =INDEX(ODC!G:G, MATCH("Blended IRR", ODC!$A:$A, 0)) -> 0 | H42: =INDEX(ODC!H:H, MATCH("Blended IRR", ODC!$A:$A, 0)) -> 0 | I42: =INDEX(ODC!I:I, MATCH("Blended IRR", ODC!$A:$A, 0)) -> 0 | J42: =INDEX(ODC!J:J, MATCH("Blended IRR", ODC!$A:$A, 0)) -> 0 | K42: =INDEX(ODC!K:K, MATCH("Blended IRR", ODC!$A:$A, 0)) -> 0 | L42: =INDEX(ODC!L:L, MATCH("Blended IRR", ODC!$A:$A, 0)) -> 0 | M42: =INDEX(ODC!M:M, MATCH("Blended IRR", ODC!$A:$A, 0)) -> 0 | N42: =INDEX(ODC!N:N, MATCH("Blended IRR", ODC!$A:$A, 0)) -> 0 | O42: =INDEX(ODC!O:O, MATCH("Blended IRR", ODC!$A:$A, 0)) -> 0 | P42: =INDEX(ODC!P:P, MATCH("Blended IRR", ODC!$A:$A, 0)) -> 0 | Q42: =INDEX(ODC!Q:Q, MATCH("Blended IRR", ODC!$A:$A, 0)) -> 0 | R42: =INDEX(ODC!R:R, MATCH("Blended IRR", ODC!$A:$A, 0)) -> 0 | S42: =INDEX(ODC!S:S, MATCH("Blended IRR", ODC!$A:$A, 0)) -> 0 | T42: =INDEX(ODC!T:T, MATCH("Blended IRR", ODC!$A:$A, 0)) -> 0 | U42: =INDEX(ODC!U:U, MATCH("Blended IRR", ODC!$A:$A, 0)) -> 0 | V42: =INDEX(ODC!V:V, MATCH("Blended IRR", ODC!$A:$A, 0)) -> 0 | W42: =INDEX(ODC!W:W, MATCH("Blended IRR", ODC!$A:$A, 0)) -> 0 | X42: =INDEX(ODC!X:X, MATCH("Blended IRR", ODC!$A:$A, 0)) -> 0 | Y42: =INDEX(ODC!Y:Y, MATCH("Blended IRR", ODC!$A:$A, 0)) -> 0 | Z42: =INDEX(ODC!Z:Z, MATCH("Blended IRR", ODC!$A:$A, 0)) -> 0 | AA42: =INDEX(ODC!AA:AA, MATCH("Blended IRR", ODC!$A:$A, 0)) -> 0 | AB42: =INDEX(ODC!AB:AB, MATCH("Blended IRR", ODC!$A:$A, 0)) -> 0 | AC42: =INDEX(ODC!AC:AC, MATCH("Blended IRR", ODC!$A:$A, 0)) -> 0
A43: AI Stack Blended IRR | D43: =INDEX('AI Stack'!D:D, MATCH("Blended IRR", 'AI Stack'!$A:$A, 0)) -> 0 | E43: =INDEX('AI Stack'!E:E, MATCH("Blended IRR", 'AI Stack'!$A:$A, 0)) -> 0 | F43: =INDEX('AI Stack'!F:F, MATCH("Blended IRR", 'AI Stack'!$A:$A, 0)) -> 0 | G43: =INDEX('AI Stack'!G:G, MATCH("Blended IRR", 'AI Stack'!$A:$A, 0)) -> 0 | H43: =INDEX('AI Stack'!H:H, MATCH("Blended IRR", 'AI Stack'!$A:$A, 0)) -> 0 | I43: =INDEX('AI Stack'!I:I, MATCH("Blended IRR", 'AI Stack'!$A:$A, 0)) -> 0 | J43: =INDEX('AI Stack'!J:J, MATCH("Blended IRR", 'AI Stack'!$A:$A, 0)) -> 0 | K43: =INDEX('AI Stack'!K:K, MATCH("Blended IRR", 'AI Stack'!$A:$A, 0)) -> 0 | L43: =INDEX('AI Stack'!L:L, MATCH("Blended IRR", 'AI Stack'!$A:$A, 0)) -> 0 | M43: =INDEX('AI Stack'!M:M, MATCH("Blended IRR", 'AI Stack'!$A:$A, 0)) -> 0 | N43: =INDEX('AI Stack'!N:N, MATCH("Blended IRR", 'AI Stack'!$A:$A, 0)) -> 0 | O43: =INDEX('AI Stack'!O:O, MATCH("Blended IRR", 'AI Stack'!$A:$A, 0)) -> 0 | P43: =INDEX('AI Stack'!P:P, MATCH("Blended IRR", 'AI Stack'!$A:$A, 0)) -> 0 | Q43: =INDEX('AI Stack'!Q:Q, MATCH("Blended IRR", 'AI Stack'!$A:$A, 0)) -> 0 | R43: =INDEX('AI Stack'!R:R, MATCH("Blended IRR", 'AI Stack'!$A:$A, 0)) -> 0 | S43: =INDEX('AI Stack'!S:S, MATCH("Blended IRR", 'AI Stack'!$A:$A, 0)) -> 0 | T43: =INDEX('AI Stack'!T:T, MATCH("Blended IRR", 'AI Stack'!$A:$A, 0)) -> 0 | U43: =INDEX('AI Stack'!U:U, MATCH("Blended IRR", 'AI Stack'!$A:$A, 0)) -> 0 | V43: =INDEX('AI Stack'!V:V, MATCH("Blended IRR", 'AI Stack'!$A:$A, 0)) -> 0 | W43: =INDEX('AI Stack'!W:W, MATCH("Blended IRR", 'AI Stack'!$A:$A, 0)) -> 0 | X43: =INDEX('AI Stack'!X:X, MATCH("Blended IRR", 'AI Stack'!$A:$A, 0)) -> 0 | Y43: =INDEX('AI Stack'!Y:Y, MATCH("Blended IRR", 'AI Stack'!$A:$A, 0)) -> 0 | Z43: =INDEX('AI Stack'!Z:Z, MATCH("Blended IRR", 'AI Stack'!$A:$A, 0)) -> 0 | AA43: =INDEX('AI Stack'!AA:AA, MATCH("Blended IRR", 'AI Stack'!$A:$A, 0)) -> 0 | AB43: =INDEX('AI Stack'!AB:AB, MATCH("Blended IRR", 'AI Stack'!$A:$A, 0)) -> 0 | AC43: =INDEX('AI Stack'!AC:AC, MATCH("Blended IRR", 'AI Stack'!$A:$A, 0)) -> 0
A44: Lunar / Mars Blended IRR | D44: =INDEX('Lunar Mars'!D:D, MATCH("Blended IRR", 'Lunar Mars'!$A:$A, 0)) -> 0 | E44: =INDEX('Lunar Mars'!E:E, MATCH("Blended IRR", 'Lunar Mars'!$A:$A, 0)) -> 0 | F44: =INDEX('Lunar Mars'!F:F, MATCH("Blended IRR", 'Lunar Mars'!$A:$A, 0)) -> 0 | G44: =INDEX('Lunar Mars'!G:G, MATCH("Blended IRR", 'Lunar Mars'!$A:$A, 0)) -> 0 | H44: =INDEX('Lunar Mars'!H:H, MATCH("Blended IRR", 'Lunar Mars'!$A:$A, 0)) -> 0 | I44: =INDEX('Lunar Mars'!I:I, MATCH("Blended IRR", 'Lunar Mars'!$A:$A, 0)) -> 0 | J44: =INDEX('Lunar Mars'!J:J, MATCH("Blended IRR", 'Lunar Mars'!$A:$A, 0)) -> 0 | K44: =INDEX('Lunar Mars'!K:K, MATCH("Blended IRR", 'Lunar Mars'!$A:$A, 0)) -> 0 | L44: =INDEX('Lunar Mars'!L:L, MATCH("Blended IRR", 'Lunar Mars'!$A:$A, 0)) -> 0 | M44: =INDEX('Lunar Mars'!M:M, MATCH("Blended IRR", 'Lunar Mars'!$A:$A, 0)) -> 0 | N44: =INDEX('Lunar Mars'!N:N, MATCH("Blended IRR", 'Lunar Mars'!$A:$A, 0)) -> 0 | O44: =INDEX('Lunar Mars'!O:O, MATCH("Blended IRR", 'Lunar Mars'!$A:$A, 0)) -> 0 | P44: =INDEX('Lunar Mars'!P:P, MATCH("Blended IRR", 'Lunar Mars'!$A:$A, 0)) -> 0 | Q44: =INDEX('Lunar Mars'!Q:Q, MATCH("Blended IRR", 'Lunar Mars'!$A:$A, 0)) -> 0 | R44: =INDEX('Lunar Mars'!R:R, MATCH("Blended IRR", 'Lunar Mars'!$A:$A, 0)) -> 0 | S44: =INDEX('Lunar Mars'!S:S, MATCH("Blended IRR", 'Lunar Mars'!$A:$A, 0)) -> 0 | T44: =INDEX('Lunar Mars'!T:T, MATCH("Blended IRR", 'Lunar Mars'!$A:$A, 0)) -> 0 | U44: =INDEX('Lunar Mars'!U:U, MATCH("Blended IRR", 'Lunar Mars'!$A:$A, 0)) -> 0 | V44: =INDEX('Lunar Mars'!V:V, MATCH("Blended IRR", 'Lunar Mars'!$A:$A, 0)) -> 0 | W44: =INDEX('Lunar Mars'!W:W, MATCH("Blended IRR", 'Lunar Mars'!$A:$A, 0)) -> 0 | X44: =INDEX('Lunar Mars'!X:X, MATCH("Blended IRR", 'Lunar Mars'!$A:$A, 0)) -> 0 | Y44: =INDEX('Lunar Mars'!Y:Y, MATCH("Blended IRR", 'Lunar Mars'!$A:$A, 0)) -> 0 | Z44: =INDEX('Lunar Mars'!Z:Z, MATCH("Blended IRR", 'Lunar Mars'!$A:$A, 0)) -> 0 | AA44: =INDEX('Lunar Mars'!AA:AA, MATCH("Blended IRR", 'Lunar Mars'!$A:$A, 0)) -> 0 | AB44: =INDEX('Lunar Mars'!AB:AB, MATCH("Blended IRR", 'Lunar Mars'!$A:$A, 0)) -> 0 | AC44: =INDEX('Lunar Mars'!AC:AC, MATCH("Blended IRR", 'Lunar Mars'!$A:$A, 0)) -> 0
A46: ▸ Inputs read: per-module Strategic Priority Weight
A47: Launch | D47: =INDEX('Customer Launch'!D:D, MATCH("Strategic Priority Weight (1–5)", 'Customer Launch'!$A:$A, 0)) -> 2 | E47: =INDEX('Customer Launch'!E:E, MATCH("Strategic Priority Weight (1–5)", 'Customer Launch'!$A:$A, 0)) -> 2 | F47: =INDEX('Customer Launch'!F:F, MATCH("Strategic Priority Weight (1–5)", 'Customer Launch'!$A:$A, 0)) -> 2 | G47: =INDEX('Customer Launch'!G:G, MATCH("Strategic Priority Weight (1–5)", 'Customer Launch'!$A:$A, 0)) -> 2 | H47: =INDEX('Customer Launch'!H:H, MATCH("Strategic Priority Weight (1–5)", 'Customer Launch'!$A:$A, 0)) -> 2 | I47: =INDEX('Customer Launch'!I:I, MATCH("Strategic Priority Weight (1–5)", 'Customer Launch'!$A:$A, 0)) -> 2 | J47: =INDEX('Customer Launch'!J:J, MATCH("Strategic Priority Weight (1–5)", 'Customer Launch'!$A:$A, 0)) -> 2 | K47: =INDEX('Customer Launch'!K:K, MATCH("Strategic Priority Weight (1–5)", 'Customer Launch'!$A:$A, 0)) -> 2 | L47: =INDEX('Customer Launch'!L:L, MATCH("Strategic Priority Weight (1–5)", 'Customer Launch'!$A:$A, 0)) -> 2 | M47: =INDEX('Customer Launch'!M:M, MATCH("Strategic Priority Weight (1–5)", 'Customer Launch'!$A:$A, 0)) -> 2 | N47: =INDEX('Customer Launch'!N:N, MATCH("Strategic Priority Weight (1–5)", 'Customer Launch'!$A:$A, 0)) -> 2 | O47: =INDEX('Customer Launch'!O:O, MATCH("Strategic Priority Weight (1–5)", 'Customer Launch'!$A:$A, 0)) -> 2 | P47: =INDEX('Customer Launch'!P:P, MATCH("Strategic Priority Weight (1–5)", 'Customer Launch'!$A:$A, 0)) -> 2 | Q47: =INDEX('Customer Launch'!Q:Q, MATCH("Strategic Priority Weight (1–5)", 'Customer Launch'!$A:$A, 0)) -> 2 | R47: =INDEX('Customer Launch'!R:R, MATCH("Strategic Priority Weight (1–5)", 'Customer Launch'!$A:$A, 0)) -> 2 | S47: =INDEX('Customer Launch'!S:S, MATCH("Strategic Priority Weight (1–5)", 'Customer Launch'!$A:$A, 0)) -> 2 | T47: =INDEX('Customer Launch'!T:T, MATCH("Strategic Priority Weight (1–5)", 'Customer Launch'!$A:$A, 0)) -> 2 | U47: =INDEX('Customer Launch'!U:U, MATCH("Strategic Priority Weight (1–5)", 'Customer Launch'!$A:$A, 0)) -> 2 | V47: =INDEX('Customer Launch'!V:V, MATCH("Strategic Priority Weight (1–5)", 'Customer Launch'!$A:$A, 0)) -> 2 | W47: =INDEX('Customer Launch'!W:W, MATCH("Strategic Priority Weight (1–5)", 'Customer Launch'!$A:$A, 0)) -> 2 | X47: =INDEX('Customer Launch'!X:X, MATCH("Strategic Priority Weight (1–5)", 'Customer Launch'!$A:$A, 0)) -> 2 | Y47: =INDEX('Customer Launch'!Y:Y, MATCH("Strategic Priority Weight (1–5)", 'Customer Launch'!$A:$A, 0)) -> 2 | Z47: =INDEX('Customer Launch'!Z:Z, MATCH("Strategic Priority Weight (1–5)", 'Customer Launch'!$A:$A, 0)) -> 2 | AA47: =INDEX('Customer Launch'!AA:AA, MATCH("Strategic Priority Weight (1–5)", 'Customer Launch'!$A:$A, 0)) -> 2 | AB47: =INDEX('Customer Launch'!AB:AB, MATCH("Strategic Priority Weight (1–5)", 'Customer Launch'!$A:$A, 0)) -> 2 | AC47: =INDEX('Customer Launch'!AC:AC, MATCH("Strategic Priority Weight (1–5)", 'Customer Launch'!$A:$A, 0)) -> 2
A48: Starlink | D48: =INDEX(Starlink!D:D, MATCH("Strategic Priority Weight (1–5)", Starlink!$A:$A, 0)) -> 5 | E48: =INDEX(Starlink!E:E, MATCH("Strategic Priority Weight (1–5)", Starlink!$A:$A, 0)) -> 5 | F48: =INDEX(Starlink!F:F, MATCH("Strategic Priority Weight (1–5)", Starlink!$A:$A, 0)) -> 5 | G48: =INDEX(Starlink!G:G, MATCH("Strategic Priority Weight (1–5)", Starlink!$A:$A, 0)) -> 5 | H48: =INDEX(Starlink!H:H, MATCH("Strategic Priority Weight (1–5)", Starlink!$A:$A, 0)) -> 5 | I48: =INDEX(Starlink!I:I, MATCH("Strategic Priority Weight (1–5)", Starlink!$A:$A, 0)) -> 5 | J48: =INDEX(Starlink!J:J, MATCH("Strategic Priority Weight (1–5)", Starlink!$A:$A, 0)) -> 5 | K48: =INDEX(Starlink!K:K, MATCH("Strategic Priority Weight (1–5)", Starlink!$A:$A, 0)) -> 5 | L48: =INDEX(Starlink!L:L, MATCH("Strategic Priority Weight (1–5)", Starlink!$A:$A, 0)) -> 5 | M48: =INDEX(Starlink!M:M, MATCH("Strategic Priority Weight (1–5)", Starlink!$A:$A, 0)) -> 5 | N48: =INDEX(Starlink!N:N, MATCH("Strategic Priority Weight (1–5)", Starlink!$A:$A, 0)) -> 5 | O48: =INDEX(Starlink!O:O, MATCH("Strategic Priority Weight (1–5)", Starlink!$A:$A, 0)) -> 5 | P48: =INDEX(Starlink!P:P, MATCH("Strategic Priority Weight (1–5)", Starlink!$A:$A, 0)) -> 5 | Q48: =INDEX(Starlink!Q:Q, MATCH("Strategic Priority Weight (1–5)", Starlink!$A:$A, 0)) -> 5 | R48: =INDEX(Starlink!R:R, MATCH("Strategic Priority Weight (1–5)", Starlink!$A:$A, 0)) -> 5 | S48: =INDEX(Starlink!S:S, MATCH("Strategic Priority Weight (1–5)", Starlink!$A:$A, 0)) -> 5 | T48: =INDEX(Starlink!T:T, MATCH("Strategic Priority Weight (1–5)", Starlink!$A:$A, 0)) -> 5 | U48: =INDEX(Starlink!U:U, MATCH("Strategic Priority Weight (1–5)", Starlink!$A:$A, 0)) -> 5 | V48: =INDEX(Starlink!V:V, MATCH("Strategic Priority Weight (1–5)", Starlink!$A:$A, 0)) -> 5 | W48: =INDEX(Starlink!W:W, MATCH("Strategic Priority Weight (1–5)", Starlink!$A:$A, 0)) -> 5 | X48: =INDEX(Starlink!X:X, MATCH("Strategic Priority Weight (1–5)", Starlink!$A:$A, 0)) -> 5 | Y48: =INDEX(Starlink!Y:Y, MATCH("Strategic Priority Weight (1–5)", Starlink!$A:$A, 0)) -> 5 | Z48: =INDEX(Starlink!Z:Z, MATCH("Strategic Priority Weight (1–5)", Starlink!$A:$A, 0)) -> 5 | AA48: =INDEX(Starlink!AA:AA, MATCH("Strategic Priority Weight (1–5)", Starlink!$A:$A, 0)) -> 5 | AB48: =INDEX(Starlink!AB:AB, MATCH("Strategic Priority Weight (1–5)", Starlink!$A:$A, 0)) -> 5 | AC48: =INDEX(Starlink!AC:AC, MATCH("Strategic Priority Weight (1–5)", Starlink!$A:$A, 0)) -> 5
A49: ODC | D49: =INDEX(ODC!D:D, MATCH("Strategic Priority Weight (1–5)", ODC!$A:$A, 0)) -> 4 | E49: =INDEX(ODC!E:E, MATCH("Strategic Priority Weight (1–5)", ODC!$A:$A, 0)) -> 4 | F49: =INDEX(ODC!F:F, MATCH("Strategic Priority Weight (1–5)", ODC!$A:$A, 0)) -> 4 | G49: =INDEX(ODC!G:G, MATCH("Strategic Priority Weight (1–5)", ODC!$A:$A, 0)) -> 4 | H49: =INDEX(ODC!H:H, MATCH("Strategic Priority Weight (1–5)", ODC!$A:$A, 0)) -> 4 | I49: =INDEX(ODC!I:I, MATCH("Strategic Priority Weight (1–5)", ODC!$A:$A, 0)) -> 4 | J49: =INDEX(ODC!J:J, MATCH("Strategic Priority Weight (1–5)", ODC!$A:$A, 0)) -> 4 | K49: =INDEX(ODC!K:K, MATCH("Strategic Priority Weight (1–5)", ODC!$A:$A, 0)) -> 4 | L49: =INDEX(ODC!L:L, MATCH("Strategic Priority Weight (1–5)", ODC!$A:$A, 0)) -> 4 | M49: =INDEX(ODC!M:M, MATCH("Strategic Priority Weight (1–5)", ODC!$A:$A, 0)) -> 4 | N49: =INDEX(ODC!N:N, MATCH("Strategic Priority Weight (1–5)", ODC!$A:$A, 0)) -> 4 | O49: =INDEX(ODC!O:O, MATCH("Strategic Priority Weight (1–5)", ODC!$A:$A, 0)) -> 4 | P49: =INDEX(ODC!P:P, MATCH("Strategic Priority Weight (1–5)", ODC!$A:$A, 0)) -> 4 | Q49: =INDEX(ODC!Q:Q, MATCH("Strategic Priority Weight (1–5)", ODC!$A:$A, 0)) -> 4 | R49: =INDEX(ODC!R:R, MATCH("Strategic Priority Weight (1–5)", ODC!$A:$A, 0)) -> 4 | S49: =INDEX(ODC!S:S, MATCH("Strategic Priority Weight (1–5)", ODC!$A:$A, 0)) -> 4 | T49: =INDEX(ODC!T:T, MATCH("Strategic Priority Weight (1–5)", ODC!$A:$A, 0)) -> 4 | U49: =INDEX(ODC!U:U, MATCH("Strategic Priority Weight (1–5)", ODC!$A:$A, 0)) -> 4 | V49: =INDEX(ODC!V:V, MATCH("Strategic Priority Weight (1–5)", ODC!$A:$A, 0)) -> 4 | W49: =INDEX(ODC!W:W, MATCH("Strategic Priority Weight (1–5)", ODC!$A:$A, 0)) -> 4 | X49: =INDEX(ODC!X:X, MATCH("Strategic Priority Weight (1–5)", ODC!$A:$A, 0)) -> 4 | Y49: =INDEX(ODC!Y:Y, MATCH("Strategic Priority Weight (1–5)", ODC!$A:$A, 0)) -> 4 | Z49: =INDEX(ODC!Z:Z, MATCH("Strategic Priority Weight (1–5)", ODC!$A:$A, 0)) -> 4 | AA49: =INDEX(ODC!AA:AA, MATCH("Strategic Priority Weight (1–5)", ODC!$A:$A, 0)) -> 4 | AB49: =INDEX(ODC!AB:AB, MATCH("Strategic Priority Weight (1–5)", ODC!$A:$A, 0)) -> 4 | AC49: =INDEX(ODC!AC:AC, MATCH("Strategic Priority Weight (1–5)", ODC!$A:$A, 0)) -> 4
A50: AI Stack | D50: =INDEX('AI Stack'!D:D, MATCH("Strategic Priority Weight (1–5)", 'AI Stack'!$A:$A, 0)) -> 4 | E50: =INDEX('AI Stack'!E:E, MATCH("Strategic Priority Weight (1–5)", 'AI Stack'!$A:$A, 0)) -> 4 | F50: =INDEX('AI Stack'!F:F, MATCH("Strategic Priority Weight (1–5)", 'AI Stack'!$A:$A, 0)) -> 4 | G50: =INDEX('AI Stack'!G:G, MATCH("Strategic Priority Weight (1–5)", 'AI Stack'!$A:$A, 0)) -> 4 | H50: =INDEX('AI Stack'!H:H, MATCH("Strategic Priority Weight (1–5)", 'AI Stack'!$A:$A, 0)) -> 4 | I50: =INDEX('AI Stack'!I:I, MATCH("Strategic Priority Weight (1–5)", 'AI Stack'!$A:$A, 0)) -> 4 | J50: =INDEX('AI Stack'!J:J, MATCH("Strategic Priority Weight (1–5)", 'AI Stack'!$A:$A, 0)) -> 4 | K50: =INDEX('AI Stack'!K:K, MATCH("Strategic Priority Weight (1–5)", 'AI Stack'!$A:$A, 0)) -> 4 | L50: =INDEX('AI Stack'!L:L, MATCH("Strategic Priority Weight (1–5)", 'AI Stack'!$A:$A, 0)) -> 4 | M50: =INDEX('AI Stack'!M:M, MATCH("Strategic Priority Weight (1–5)", 'AI Stack'!$A:$A, 0)) -> 4 | N50: =INDEX('AI Stack'!N:N, MATCH("Strategic Priority Weight (1–5)", 'AI Stack'!$A:$A, 0)) -> 4 | O50: =INDEX('AI Stack'!O:O, MATCH("Strategic Priority Weight (1–5)", 'AI Stack'!$A:$A, 0)) -> 4 | P50: =INDEX('AI Stack'!P:P, MATCH("Strategic Priority Weight (1–5)", 'AI Stack'!$A:$A, 0)) -> 4 | Q50: =INDEX('AI Stack'!Q:Q, MATCH("Strategic Priority Weight (1–5)", 'AI Stack'!$A:$A, 0)) -> 4 | R50: =INDEX('AI Stack'!R:R, MATCH("Strategic Priority Weight (1–5)", 'AI Stack'!$A:$A, 0)) -> 4 | S50: =INDEX('AI Stack'!S:S, MATCH("Strategic Priority Weight (1–5)", 'AI Stack'!$A:$A, 0)) -> 4 | T50: =INDEX('AI Stack'!T:T, MATCH("Strategic Priority Weight (1–5)", 'AI Stack'!$A:$A, 0)) -> 4 | U50: =INDEX('AI Stack'!U:U, MATCH("Strategic Priority Weight (1–5)", 'AI Stack'!$A:$A, 0)) -> 4 | V50: =INDEX('AI Stack'!V:V, MATCH("Strategic Priority Weight (1–5)", 'AI Stack'!$A:$A, 0)) -> 4 | W50: =INDEX('AI Stack'!W:W, MATCH("Strategic Priority Weight (1–5)", 'AI Stack'!$A:$A, 0)) -> 4 | X50: =INDEX('AI Stack'!X:X, MATCH("Strategic Priority Weight (1–5)", 'AI Stack'!$A:$A, 0)) -> 4 | Y50: =INDEX('AI Stack'!Y:Y, MATCH("Strategic Priority Weight (1–5)", 'AI Stack'!$A:$A, 0)) -> 4 | Z50: =INDEX('AI Stack'!Z:Z, MATCH("Strategic Priority Weight (1–5)", 'AI Stack'!$A:$A, 0)) -> 4 | AA50: =INDEX('AI Stack'!AA:AA, MATCH("Strategic Priority Weight (1–5)", 'AI Stack'!$A:$A, 0)) -> 4 | AB50: =INDEX('AI Stack'!AB:AB, MATCH("Strategic Priority Weight (1–5)", 'AI Stack'!$A:$A, 0)) -> 4 | AC50: =INDEX('AI Stack'!AC:AC, MATCH("Strategic Priority Weight (1–5)", 'AI Stack'!$A:$A, 0)) -> 4
A51: Lunar / Mars | D51: =INDEX('Lunar Mars'!D:D, MATCH("Strategic Priority Weight (1–5)", 'Lunar Mars'!$A:$A, 0)) -> 3 | E51: =INDEX('Lunar Mars'!E:E, MATCH("Strategic Priority Weight (1–5)", 'Lunar Mars'!$A:$A, 0)) -> 3 | F51: =INDEX('Lunar Mars'!F:F, MATCH("Strategic Priority Weight (1–5)", 'Lunar Mars'!$A:$A, 0)) -> 3 | G51: =INDEX('Lunar Mars'!G:G, MATCH("Strategic Priority Weight (1–5)", 'Lunar Mars'!$A:$A, 0)) -> 3 | H51: =INDEX('Lunar Mars'!H:H, MATCH("Strategic Priority Weight (1–5)", 'Lunar Mars'!$A:$A, 0)) -> 3 | I51: =INDEX('Lunar Mars'!I:I, MATCH("Strategic Priority Weight (1–5)", 'Lunar Mars'!$A:$A, 0)) -> 3 | J51: =INDEX('Lunar Mars'!J:J, MATCH("Strategic Priority Weight (1–5)", 'Lunar Mars'!$A:$A, 0)) -> 3 | K51: =INDEX('Lunar Mars'!K:K, MATCH("Strategic Priority Weight (1–5)", 'Lunar Mars'!$A:$A, 0)) -> 3 | L51: =INDEX('Lunar Mars'!L:L, MATCH("Strategic Priority Weight (1–5)", 'Lunar Mars'!$A:$A, 0)) -> 3 | M51: =INDEX('Lunar Mars'!M:M, MATCH("Strategic Priority Weight (1–5)", 'Lunar Mars'!$A:$A, 0)) -> 3 | N51: =INDEX('Lunar Mars'!N:N, MATCH("Strategic Priority Weight (1–5)", 'Lunar Mars'!$A:$A, 0)) -> 3 | O51: =INDEX('Lunar Mars'!O:O, MATCH("Strategic Priority Weight (1–5)", 'Lunar Mars'!$A:$A, 0)) -> 3 | P51: =INDEX('Lunar Mars'!P:P, MATCH("Strategic Priority Weight (1–5)", 'Lunar Mars'!$A:$A, 0)) -> 3 | Q51: =INDEX('Lunar Mars'!Q:Q, MATCH("Strategic Priority Weight (1–5)", 'Lunar Mars'!$A:$A, 0)) -> 3 | R51: =INDEX('Lunar Mars'!R:R, MATCH("Strategic Priority Weight (1–5)", 'Lunar Mars'!$A:$A, 0)) -> 3 | S51: =INDEX('Lunar Mars'!S:S, MATCH("Strategic Priority Weight (1–5)", 'Lunar Mars'!$A:$A, 0)) -> 3 | T51: =INDEX('Lunar Mars'!T:T, MATCH("Strategic Priority Weight (1–5)", 'Lunar Mars'!$A:$A, 0)) -> 3 | U51: =INDEX('Lunar Mars'!U:U, MATCH("Strategic Priority Weight (1–5)", 'Lunar Mars'!$A:$A, 0)) -> 3 | V51: =INDEX('Lunar Mars'!V:V, MATCH("Strategic Priority Weight (1–5)", 'Lunar Mars'!$A:$A, 0)) -> 3 | W51: =INDEX('Lunar Mars'!W:W, MATCH("Strategic Priority Weight (1–5)", 'Lunar Mars'!$A:$A, 0)) -> 3 | X51: =INDEX('Lunar Mars'!X:X, MATCH("Strategic Priority Weight (1–5)", 'Lunar Mars'!$A:$A, 0)) -> 3 | Y51: =INDEX('Lunar Mars'!Y:Y, MATCH("Strategic Priority Weight (1–5)", 'Lunar Mars'!$A:$A, 0)) -> 3 | Z51: =INDEX('Lunar Mars'!Z:Z, MATCH("Strategic Priority Weight (1–5)", 'Lunar Mars'!$A:$A, 0)) -> 3 | AA51: =INDEX('Lunar Mars'!AA:AA, MATCH("Strategic Priority Weight (1–5)", 'Lunar Mars'!$A:$A, 0)) -> 3 | AB51: =INDEX('Lunar Mars'!AB:AB, MATCH("Strategic Priority Weight (1–5)", 'Lunar Mars'!$A:$A, 0)) -> 3 | AC51: =INDEX('Lunar Mars'!AC:AC, MATCH("Strategic Priority Weight (1–5)", 'Lunar Mars'!$A:$A, 0)) -> 3
A53: LAYER 2 — STARSHIP CAPACITY ALLOCATION
A55: Total Starship annual capacity (kg) | D55: ='Launch Capacity'!D23 -> 150000 | E55: ='Launch Capacity'!E23 -> 145833.33 | F55: ='Launch Capacity'!F23 -> 166224.03 | G55: ='Launch Capacity'!G23 -> 179613.66 | H55: ='Launch Capacity'!H23 -> 178825.75 | I55: ='Launch Capacity'!I23 -> 175551.24 | J55: ='Launch Capacity'!J23 -> 179180.09 | K55: ='Launch Capacity'!K23 -> 179343.62 | ... AC55: ='Launch Capacity'!AC23 -> 247339.5
A57: ▸ Dedicated reservations — off the top (per Sprint 4)
...

Sheet Launch Capacity
A1: LAUNCH CAPACITY
A2: Starship + Falcon 9 — fleet × cadence × payload, with cost curves
A4: Year | D4: 2025 | E4: 2026 | F4: 2027 | G4: 2028 | H4: 2029 | I4: 2030 | J4: 2031 | K4: 2032 | L4: 2033 | M4: 2034 | N4: 2035 | O4: 2036 | P4: 2037 | Q4: 2038 | R4: 2039 | S4: 2040 | T4: 2041 | U4: 2042 | V4: 2043 | W4: 2044 | X4: 2045 | Y4: 2046 | Z4: 2047 | AA4: 2048 | AB4: 2049 | AC4: 2050
A6: OUTPUTS — FALCON 9 (feeds Launch module)
A7: Total F9 launches available | D7: =D72 -> 336 | E7: =E72 -> 432 | F7: =F72 -> 528 | G7: =G72 -> 618 | H7: =H72 -> 696 | I7: =I72 -> 762 | J7: =J72 -> 816 | K7: =K72 -> 858 | ... AC7: =AC72 -> 912
A8: F9 cost per launch ($mm, blended) | D8: =D68 -> 17.75 | E8: =E68 -> 17.727832 | F8: =F68 -> 17.72 | G8: =G68 -> 17.714179 | H8: =H68 -> 17.709767 | I8: =I68 -> 17.706419 | J8: =J68 -> 17.703923 | K8: =K68 -> 17.702146 | ... AC8: =AC68 -> 17.700443
A9: F9 annual capacity (kg-to-LEO) | D9: =D73 -> 7660800 | E9: =E73 -> 9849600 | F9: =F73 -> 12038400 | G9: =G73 -> 14090400 | H9: =H73 -> 15868800 | I9: =I73 -> 17373600 | J9: =J73 -> 18604800 | K9: =K73 -> 19562400 | ... AC9: =AC73 -> 20793600
A11: OUTPUTS — STARSHIP (feeds Allocator Layer 2 at D23)
A23: Total Annual Capacity (kg-to-LEO) ← EXTERNAL REF: Allocator!D38, Dashboard!D46 | D23: =D144 -> 150000 | E23: =E144 -> 145833.33 | F23: =F144 -> 166224.03 | G23: =G144 -> 179613.66 | H23: =H144 -> 178825.75 | I23: =I144 -> 175551.24 | J23: =J144 -> 179180.09 | K23: =K144 -> 179343.62 | ... AC23: =AC144 -> 247339.5
A24: Total Annual Launches | D24: =D143 -> 1 | E24: =E143 -> 1 | F24: =F143 -> 1.1733461 | G24: =G143 -> 1.3062812 | H24: =H143 -> 1.4164415 | I24: =I143 -> 1.5265325 | J24: =J143 -> 1.6289099 | K24: =K143 -> 1.7080345 | ... AC24: =AC143 -> 2.4130683
A25: Average $/kg | D25: =D146 -> 390 | E25: =E146 -> 267.696 | F25: =F146 -> 216.27445 | G25: =G146 -> 185.47253 | H25: =H146 -> 146.22114 | I25: =I146 -> 105.01218 | J25: =J146 -> 81.201868 | K25: =K146 -> 57.3659 | ... AC25: =AC146 -> 22.71187
A27: OUTPUTS — COMBINED FLEET
A28: Combined fleet blended $/kg | D28: =(D8*D7+D141*D143)/(D7+D143) -> 17.87092 | E28: =IFERROR((E8*E7+E141*E143)/(E7+E143),0) -> 17.77705 | F28: =IFERROR((F8*F7+F141*F143)/(F7+F143),0) -> 17.748645 | G28: =IFERROR((G8*G7+G141*G143)/(G7+G143),0) -> 17.730607 | H28: =IFERROR((H8*H7+H141*H143)/(H7+H143),0) -> 17.711292 | I28: =IFERROR((I8*I7+I141*I143)/(I7+I143),0) -> 17.695163 | J28: =IFERROR((J8*J7+J141*J143)/(J7+J143),0) -> 17.686448 | K28: =IFERROR((K8*K7+K141*K143)/(K7+K143),0) -> 17.678943 | L28: =IFERROR((L8*L7+L141*L143)/(L7+L143),0) -> 17.675916 | ... AC28: =IFERROR((AC8*AC7+AC141*AC143)/(AC7+AC143),0) -> 17.659876
A30: ══════════ FALCON 9 ══════════
A32: SECTION F1 — INPUTS FROM ASSUMPTIONS
A33: F9 booster (1st stage) mfg cost ($mm) | B33: =Assumptions!B170 -> 30
A34: F9 2nd stage mfg cost ($mm, expendable) | B34: =Assumptions!B171 -> 10
A35: F9 fairing cost ($mm, net of 75% recovery) | B35: =Assumptions!B172 -> 1.25
A36: F9 per-launch ops cost ($mm) | B36: =Assumptions!B173 -> 5
A37: F9 booster refurb % of mfg | B37: =Assumptions!B174 -> 0.03
A38: F9 payload to LEO (kg) | B38: =Assumptions!B175 -> 22800
A39: F9 lifetime reuses per booster | B39: =Assumptions!B176 -> 50
A40: F9 Wright's Law mfg learning rate | B40: =Assumptions!B177 -> 0.02
A41: F9 cadence per booster (flights/yr, flat) | B41: =Assumptions!B178 -> 12
A42: F9 base booster build rate (boosters/year) | B42: =Assumptions!B179 -> 8
A43: V3 Starlink launch trigger year | B43: =Assumptions!B180 -> 2027
A44: F9 build-rate decay window (years) | B44: =Assumptions!B181 -> 8
A45: F9 seed fleet (boosters at start of 2025) | B45: =Assumptions!B185 -> 24
A50: SECTION F2 — FLEET BUILD (build rate decays once V3 Starship trigger fires)
A51: Boosters in fleet (start of year) | D51: =$B$45 -> 24 | E51: =D54 -> 32 | F51: =E54 -> 40 | G51: =F54 -> 48 | H51: =G54 -> 55 | I51: =H54 -> 61 | J51: =I54 -> 66 | K51: =J54 -> 70 | L51: =K54 -> 73 | ... AC51: =AB54 -> 76
A52: Boosters built this year | D52: =IF(D$4<$B$43,$B$42,MAX(0,$B$42*(1-(D$4-$B$43)/$B$44))) -> 8 | E52: =IF(E$4<$B$43,$B$42,MAX(0,$B$42*(1-(E$4-$B$43)/$B$44))) -> 8 | F52: =IF(F$4<$B$43,$B$42,MAX(0,$B$42*(1-(F$4-$B$43)/$B$44))) -> 8 | G52: =IF(G$4<$B$43,$B$42,MAX(0,$B$42*(1-(G$4-$B$43)/$B$44))) -> 7 | H52: =IF(H$4<$B$43,$B$42,MAX(0,$B$42*(1-(H$4-$B$43)/$B$44))) -> 6 | I52: =IF(I$4<$B$43,$B$42,MAX(0,$B$42*(1-(I$4-$B$43)/$B$44))) -> 5 | J52: =IF(J$4<$B$43,$B$42,MAX(0,$B$42*(1-(J$4-$B$43)/$B$44))) -> 4 | K52: =IF(K$4<$B$43,$B$42,MAX(0,$B$42*(1-(K$4-$B$43)/$B$44))) -> 3 | ... AC52: =IF(AC$4<$B$43,$B$42,MAX(0,$B$42*(1-(AC$4-$B$43)/$B$44))) -> 0
A53: Boosters retired this year (80% of lifetime cap) | D53: =IFERROR(MAX(0,(D51+D52)*MIN(1,MAX(0,(D55-0.8*$B$39)/(0.2*$B$39)))),0) -> 0 | E53: =IFERROR(MIN(E51+E52,(E51+E52)*E$57/$B$39),0) -> 0 | F53: =IFERROR(MIN(F51+F52,(F51+F52)*F$57/$B$39),0) -> 0 | G53: =IFERROR(MIN(G51+G52,(G51+G52)*G$57/$B$39),0) -> 0 | H53: =IFERROR(MIN(H51+H52,(H51+H52)*H$57/$B$39),0) -> 0 | I53: =IFERROR(MIN(I51+I52,(I51+I52)*I$57/$B$39),0) -> 0 | J53: =IFERROR(MIN(J51+J52,(J51+J52)*J$57/$B$39),0) -> 0 | K53: =IFERROR(MIN(K51+K52,(K51+K52)*K$57/$B$39),0) -> 0 | L53: =IFERROR(MIN(L51+L52,(L51+L52)*L$57/$B$39),0) -> 0 | ... AC53: =IFERROR(MIN(AC51+AC52,(AC51+AC52)*AC$57/$B$39),0) -> 0
A54: Boosters in fleet (end of year) | D54: =MAX(0,D51+D52-D53) -> 32 | E54: =MAX(0,E51+E52-E53) -> 40 | F54: =MAX(0,F51+F52-F53) -> 48 | G54: =MAX(0,G51+G52-G53) -> 55 | H54: =MAX(0,H51+H52-H53) -> 61 | I54: =MAX(0,I51+I52-I53) -> 66 | J54: =MAX(0,J51+J52-J53) -> 70 | K54: =MAX(0,K51+K52-K53) -> 73 | ... AC54: =MAX(0,AC51+AC52-AC53) -> 76
A55: Avg cum flights per booster (lifetime usage) | D55: =IFERROR(D58/((D51+D54)/2),0) -> 12 | E55: =IFERROR(IF(E54=0,0,(D55*D54+E58)/MAX(1,(D54+E52))),0) -> 20.4 | F55: =IFERROR(IF(F54=0,0,(E55*E54+F58)/MAX(1,(E54+F52))),0) -> 28 | G55: =IFERROR(IF(G54=0,0,(F55*F54+G58)/MAX(1,(F54+G52))),0) -> 35.672727 | H55: =IFERROR(IF(H54=0,0,(G55*G54+H58)/MAX(1,(G54+H52))),0) -> 43.57377 | I55: =IFERROR(IF(I54=0,0,(H55*H54+I58)/MAX(1,(H54+I52))),0) -> 51.818182 | J55: =IFERROR(IF(J54=0,0,(I55*I54+J58)/MAX(1,(I54+J52))),0) -> 60.514286 | K55: =IFERROR(IF(K54=0,0,(J55*J54+K58)/MAX(1,(J54+K52))),0) -> 69.780822 | L55: =IFERROR(IF(L54=0,0,(K55*K54+L58)/MAX(1,(K54+L52))),0) -> 79.76 | ... AC55: =IFERROR(IF(AC54=0,0,(AB55*AB54+AC58)/MAX(1,(AB54+AC52))),0) -> 282.63158
A56: Cumulative F9 boosters ever built (running total) | D56: =D51+D52 -> 32 | E56: =D56+E52 -> 40 | F56: =E56+F52 -> 48 | G56: =F56+G52 -> 55 | H56: =G56+H52 -> 61 | I56: =H56+I52 -> 66 | J56: =I56+J52 -> 70 | K56: =J56+K52 -> 73 | L56: =K56+L52 -> 75 | ... AC56: =AB56+AC52 -> 76
A57: SECTION F3 — CADENCE & ANNUAL LAUNCHES
A58: Total F9 launches this year (avg fleet × cadence) | D58: =((D51+D54)/2)*$B$41 -> 336 | E58: =((E51+E54)/2)*$B$41 -> 432 | F58: =((F51+F54)/2)*$B$41 -> 528 | G58: =((G51+G54)/2)*$B$41 -> 618 | H58: =((H51+H54)/2)*$B$41 -> 696 | I58: =((I51+I54)/2)*$B$41 -> 762 | J58: =((J51+J54)/2)*$B$41 -> 816 | K58: =((K51+K54)/2)*$B$41 -> 858 | ... AC58: =((AC51+AC54)/2)*$B$41 -> 912
A59: Cumulative F9 booster flights (running total) | D59: =D58 -> 336 | E59: =D59+E58 -> 768 | F59: =E59+F58 -> 1296 | G59: =F59+G58 -> 1914 | H59: =G59+H58 -> 2610 | I59: =H59+I58 -> 3372 | J59: =I59+J58 -> 4188 | K59: =J59+K58 -> 5046 | L59: =K59+L58 -> 5934 | ... AC59: =AB59+AC58 -> 21432
A61: SECTION F4 — PER-LAUNCH COST BUILD
A62: Booster mfg cost this year (Wright's Law @ 2%) | D62: =$B$33 -> 30 | E62: =$B$33*(1-$B$40)^IFERROR(LOG(E56/$B$45,2),0) -> 29.556648 | F62: =$B$33*(1-$B$40)^IFERROR(LOG(F56/$B$45,2),0) -> 29.4 | G62: =$B$33*(1-$B$40)^IFERROR(LOG(G56/$B$45,2),0) -> 29.283579 | H62: =$B$33*(1-$B$40)^IFERROR(LOG(H56/$B$45,2),0) -> 29.195339 | I62: =$B$33*(1-$B$40)^IFERROR(LOG(I56/$B$45,2),0) -> 29.128379 | J62: =$B$33*(1-$B$40)^IFERROR(LOG(J56/$B$45,2),0) -> 29.078467 | K62: =$B$33*(1-$B$40)^IFERROR(LOG(K56/$B$45,2),0) -> 29.042923 | L62: =$B$33*(1-$B$40)^IFERROR(LOG(L56/$B$45,2),0) -> 29.020052 | ... AC62: =$B$33*(1-$B$40)^IFERROR(LOG(AC56/$B$45,2),0) -> 29.008851
...

Sheet Starlink Capacity
A1: STARLINK CAPACITY
A2: Aggregates Starlink constellation capacity (BB + DTC). Allocates bandwidth to ODC (and AI Stack when active) as internal claims on both pools. Remainder = available for external Starlink revenue (BB and DTC separately). At-cost proportional cost allocation per pool.
A4: Year | D4: 2025 | E4: 2026 | F4: 2027 | G4: 2028 | H4: 2029 | I4: 2030 | J4: 2031 | K4: 2032 | L4: 2033 | M4: 2034 | N4: 2035 | O4: 2036 | P4: 2037 | Q4: 2038 | R4: 2039 | S4: 2040 | T4: 2041 | U4: 2042 | V4: 2043 | W4: 2044 | X4: 2045 | Y4: 2046 | Z4: 2047 | AA4: 2048 | AB4: 2049 | AC4: 2050
A5: Year offset | D5: 0 | E5: 1 | F5: 2 | G5: 3 | H5: 4 | I5: 5 | J5: 6 | K5: 7 | L5: 8 | M5: 9 | N5: 10 | O5: 11 | P5: 12 | Q5: 13 | R5: 14 | S5: 15 | T5: 16 | U5: 17 | V5: 18 | W5: 19 | X5: 20 | Y5: 21 | Z5: 22 | AA5: 23 | AB5: 24 | AC5: 25
A7: SECTION A — CONSTELLATION SUMMARY (from Starlink tab)
A8: Total Active BB Satellites | D8: =INDEX(Starlink!D:D, MATCH("Total Active BB Satellites", Starlink!$A:$A, 0)) -> 4196.8 | E8: =INDEX(Starlink!E:E, MATCH("Total Active BB Satellites", Starlink!$A:$A, 0)) -> 3201.0593 | F8: =INDEX(Starlink!F:F, MATCH("Total Active BB Satellites", Starlink!$A:$A, 0)) -> 2202.7341 | G8: =INDEX(Starlink!G:G, MATCH("Total Active BB Satellites", Starlink!$A:$A, 0)) -> 1200.7861 | H8: =INDEX(Starlink!H:H, MATCH("Total Active BB Satellites", Starlink!$A:$A, 0)) -> 192.84057 | I8: =INDEX(Starlink!I:I, MATCH("Total Active BB Satellites", Starlink!$A:$A, 0)) -> 223.78213 | J8: =INDEX(Starlink!J:J, MATCH("Total Active BB Satellites", Starlink!$A:$A, 0)) -> 200.45163 | K8: =INDEX(Starlink!K:K, MATCH("Total Active BB Satellites", Starlink!$A:$A, 0)) -> 177.12156 | L8: =INDEX(Starlink!L:L, MATCH("Total Active BB Satellites", Starlink!$A:$A, 0)) -> 157.70168 | M8: =INDEX(Starlink!M:M, MATCH("Total Active BB Satellites", Starlink!$A:$A, 0)) -> 146.86681 | N8: =INDEX(Starlink!N:N, MATCH("Total Active BB Satellites", Starlink!$A:$A, 0)) -> 149.033 | O8: =INDEX(Starlink!O:O, MATCH("Total Active BB Satellites", Starlink!$A:$A, 0)) -> 156.46247 | P8: =INDEX(Starlink!P:P, MATCH("Total Active BB Satellites", Starlink!$A:$A, 0)) -> 171.03659 | Q8: =INDEX(Starlink!Q:Q, MATCH("Total Active BB Satellites", Starlink!$A:$A, 0)) -> 190.51761 | R8: =INDEX(Starlink!R:R, MATCH("Total Active BB Satellites", Starlink!$A:$A, 0)) -> 212.74692 | S8: =INDEX(Starlink!S:S, MATCH("Total Active BB Satellites", Starlink!$A:$A, 0)) -> 237.85284 | T8: =INDEX(Starlink!T:T, MATCH("Total Active BB Satellites", Starlink!$A:$A, 0)) -> 230.62516 | U8: =INDEX(Starlink!U:U, MATCH("Total Active BB Satellites", Starlink!$A:$A, 0)) -> 257.67218 | V8: =INDEX(Starlink!V:V, MATCH("Total Active BB Satellites", Starlink!$A:$A, 0)) -> 284.67329 | W8: =INDEX(Starlink!W:W, MATCH("Total Active BB Satellites", Starlink!$A:$A, 0)) -> 311.1473 | X8: =INDEX(Starlink!X:X, MATCH("Total Active BB Satellites", Starlink!$A:$A, 0)) -> 334.82386 | Y8: =INDEX(Starlink!Y:Y, MATCH("Total Active BB Satellites", Starlink!$A:$A, 0)) -> 420.95411 | Z8: =INDEX(Starlink!Z:Z, MATCH("Total Active BB Satellites", Starlink!$A:$A, 0)) -> 510.38749 | AA8: =INDEX(Starlink!AA:AA, MATCH("Total Active BB Satellites", Starlink!$A:$A, 0)) -> 603.30773 | AB8: =INDEX(Starlink!AB:AB, MATCH("Total Active BB Satellites", Starlink!$A:$A, 0)) -> 693.7572 | AC8: =INDEX(Starlink!AC:AC, MATCH("Total Active BB Satellites", Starlink!$A:$A, 0)) -> 788.02895
A9: Total Active DTC Satellites | D9: =INDEX(Starlink!D:D, MATCH("Total Active DTC Satellites", Starlink!$A:$A, 0)) -> 520 | E9: =INDEX(Starlink!E:E, MATCH("Total Active DTC Satellites", Starlink!$A:$A, 0)) -> 399.43399 | F9: =INDEX(Starlink!F:F, MATCH("Total Active DTC Satellites", Starlink!$A:$A, 0)) -> 278.4119 | G9: =INDEX(Starlink!G:G, MATCH("Total Active DTC Satellites", Starlink!$A:$A, 0)) -> 156.75049 | H9: =INDEX(Starlink!H:H, MATCH("Total Active DTC Satellites", Starlink!$A:$A, 0)) -> 34.03069 | I9: =INDEX(Starlink!I:I, MATCH("Total Active DTC Satellites", Starlink!$A:$A, 0)) -> 39.490964 | J9: =INDEX(Starlink!J:J, MATCH("Total Active DTC Satellites", Starlink!$A:$A, 0)) -> 35.373817 | K9: =INDEX(Starlink!K:K, MATCH("Total Active DTC Satellites", Starlink!$A:$A, 0)) -> 31.256746 | L9: =INDEX(Starlink!L:L, MATCH("Total Active DTC Satellites", Starlink!$A:$A, 0)) -> 27.829708 | M9: =INDEX(Starlink!M:M, MATCH("Total Active DTC Satellites", Starlink!$A:$A, 0)) -> 25.917673 | N9: =INDEX(Starlink!N:N, MATCH("Total Active DTC Satellites", Starlink!$A:$A, 0)) -> 26.299942 | O9: =INDEX(Starlink!O:O, MATCH("Total Active DTC Satellites", Starlink!$A:$A, 0)) -> 27.611024 | P9: =INDEX(Starlink!P:P, MATCH("Total Active DTC Satellites", Starlink!$A:$A, 0)) -> 30.182928 | Q9: =INDEX(Starlink!Q:Q, MATCH("Total Active DTC Satellites", Starlink!$A:$A, 0)) -> 33.620755 | R9: =INDEX(Starlink!R:R, MATCH("Total Active DTC Satellites", Starlink!$A:$A, 0)) -> 37.543574 | S9: =INDEX(Starlink!S:S, MATCH("Total Active DTC Satellites", Starlink!$A:$A, 0)) -> 41.97403 | T9: =INDEX(Starlink!T:T, MATCH("Total Active DTC Satellites", Starlink!$A:$A, 0)) -> 65.676695 | U9: =INDEX(Starlink!U:U, MATCH("Total Active DTC Satellites", Starlink!$A:$A, 0)) -> 70.449699 | V9: =INDEX(Starlink!V:V, MATCH("Total Active DTC Satellites", Starlink!$A:$A, 0)) -> 75.2146 | W9: =INDEX(Starlink!W:W, MATCH("Total Active DTC Satellites", Starlink!$A:$A, 0)) -> 79.886484 | X9: =INDEX(Starlink!X:X, MATCH("Total Active DTC Satellites", Starlink!$A:$A, 0)) -> 84.0647 | Y9: =INDEX(Starlink!Y:Y, MATCH("Total Active DTC Satellites", Starlink!$A:$A, 0)) -> 99.264157 | Z9: =INDEX(Starlink!Z:Z, MATCH("Total Active DTC Satellites", Starlink!$A:$A, 0)) -> 115.04652 | AA9: =INDEX(Starlink!AA:AA, MATCH("Total Active DTC Satellites", Starlink!$A:$A, 0)) -> 131.44421 | AB9: =INDEX(Starlink!AB:AB, MATCH("Total Active DTC Satellites", Starlink!$A:$A, 0)) -> 147.40588 | AC9: =INDEX(Starlink!AC:AC, MATCH("Total Active DTC Satellites", Starlink!$A:$A, 0)) -> 164.04207
A10: Total Active Satellites (All) | D10: =D8+D9 -> 4716.8 | E10: =E8+E9 -> 3600.4933 | F10: =F8+F9 -> 2481.146 | G10: =G8+G9 -> 1357.5366 | H10: =H8+H9 -> 226.87126 | I10: =I8+I9 -> 263.27309 | J10: =J8+J9 -> 235.82545 | K10: =K8+K9 -> 208.37831 | ... AC10: =AC8+AC9 -> 952.07102
A12: Total Active BB Bandwidth (Gbps) | D12: =INDEX(Starlink!D:D, MATCH("Total Active BB Bandwidth (Gbps)", Starlink!$A:$A, 0)) -> 575504 | E12: =INDEX(Starlink!E:E, MATCH("Total Active BB Bandwidth (Gbps)", Starlink!$A:$A, 0)) -> 613339.36 | F12: =INDEX(Starlink!F:F, MATCH("Total Active BB Bandwidth (Gbps)", Starlink!$A:$A, 0)) -> 648495.11 | G12: =INDEX(Starlink!G:G, MATCH("Total Active BB Bandwidth (Gbps)", Starlink!$A:$A, 0)) -> 679883.88 | H12: =INDEX(Starlink!H:H, MATCH("Total Active BB Bandwidth (Gbps)", Starlink!$A:$A, 0)) -> 705020.58 | I12: =INDEX(Starlink!I:I, MATCH("Total Active BB Bandwidth (Gbps)", Starlink!$A:$A, 0)) -> 520497.37 | J12: =INDEX(Starlink!J:J, MATCH("Total Active BB Bandwidth (Gbps)", Starlink!$A:$A, 0)) -> 496187.52 | K12: =INDEX(Starlink!K:K, MATCH("Total Active BB Bandwidth (Gbps)", Starlink!$A:$A, 0)) -> 471861.32 | L12: =INDEX(Starlink!L:L, MATCH("Total Active BB Bandwidth (Gbps)", Starlink!$A:$A, 0)) -> 451607.73 | M12: =INDEX(Starlink!M:M, MATCH("Total Active BB Bandwidth (Gbps)", Starlink!$A:$A, 0)) -> 440317.87 | N12: =INDEX(Starlink!N:N, MATCH("Total Active BB Bandwidth (Gbps)", Starlink!$A:$A, 0)) -> 442614.34 | O12: =INDEX(Starlink!O:O, MATCH("Total Active BB Bandwidth (Gbps)", Starlink!$A:$A, 0)) -> 450418.43 | P12: =INDEX(Starlink!P:P, MATCH("Total Active BB Bandwidth (Gbps)", Starlink!$A:$A, 0)) -> 465701.14 | Q12: =INDEX(Starlink!Q:Q, MATCH("Total Active BB Bandwidth (Gbps)", Starlink!$A:$A, 0)) -> 486127.99 | R12: =INDEX(Starlink!R:R, MATCH("Total Active BB Bandwidth (Gbps)", Starlink!$A:$A, 0)) -> 509445.74 | S12: =INDEX(Starlink!S:S, MATCH("Total Active BB Bandwidth (Gbps)", Starlink!$A:$A, 0)) -> 535792.67 | T12: =INDEX(Starlink!T:T, MATCH("Total Active BB Bandwidth (Gbps)", Starlink!$A:$A, 0)) -> 745140.62 | U12: =INDEX(Starlink!U:U, MATCH("Total Active BB Bandwidth (Gbps)", Starlink!$A:$A, 0)) -> 773563.13 | V12: =INDEX(Starlink!V:V, MATCH("Total Active BB Bandwidth (Gbps)", Starlink!$A:$A, 0)) -> 801965.99 | W12: =INDEX(Starlink!W:W, MATCH("Total Active BB Bandwidth (Gbps)", Starlink!$A:$A, 0)) -> 829847 | X12: =INDEX(Starlink!X:X, MATCH("Total Active BB Bandwidth (Gbps)", Starlink!$A:$A, 0)) -> 854825.05 | Y12: =INDEX(Starlink!Y:Y, MATCH("Total Active BB Bandwidth (Gbps)", Starlink!$A:$A, 0)) -> 945282.73 | Z12: =INDEX(Starlink!Z:Z, MATCH("Total Active BB Bandwidth (Gbps)", Starlink!$A:$A, 0)) -> 1039257.8 | AA12: =INDEX(Starlink!AA:AA, MATCH("Total Active BB Bandwidth (Gbps)", Starlink!$A:$A, 0)) -> 1136948.7 | AB12: =INDEX(Starlink!AB:AB, MATCH("Total Active BB Bandwidth (Gbps)", Starlink!$A:$A, 0)) -> 1232094 | AC12: =INDEX(Starlink!AC:AC, MATCH("Total Active BB Bandwidth (Gbps)", Starlink!$A:$A, 0)) -> 1331312.5
A13: Total Active DTC Bandwidth (Gbps) | D13: =INDEX(Starlink!D:D, MATCH("Total Active DTC Bandwidth (Gbps)", Starlink!$A:$A, 0)) -> 1936 | E13: =INDEX(Starlink!E:E, MATCH("Total Active DTC Bandwidth (Gbps)", Starlink!$A:$A, 0)) -> 1961.9435 | F13: =INDEX(Starlink!F:F, MATCH("Total Active DTC Bandwidth (Gbps)", Starlink!$A:$A, 0)) -> 1986.6327 | G13: =INDEX(Starlink!G:G, MATCH("Total Active DTC Bandwidth (Gbps)", Starlink!$A:$A, 0)) -> 2009.5638 | H13: =INDEX(Starlink!H:H, MATCH("Total Active DTC Bandwidth (Gbps)", Starlink!$A:$A, 0)) -> 2029.5844 | I13: =INDEX(Starlink!I:I, MATCH("Total Active DTC Bandwidth (Gbps)", Starlink!$A:$A, 0)) -> 2044.6001 | J13: =INDEX(Starlink!J:J, MATCH("Total Active DTC Bandwidth (Gbps)", Starlink!$A:$A, 0)) -> 2033.278 | K13: =INDEX(Starlink!K:K, MATCH("Total Active DTC Bandwidth (Gbps)", Starlink!$A:$A, 0)) -> 2021.9561 | L13: =INDEX(Starlink!L:L, MATCH("Total Active DTC Bandwidth (Gbps)", Starlink!$A:$A, 0)) -> 2012.5317 | M13: =INDEX(Starlink!M:M, MATCH("Total Active DTC Bandwidth (Gbps)", Starlink!$A:$A, 0)) -> 2007.2736 | N13: =INDEX(Starlink!N:N, MATCH("Total Active DTC Bandwidth (Gbps)", Starlink!$A:$A, 0)) -> 2008.3248 | O13: =INDEX(Starlink!O:O, MATCH("Total Active DTC Bandwidth (Gbps)", Starlink!$A:$A, 0)) -> 2011.9303 | P13: =INDEX(Starlink!P:P, MATCH("Total Active DTC Bandwidth (Gbps)", Starlink!$A:$A, 0)) -> 2019.0031 | Q13: =INDEX(Starlink!Q:Q, MATCH("Total Active DTC Bandwidth (Gbps)", Starlink!$A:$A, 0)) -> 2028.4571 | R13: =INDEX(Starlink!R:R, MATCH("Total Active DTC Bandwidth (Gbps)", Starlink!$A:$A, 0)) -> 2039.2448 | S13: =INDEX(Starlink!S:S, MATCH("Total Active DTC Bandwidth (Gbps)", Starlink!$A:$A, 0)) -> 2051.4286 | T13: =INDEX(Starlink!T:T, MATCH("Total Active DTC Bandwidth (Gbps)", Starlink!$A:$A, 0)) -> 2116.6109 | U13: =INDEX(Starlink!U:U, MATCH("Total Active DTC Bandwidth (Gbps)", Starlink!$A:$A, 0)) -> 2129.7367 | V13: =INDEX(Starlink!V:V, MATCH("Total Active DTC Bandwidth (Gbps)", Starlink!$A:$A, 0)) -> 2142.8401 | W13: =INDEX(Starlink!W:W, MATCH("Total Active DTC Bandwidth (Gbps)", Starlink!$A:$A, 0)) -> 2155.6878 | X13: =INDEX(Starlink!X:X, MATCH("Total Active DTC Bandwidth (Gbps)", Starlink!$A:$A, 0)) -> 2167.1779 | Y13: =INDEX(Starlink!Y:Y, MATCH("Total Active DTC Bandwidth (Gbps)", Starlink!$A:$A, 0)) -> 2208.9764 | Z13: =INDEX(Starlink!Z:Z, MATCH("Total Active DTC Bandwidth (Gbps)", Starlink!$A:$A, 0)) -> 2252.3779 | AA13: =INDEX(Starlink!AA:AA, MATCH("Total Active DTC Bandwidth (Gbps)", Starlink!$A:$A, 0)) -> 2297.4716 | AB13: =INDEX(Starlink!AB:AB, MATCH("Total Active DTC Bandwidth (Gbps)", Starlink!$A:$A, 0)) -> 2341.3662 | AC13: =INDEX(Starlink!AC:AC, MATCH("Total Active DTC Bandwidth (Gbps)", Starlink!$A:$A, 0)) -> 2387.1157
A14: Starshield Reserved Bandwidth (Gbps) | D14: =INDEX(Starlink!D:D, MATCH("Starshield Reserved Bandwidth (Gbps)", Starlink!$A:$A, 0)) -> 14790.453 | E14: =INDEX(Starlink!E:E, MATCH("Starshield Reserved Bandwidth (Gbps)", Starlink!$A:$A, 0)) -> 5837.5885 | F14: =INDEX(Starlink!F:F, MATCH("Starshield Reserved Bandwidth (Gbps)", Starlink!$A:$A, 0)) -> 2311.6148 | G14: =INDEX(Starlink!G:G, MATCH("Starshield Reserved Bandwidth (Gbps)", Starlink!$A:$A, 0)) -> 934.53368 | H14: =INDEX(Starlink!H:H, MATCH("Starshield Reserved Bandwidth (Gbps)", Starlink!$A:$A, 0)) -> 70.502058 | I14: =INDEX(Starlink!I:I, MATCH("Starshield Reserved Bandwidth (Gbps)", Starlink!$A:$A, 0)) -> 52.049737 | J14: =INDEX(Starlink!J:J, MATCH("Starshield Reserved Bandwidth (Gbps)", Starlink!$A:$A, 0)) -> 49.618752 | K14: =INDEX(Starlink!K:K, MATCH("Starshield Reserved Bandwidth (Gbps)", Starlink!$A:$A, 0)) -> 47.186132 | L14: =INDEX(Starlink!L:L, MATCH("Starshield Reserved Bandwidth (Gbps)", Starlink!$A:$A, 0)) -> 45.160773 | M14: =INDEX(Starlink!M:M, MATCH("Starshield Reserved Bandwidth (Gbps)", Starlink!$A:$A, 0)) -> 44.031787 | N14: =INDEX(Starlink!N:N, MATCH("Starshield Reserved Bandwidth (Gbps)", Starlink!$A:$A, 0)) -> 44.261434 | O14: =INDEX(Starlink!O:O, MATCH("Starshield Reserved Bandwidth (Gbps)", Starlink!$A:$A, 0)) -> 45.041843 | P14: =INDEX(Starlink!P:P, MATCH("Starshield Reserved Bandwidth (Gbps)", Starlink!$A:$A, 0)) -> 46.570114 | Q14: =INDEX(Starlink!Q:Q, MATCH("Starshield Reserved Bandwidth (Gbps)", Starlink!$A:$A, 0)) -> 48.612799 | R14: =INDEX(Starlink!R:R, MATCH("Starshield Reserved Bandwidth (Gbps)", Starlink!$A:$A, 0)) -> 50.944574 | S14: =INDEX(Starlink!S:S, MATCH("Starshield Reserved Bandwidth (Gbps)", Starlink!$A:$A, 0)) -> 53.579267 | T14: =INDEX(Starlink!T:T, MATCH("Starshield Reserved Bandwidth (Gbps)", Starlink!$A:$A, 0)) -> 74.514062 | U14: =INDEX(Starlink!U:U, MATCH("Starshield Reserved Bandwidth (Gbps)", Starlink!$A:$A, 0)) -> 77.356313 | V14: =INDEX(Starlink!V:V, MATCH("Starshield Reserved Bandwidth (Gbps)", Starlink!$A:$A, 0)) -> 80.196599 | W14: =INDEX(Starlink!W:W, MATCH("Starshield Reserved Bandwidth (Gbps)", Starlink!$A:$A, 0)) -> 82.9847 | X14: =INDEX(Starlink!X:X, MATCH("Starshield Reserved Bandwidth (Gbps)", Starlink!$A:$A, 0)) -> 85.482505 | Y14: =INDEX(Starlink!Y:Y, MATCH("Starshield Reserved Bandwidth (Gbps)", Starlink!$A:$A, 0)) -> 94.528273 | Z14: =INDEX(Starlink!Z:Z, MATCH("Starshield Reserved Bandwidth (Gbps)", Starlink!$A:$A, 0)) -> 103.92578 | AA14: =INDEX(Starlink!AA:AA, MATCH("Starshield Reserved Bandwidth (Gbps)", Starlink!$A:$A, 0)) -> 113.69487 | AB14: =INDEX(Starlink!AB:AB, MATCH("Starshield Reserved Bandwidth (Gbps)", Starlink!$A:$A, 0)) -> 123.2094 | AC14: =INDEX(Starlink!AC:AC, MATCH("Starshield Reserved Bandwidth (Gbps)", Starlink!$A:$A, 0)) -> 133.13125
