Workbook

Sheet Assumptions
A1: 0.01 | D1: 2025 | E1: 2026 | F1: 2027 | G1: 2028 | H1: 2029 | I1: 2030 | J1: 2031 | K1: 2032 | L1: 2033 | M1: 2034 | N1: 2035 | O1: 2036 | P1: 2037 | Q1: 2038 | R1: 2039 | S1: 2040
A2: GLOBAL | D2: 0 | E2: 1 | F2: 2 | G2: 3 | H2: 4 | I2: 5 | J2: 6 | K2: 7 | L2: 8 | M2: 9 | N2: 10 | O2: 11 | P2: 12 | Q2: 13 | R2: 14 | S2: 15
A3: Tax rate (corporate, US federal + state blended) | B3: 0.21 | C3: Standard US corporate rate; S-1 silent on effective rate split. | W3: 0.18 | X3: 0.27 | Y3: triangle
A4: Demand curve escalator: start rate (annual) | B4: 0.035 | C4: Early willingness-to-pay growth above inflation. | D4: 2025 | E4: 2026 | F4: 2027 | G4: 2028 | H4: 2029 | I4: 2030 | J4: 2031 | K4: 2032 | L4: 2033 | M4: 2034 | N4: 2035 | O4: 2036 | P4: 2037 | Q4: 2038 | R4: 2039 | S4: 2040 | W4: 0.025 | X4: 0.05 | Y4: triangle
A5: Demand curve escalator: terminal rate (annual) | B5: 0.025 | C5: Mature-market escalator ≈ inflation. The tapered curve converges here after the taper ends. | D5: 0 | E5: 1 | F5: 2 | G5: 3 | H5: 4 | I5: 5 | J5: 6 | K5: 7 | L5: 8 | M5: 9 | N5: 10 | O5: 11 | P5: 12 | Q5: 13 | R5: 14 | S5: 15 | W5: 0.02 | X5: 0.03 | Y5: triangle
A6: ALLOCATOR
A7: ▸ Cash pool boundary inputs
A8: IPO injection amount ($mm) | B8: 75000 | C8: IPO proceeds target not disclosed; placeholder.
A9: IPO injection year | B9: 2027 | W9: 2026 | X9: 2028 | Y9: discrete
A10: ▸ Lunar/Mars strategic carve-out (Monte Carlo variable)
A11: Lunar/Mars carve-out % of prior-year Group FCF | B11: 0.15 | W11: 0.03 | X11: 0.35 | Y11: triangle
A12: Lunar/Mars carve-out floor ($mm/yr) | B12: 1000 | C12: Floor below which carve-out doesn't drop even if prior FCF is small. | W12: 500 | X12: 2500 | Y12: triangle
A13: Lunar/Mars carve-out uses prior-year FCF (0/1) | B13: 1 | C13: 1 = prior year (breaks circularity per Principle 22). Structural input. | Y13: fixed
A14: Lunar/Mars carve-out pre-first-mission-year R&D-only override ($mm/yr) | B14: 750 | W14: 500 | X14: 1000 | Y14: triangle
A15: ▸ IRR-weighted allocation parameters
A16: Allocation sharpness β (top-level 3-module blend) | B16: 3 | W16: 1 | X16: 10 | Y16: triangle
A17: ▸ Per-module asset life L (canonical IRR formula input)
A18: Asset life L: Customer Launch Starship (years) | B18: 8 | C18: F9 booster analog (lifetime reuses ramp). | W18: 6 | X18: 10 | Y18: triangle
A19: Asset life L: Customer Launch F9 (years) | B19: 8 | C19: Customer Launch IRR anchor. | W19: 6 | X19: 10 | Y19: triangle
A20: Asset life L: AI/Compute Orbital DC (years) | B20: 5 | C20: Sat-based; matches Starlink sat life. | W20: 4 | X20: 7 | Y20: triangle
A21: Asset life L: AI/Compute Terrestrial DC (years) | B21: 15 | C21: Industry norm for DC infrastructure. | W21: 10 | X21: 20 | Y21: triangle
A22: Asset life L: AI/Compute AI Apps (years) | B22: 3 | C22: Customer subscription life / CAC payback. | W22: 2 | X22: 5 | Y22: triangle
A23: ▸ Customer Launch IRR life clamps
A24: ▸ Vehicle build claim (demand-pulled, one-period lag)
A25: CAPACITY (Starship + F9)
A26: ▸ Starship vehicle physical + cost parameters
A27: Starship 2nd-stage manufacturing cost ($mm/unit, base) | B27: 23.4 | C27: Reusability matrix anchor. | W27: 18 | X27: 30 | Y27: triangle
A28: Ship refurb % of manufacturing | B28: 0.02 | C28: Per-reuse refurb cost. | W28: 0.01 | X28: 0.05 | Y28: triangle
A29: Payload: booster-only mode (kg-to-LEO) | B29: 150000 | C29: Expendable ship config. S-1 (p.92) confirms 100 mt V3 → 200 mt V4 potentially. 150K kg booster-only sits between V3 and V4. | W29: 130000 | X29: 200000 | Y29: triangle
A30: Payload: fully reusable mode (kg-to-LEO) | B30: 100000 | C30: S-1 p.92 EXPLICIT: V3 design 100 mt. Match. | W30: 80000 | X30: 150000 | Y30: triangle
A31: ▸ Starship cadence (Wright's Law on cum upmass)
A32: Base turnaround time per booster (years/flight) | B32: 1 | C32: 2025 starting point. | W32: 0.8 | X32: 1.5 | Y32: triangle
A33: WL learning rate: turnaround vs cum upmass doubling | B33: 0.21 | C33: Booster learning rate (0.21). Cumulative experience compounds faster than an annual proxy. Monte Carlo range 0.15–0.28. Holds the rising 6→~22 booster cadence ramp. | W33: 0.05 | X33: 0.25 | Y33: triangle
A34: Cadence ceiling (flights/booster/year) | B34: 60 | C34: Physical refly ceiling at full maturity. | W34: 40 | X34: 100 | Y34: triangle
A35: ▸ Starship time-varying inputs (year-rows)
A36: Lifetime reuses per booster (year cap) | C36: Ramps 5 → 100. S-1 anchors F9 at 34x (p.4); soft-anchor 2025 to ~30-35 for F9-class maturity. | D36: =5*$B$481 -> 5 | E36: =8*$B$481 -> 8 | F36: =12*$B$481 -> 12 | G36: =18*$B$481 -> 18 | H36: =25*$B$481 -> 25 | I36: =30*$B$481 -> 30 | J36: =35*$B$481 -> 35 | K36: =42*$B$481 -> 42 | L36: =50*$B$481 -> 50 | M36: =58*$B$481 -> 58 | N36: =65*$B$481 -> 65 | O36: =70*$B$481 -> 70 | P36: =75*$B$481 -> 75 | Q36: =80*$B$481 -> 80 | R36: =85*$B$481 -> 85 | S36: =90*$B$481 -> 90 | Y36: fixed-yearrow
A37: ▸ Falcon 9 physical + cost parameters
A38: F9 booster (1st stage) mfg cost ($mm/unit) | B38: 30 | C38: 60% of total per reusability matrix source notes. S-1 silent. | W38: 25 | X38: 35 | Y38: triangle
A39: F9 2nd stage mfg cost ($mm/unit) | B39: 10 | C39: Expendable each flight. | W39: 8 | X39: 13 | Y39: triangle
A40: F9 fairing cost net of 75% recovery ($mm/flight) | B40: 1.25 | C40: $5M × 25% non-recovered. | W40: 1 | X40: 2 | Y40: triangle
...

Sheet Demand Curves
A1: Demand Curves: Starlink BB + DTC piecewise-linear lookup
A2: Lookup form: INDEX/MATCH(..., 1) bracket-find + manual linear interp. NO FORECAST / TREND. Per Memory Snapshot v3 §2.4.
D4: 2025 | E4: 2026 | F4: 2027 | G4: 2028 | H4: 2029 | I4: 2030 | J4: 2031 | K4: 2032 | L4: 2033 | M4: 2034 | N4: 2035 | O4: 2036 | P4: 2037 | Q4: 2038 | R4: 2039 | S4: 2040
D5: 0 | E5: 1 | F5: 2 | G5: 3 | H5: 4 | I5: 5 | J5: 6 | K5: 7 | L5: 8 | M5: 9 | N5: 10 | O5: 11 | P5: 12 | Q5: 13 | R5: 14 | S5: 15
A15: DTC DEMAND CURVE (piecewise-linear Q→Revenue lookup)
A16: Constellation Bandwidth (Gbps) | B16: Q (Gbps) | C16: Annual DTC Revenue ($mm)
A17: DTC Q breakpoint #1 (Gbps) | B17: 280.2 | C17: 307
A18: DTC Q breakpoint #2 (Gbps) | B18: 560.3 | C18: 613
A19: DTC Q breakpoint #3 (Gbps) | B19: 840.5 | C19: 920
A20: DTC Q breakpoint #4 (Gbps) | B20: 1120.6 | C20: 1227
A21: DTC Q breakpoint #5 (Gbps) | B21: 1400.8 | C21: 1534
A22: DTC Q breakpoint #6 (Gbps) | B22: 1680.9 | C22: 1840
A23: DTC Q breakpoint #7 (Gbps) | B23: 1961.1 | C23: 2147
A24: DTC Q breakpoint #8 (Gbps) | B24: 2241.2 | C24: 2454
A25: DTC Q breakpoint #9 (Gbps) | B25: 2521.4 | C25: 2760
A26: DTC Q breakpoint #10 (Gbps) | B26: 2801.5 | C26: 3067
A27: DTC Q breakpoint #11 (Gbps) | B27: 3501.9 | C27: 3827
A28: DTC Q breakpoint #12 (Gbps) | B28: 4202.3 | C28: 4587
... A77: DTC Q breakpoint #61 (Gbps) | B77: 84046.3 | C77: 15920
A80: BB DEMAND CURVE (piecewise-linear Q→Revenue lookup)
A81: Capacity (Gbps) | B81: Q (Gbps) | C81: BB TAM/Revenue ($mm)
A82: BB Q breakpoint #1 (Gbps) | B82: 100000 | C82: 2936
A83: BB Q breakpoint #2 (Gbps) | B83: 200000 | C83: 3748
A84: BB Q breakpoint #3 (Gbps) | B84: 300000 | C84: 4559
A85: BB Q breakpoint #4 (Gbps) | B85: 400000 | C85: 5370
A86: BB Q breakpoint #5 (Gbps) | B86: 500000 | C86: 6157
A87: BB Q breakpoint #6 (Gbps) | B87: 1000000 | C87: 10055
A88: BB Q breakpoint #7 (Gbps) | B88: 2000000 | C88: 17173
A89: BB Q breakpoint #8 (Gbps) | B89: 3000000 | C89: 23037
A90: BB Q breakpoint #9 (Gbps) | B90: 4000000 | C90: 28430
A91: BB Q breakpoint #10 (Gbps) | B91: 5000000 | C91: 33451
A92: BB Q breakpoint #11 (Gbps) | B92: 6000000 | C92: 38244
A93: BB Q breakpoint #12 (Gbps) | B93: 7000000 | C93: 42520
... A137: BB Q breakpoint #56 (Gbps) | B137: 250000000 | C137: 187819
A140: ▸ Curve evaluators (year-row, read by the Starlink module)
A141: Annual TAM shift multiplier | D141: =1 -> 1 | E141: =D141*(1+E149) -> 1.035 | F141: =E141*(1+F149) -> 1.070075 | G141: =F141*(1+G149) -> 1.1051497 | H141: =G141*(1+H149) -> 1.1401461 | I141: =H141*(1+I149) -> 1.1749839 | J141: =I141*(1+J149) -> 1.2095806 | K141: =J141*(1+K149) -> 1.2438521 | L141: =K141*(1+L149) -> 1.2777125 | ... S141: =R141*(1+S149) -> 1.520445
A142: Starlink BB capacity input (Gbps) | D142: {=IFERROR(INDEX(Starlink!$D:$AC,MATCH("BB Gbps available for external Starlink revenue",Starlink!$A$1:$A$204,0),COLUMN()-COLUMN($D142)+1),0)} -> 489144 | E142: {=IFERROR(INDEX(Starlink!$D:$AC,MATCH("BB Gbps available for external Starlink revenue",Starlink!$A$1:$A$204,0),COLUMN()-COLUMN($D142)+1),0)} -> 756736 | F142: {=IFERROR(INDEX(Starlink!$D:$AC,MATCH("BB Gbps available for external Starlink revenue",Starlink!$A$1:$A$204,0),COLUMN()-COLUMN($D142)+1),0)} -> 4652053.4 | G142: {=IFERROR(INDEX(Starlink!$D:$AC,MATCH("BB Gbps available for external Starlink revenue",Starlink!$A$1:$A$204,0),COLUMN()-COLUMN($D142)+1),0)} -> 13909825 | H142: {=IFERROR(INDEX(Starlink!$D:$AC,MATCH("BB Gbps available for external Starlink revenue",Starlink!$A$1:$A$204,0),COLUMN()-COLUMN($D142)+1),0)} -> 37706339 | I142: {=IFERROR(INDEX(Starlink!$D:$AC,MATCH("BB Gbps available for external Starlink revenue",Starlink!$A$1:$A$204,0),COLUMN()-COLUMN($D142)+1),0)} -> 52599406 | J142: {=IFERROR(INDEX(Starlink!$D:$AC,MATCH("BB Gbps available for external Starlink revenue",Starlink!$A$1:$A$204,0),COLUMN()-COLUMN($D142)+1),0)} -> 81246796 | K142: {=IFERROR(INDEX(Starlink!$D:$AC,MATCH("BB Gbps available for external Starlink revenue",Starlink!$A$1:$A$204,0),COLUMN()-COLUMN($D142)+1),0)} -> 93730001 | ... S142: {=IFERROR(INDEX(Starlink!$D:$AC,MATCH("BB Gbps available for external Starlink revenue",Starlink!$A$1:$A$204,0),COLUMN()-COLUMN($D142)+1),0)} -> 1.8886232e+08
A143: Starlink DTC capacity input (Gbps) | D143: {=IFERROR(INDEX(Starlink!$D:$AC,MATCH("DTC Gbps available for external Starlink revenue",Starlink!$A$1:$A$204,0),COLUMN()-COLUMN($D143)+1),0)} -> 577.71 | E143: {=IFERROR(INDEX(Starlink!$D:$AC,MATCH("DTC Gbps available for external Starlink revenue",Starlink!$A$1:$A$204,0),COLUMN()-COLUMN($D143)+1),0)} -> 577.71 | F143: {=IFERROR(INDEX(Starlink!$D:$AC,MATCH("DTC Gbps available for external Starlink revenue",Starlink!$A$1:$A$204,0),COLUMN()-COLUMN($D143)+1),0)} -> 579.3698 | G143: {=IFERROR(INDEX(Starlink!$D:$AC,MATCH("DTC Gbps available for external Starlink revenue",Starlink!$A$1:$A$204,0),COLUMN()-COLUMN($D143)+1),0)} -> 649.95121 | H143: {=IFERROR(INDEX(Starlink!$D:$AC,MATCH("DTC Gbps available for external Starlink revenue",Starlink!$A$1:$A$204,0),COLUMN()-COLUMN($D143)+1),0)} -> 3085.5434 | I143: {=IFERROR(INDEX(Starlink!$D:$AC,MATCH("DTC Gbps available for external Starlink revenue",Starlink!$A$1:$A$204,0),COLUMN()-COLUMN($D143)+1),0)} -> 33938.701 | J143: {=IFERROR(INDEX(Starlink!$D:$AC,MATCH("DTC Gbps available for external Starlink revenue",Starlink!$A$1:$A$204,0),COLUMN()-COLUMN($D143)+1),0)} -> 55683.285 | K143: {=IFERROR(INDEX(Starlink!$D:$AC,MATCH("DTC Gbps available for external Starlink revenue",Starlink!$A$1:$A$204,0),COLUMN()-COLUMN($D143)+1),0)} -> 97088.151 | ... S143: {=IFERROR(INDEX(Starlink!$D:$AC,MATCH("DTC Gbps available for external Starlink revenue",Starlink!$A$1:$A$204,0),COLUMN()-COLUMN($D143)+1),0)} -> 134521.12
A144: Starlink BB Revenue from curve ($mm) | D144: {=((IF(D142>=INDEX($B$82:$B$137,COUNTA($B$82:$B$137)),INDEX($C$82:$C$137,COUNTA($B$82:$B$137))*D141,IF(D142<=INDEX($B$82:$B$137,1),INDEX($C$82:$C$137,1)*D141,(INDEX($C$82:$C$137,MATCH(D142,$B$82:$B$137,1))+(D142-INDEX($B$82:$B$137,MATCH(D142,$B$82:$B$137,1)))*(INDEX($C$82:$C$137,MATCH(D142,$B$82:$B$137,1)+1)-INDEX($C$82:$C$137,MATCH(D142,$B$82:$B$137,1)))/(INDEX($B$82:$B$137,MATCH(D142,$B$82:$B$137,1)+1)-INDEX($B$82:$B$137,MATCH(D142,$B$82:$B$137,1))))*D141)))*INDEX(Assumptions!$B:$B,MATCH("BB demand curve level multiplier",Assumptions!$A$1:$A$257,0)))*D151} -> 6721.2206 | E144: {=((IF(E142>=INDEX($B$82:$B$137,COUNTA($B$82:$B$137)),INDEX($C$82:$C$137,COUNTA($B$82:$B$137))*E141,IF(E142<=INDEX($B$82:$B$137,1),INDEX($C$82:$C$137,1)*E141,(INDEX($C$82:$C$137,MATCH(E142,$B$82:$B$137,1))+(E142-INDEX($B$82:$B$137,MATCH(E142,$B$82:$B$137,1)))*(INDEX($C$82:$C$137,MATCH(E142,$B$82:$B$137,1)+1)-INDEX($C$82:$C$137,MATCH(E142,$B$82:$B$137,1)))/(INDEX($B$82:$B$137,MATCH(E142,$B$82:$B$137,1)+1)-INDEX($B$82:$B$137,MATCH(E142,$B$82:$B$137,1))))*E141)))*INDEX(Assumptions!$B:$B,MATCH("BB demand curve level multiplier",Assumptions!$A$1:$A$257,0)))*E151} -> 9347.5765 | F144: {=((IF(F142>=INDEX($B$82:$B$137,COUNTA($B$82:$B$137)),INDEX($C$82:$C$137,COUNTA($B$82:$B$137))*F141,IF(F142<=INDEX($B$82:$B$137,1),INDEX($C$82:$C$137,1)*F141,(INDEX($C$82:$C$137,MATCH(F142,$B$82:$B$137,1))+(F142-INDEX($B$82:$B$137,MATCH(F142,$B$82:$B$137,1)))*(INDEX($C$82:$C$137,MATCH(F142,$B$82:$B$137,1)+1)-INDEX($C$82:$C$137,MATCH(F142,$B$82:$B$137,1)))/(INDEX($B$82:$B$137,MATCH(F142,$B$82:$B$137,1)+1)-INDEX($B$82:$B$137,MATCH(F142,$B$82:$B$137,1))))*F141)))*INDEX(Assumptions!$B:$B,MATCH("BB demand curve level multiplier",Assumptions!$A$1:$A$257,0)))*F151} -> 37555.656 | G144: {=((IF(G142>=INDEX($B$82:$B$137,COUNTA($B$82:$B$137)),INDEX($C$82:$C$137,COUNTA($B$82:$B$137))*G141,IF(G142<=INDEX($B$82:$B$137,1),INDEX($C$82:$C$137,1)*G141,(INDEX($C$82:$C$137,MATCH(G142,$B$82:$B$137,1))+(G142-INDEX($B$82:$B$137,MATCH(G142,$B$82:$B$137,1)))*(INDEX($C$82:$C$137,MATCH(G142,$B$82:$B$137,1)+1)-INDEX($C$82:$C$137,MATCH(G142,$B$82:$B$137,1)))/(INDEX($B$82:$B$137,MATCH(G142,$B$82:$B$137,1)+1)-INDEX($B$82:$B$137,MATCH(G142,$B$82:$B$137,1))))*G141)))*INDEX(Assumptions!$B:$B,MATCH("BB demand curve level multiplier",Assumptions!$A$1:$A$257,0)))*G151} -> 80517.71 | H144: {=((IF(H142>=INDEX($B$82:$B$137,COUNTA($B$82:$B$137)),INDEX($C$82:$C$137,COUNTA($B$82:$B$137))*H141,IF(H142<=INDEX($B$82:$B$137,1),INDEX($C$82:$C$137,1)*H141,(INDEX($C$82:$C$137,MATCH(H142,$B$82:$B$137,1))+(H142-INDEX($B$82:$B$137,MATCH(H142,$B$82:$B$137,1)))*(INDEX($C$82:$C$137,MATCH(H142,$B$82:$B$137,1)+1)-INDEX($C$82:$C$137,MATCH(H142,$B$82:$B$137,1)))/(INDEX($B$82:$B$137,MATCH(H142,$B$82:$B$137,1)+1)-INDEX($B$82:$B$137,MATCH(H142,$B$82:$B$137,1))))*H141)))*INDEX(Assumptions!$B:$B,MATCH("BB demand curve level multiplier",Assumptions!$A$1:$A$257,0)))*H151} -> 141004.93 | I144: {=((IF(I142>=INDEX($B$82:$B$137,COUNTA($B$82:$B$137)),INDEX($C$82:$C$137,COUNTA($B$82:$B$137))*I141,IF(I142<=INDEX($B$82:$B$137,1),INDEX($C$82:$C$137,1)*I141,(INDEX($C$82:$C$137,MATCH(I142,$B$82:$B$137,1))+(I142-INDEX($B$82:$B$137,MATCH(I142,$B$82:$B$137,1)))*(INDEX($C$82:$C$137,MATCH(I142,$B$82:$B$137,1)+1)-INDEX($C$82:$C$137,MATCH(I142,$B$82:$B$137,1)))/(INDEX($B$82:$B$137,MATCH(I142,$B$82:$B$137,1)+1)-INDEX($B$82:$B$137,MATCH(I142,$B$82:$B$137,1))))*I141)))*INDEX(Assumptions!$B:$B,MATCH("BB demand curve level multiplier",Assumptions!$A$1:$A$257,0)))*I151} -> 172279.32 | J144: {=((IF(J142>=INDEX($B$82:$B$137,COUNTA($B$82:$B$137)),INDEX($C$82:$C$137,COUNTA($B$82:$B$137))*J141,IF(J142<=INDEX($B$82:$B$137,1),INDEX($C$82:$C$137,1)*J141,(INDEX($C$82:$C$137,MATCH(J142,$B$82:$B$137,1))+(J142-INDEX($B$82:$B$137,MATCH(J142,$B$82:$B$137,1)))*(INDEX($C$82:$C$137,MATCH(J142,$B$82:$B$137,1)+1)-INDEX($C$82:$C$137,MATCH(J142,$B$82:$B$137,1)))/(INDEX($B$82:$B$137,MATCH(J142,$B$82:$B$137,1)+1)-INDEX($B$82:$B$137,MATCH(J142,$B$82:$B$137,1))))*J141)))*INDEX(Assumptions!$B:$B,MATCH("BB demand curve level multiplier",Assumptions!$A$1:$A$257,0)))*J151} -> 205461.3 | K144: {=((IF(K142>=INDEX($B$82:$B$137,COUNTA($B$82:$B$137)),INDEX($C$82:$C$137,COUNTA($B$82:$B$137))*K141,IF(K142<=INDEX($B$82:$B$137,1),INDEX($C$82:$C$137,1)*K141,(INDEX($C$82:$C$137,MATCH(K142,$B$82:$B$137,1))+(K142-INDEX($B$82:$B$137,MATCH(K142,$B$82:$B$137,1)))*(INDEX($C$82:$C$137,MATCH(K142,$B$82:$B$137,1)+1)-INDEX($C$82:$C$137,MATCH(K142,$B$82:$B$137,1)))/(INDEX($B$82:$B$137,MATCH(K142,$B$82:$B$137,1)+1)-INDEX($B$82:$B$137,MATCH(K142,$B$82:$B$137,1))))*K141)))*INDEX(Assumptions!$B:$B,MATCH("BB demand curve level multiplier",Assumptions!$A$1:$A$257,0)))*K151} -> 221249.49 | ... S144: {=((IF(S142>=INDEX($B$82:$B$137,COUNTA($B$82:$B$137)),INDEX($C$82:$C$137,COUNTA($B$82:$B$137))*S141,IF(S142<=INDEX($B$82:$B$137,1),INDEX($C$82:$C$137,1)*S141,(INDEX($C$82:$C$137,MATCH(S142,$B$82:$B$137,1))+(S142-INDEX($B$82:$B$137,MATCH(S142,$B$82:$B$137,1)))*(INDEX($C$82:$C$137,MATCH(S142,$B$82:$B$137,1)+1)-INDEX($C$82:$C$137,MATCH(S142,$B$82:$B$137,1)))/(INDEX($B$82:$B$137,MATCH(S142,$B$82:$B$137,1)+1)-INDEX($B$82:$B$137,MATCH(S142,$B$82:$B$137,1))))*S141)))*INDEX(Assumptions!$B:$B,MATCH("BB demand curve level multiplier",Assumptions!$A$1:$A$257,0)))*S151} -> 304575.99
A145: Starlink DTC Revenue from curve ($mm) | D145: {=((IF(D143<=0,0,IF(D143>=INDEX($B$17:$B$77,COUNTA($B$17:$B$77)),INDEX($C$17:$C$77,COUNTA($B$17:$B$77))*D141,IF(D143<INDEX($B$17:$B$77,1),D143/INDEX($B$17:$B$77,1)*INDEX($C$17:$C$77,1)*D141,(INDEX($C$17:$C$77,MATCH(D143,$B$17:$B$77,1))+(D143-INDEX($B$17:$B$77,MATCH(D143,$B$17:$B$77,1)))*(INDEX($C$17:$C$77,MATCH(D143,$B$17:$B$77,1)+1)-INDEX($C$17:$C$77,MATCH(D143,$B$17:$B$77,1)))/(INDEX($B$17:$B$77,MATCH(D143,$B$17:$B$77,1)+1)-INDEX($B$17:$B$77,MATCH(D143,$B$17:$B$77,1))))*D141))))*INDEX(Assumptions!$B:$B,MATCH("DTC demand curve level multiplier",Assumptions!$A$1:$A$257,0)))*D150} -> 632.0752 | E145: {=((IF(E143<=0,0,IF(E143>=INDEX($B$17:$B$77,COUNTA($B$17:$B$77)),INDEX($C$17:$C$77,COUNTA($B$17:$B$77))*E141,IF(E143<INDEX($B$17:$B$77,1),E143/INDEX($B$17:$B$77,1)*INDEX($C$17:$C$77,1)*E141,(INDEX($C$17:$C$77,MATCH(E143,$B$17:$B$77,1))+(E143-INDEX($B$17:$B$77,MATCH(E143,$B$17:$B$77,1)))*(INDEX($C$17:$C$77,MATCH(E143,$B$17:$B$77,1)+1)-INDEX($C$17:$C$77,MATCH(E143,$B$17:$B$77,1)))/(INDEX($B$17:$B$77,MATCH(E143,$B$17:$B$77,1)+1)-INDEX($B$17:$B$77,MATCH(E143,$B$17:$B$77,1))))*E141))))*INDEX(Assumptions!$B:$B,MATCH("DTC demand curve level multiplier",Assumptions!$A$1:$A$257,0)))*E150} -> 794.38308 | F145: {=((IF(F143<=0,0,IF(F143>=INDEX($B$17:$B$77,COUNTA($B$17:$B$77)),INDEX($C$17:$C$77,COUNTA($B$17:$B$77))*F141,IF(F143<INDEX($B$17:$B$77,1),F143/INDEX($B$17:$B$77,1)*INDEX($C$17:$C$77,1)*F141,(INDEX($C$17:$C$77,MATCH(F143,$B$17:$B$77,1))+(F143-INDEX($B$17:$B$77,MATCH(F143,$B$17:$B$77,1)))*(INDEX($C$17:$C$77,MATCH(F143,$B$17:$B$77,1)+1)-INDEX($C$17:$C$77,MATCH(F143,$B$17:$B$77,1)))/(INDEX($B$17:$B$77,MATCH(F143,$B$17:$B$77,1)+1)-INDEX($B$17:$B$77,MATCH(F143,$B$17:$B$77,1))))*F141))))*INDEX(Assumptions!$B:$B,MATCH("DTC demand curve level multiplier",Assumptions!$A$1:$A$257,0)))*F150} -> 969.01979 | G145: {=((IF(G143<=0,0,IF(G143>=INDEX($B$17:$B$77,COUNTA($B$17:$B$77)),INDEX($C$17:$C$77,COUNTA($B$17:$B$77))*G141,IF(G143<INDEX($B$17:$B$77,1),G143/INDEX($B$17:$B$77,1)*INDEX($C$17:$C$77,1)*G141,(INDEX($C$17:$C$77,MATCH(G143,$B$17:$B$77,1))+(G143-INDEX($B$17:$B$77,MATCH(G143,$B$17:$B$77,1)))*(INDEX($C$17:$C$77,MATCH(G143,$B$17:$B$77,1)+1)-INDEX($C$17:$C$77,MATCH(G143,$B$17:$B$77,1)))/(INDEX($B$17:$B$77,MATCH(G143,$B$17:$B$77,1)+1)-INDEX($B$17:$B$77,MATCH(G143,$B$17:$B$77,1))))*G141))))*INDEX(Assumptions!$B:$B,MATCH("DTC demand curve level multiplier",Assumptions!$A$1:$A$257,0)))*G150} -> 1291.3041 | H145: {=((IF(H143<=0,0,IF(H143>=INDEX($B$17:$B$77,COUNTA($B$17:$B$77)),INDEX($C$17:$C$77,COUNTA($B$17:$B$77))*H141,IF(H143<INDEX($B$17:$B$77,1),H143/INDEX($B$17:$B$77,1)*INDEX($C$17:$C$77,1)*H141,(INDEX($C$17:$C$77,MATCH(H143,$B$17:$B$77,1))+(H143-INDEX($B$17:$B$77,MATCH(H143,$B$17:$B$77,1)))*(INDEX($C$17:$C$77,MATCH(H143,$B$17:$B$77,1)+1)-INDEX($C$17:$C$77,MATCH(H143,$B$17:$B$77,1)))/(INDEX($B$17:$B$77,MATCH(H143,$B$17:$B$77,1)+1)-INDEX($B$17:$B$77,MATCH(H143,$B$17:$B$77,1))))*H141))))*INDEX(Assumptions!$B:$B,MATCH("DTC demand curve level multiplier",Assumptions!$A$1:$A$257,0)))*H150} -> 7146.7257 | I145: {=((IF(I143<=0,0,IF(I143>=INDEX($B$17:$B$77,COUNTA($B$17:$B$77)),INDEX($C$17:$C$77,COUNTA($B$17:$B$77))*I141,IF(I143<INDEX($B$17:$B$77,1),I143/INDEX($B$17:$B$77,1)*INDEX($C$17:$C$77,1)*I141,(INDEX($C$17:$C$77,MATCH(I143,$B$17:$B$77,1))+(I143-INDEX($B$17:$B$77,MATCH(I143,$B$17:$B$77,1)))*(INDEX($C$17:$C$77,MATCH(I143,$B$17:$B$77,1)+1)-INDEX($C$17:$C$77,MATCH(I143,$B$17:$B$77,1)))/(INDEX($B$17:$B$77,MATCH(I143,$B$17:$B$77,1)+1)-INDEX($B$17:$B$77,MATCH(I143,$B$17:$B$77,1))))*I141))))*INDEX(Assumptions!$B:$B,MATCH("DTC demand curve level multiplier",Assumptions!$A$1:$A$257,0)))*I150} -> 33355.216 | J145: {=((IF(J143<=0,0,IF(J143>=INDEX($B$17:$B$77,COUNTA($B$17:$B$77)),INDEX($C$17:$C$77,COUNTA($B$17:$B$77))*J141,IF(J143<INDEX($B$17:$B$77,1),J143/INDEX($B$17:$B$77,1)*INDEX($C$17:$C$77,1)*J141,(INDEX($C$17:$C$77,MATCH(J143,$B$17:$B$77,1))+(J143-INDEX($B$17:$B$77,MATCH(J143,$B$17:$B$77,1)))*(INDEX($C$17:$C$77,MATCH(J143,$B$17:$B$77,1)+1)-INDEX($C$17:$C$77,MATCH(J143,$B$17:$B$77,1)))/(INDEX($B$17:$B$77,MATCH(J143,$B$17:$B$77,1)+1)-INDEX($B$17:$B$77,MATCH(J143,$B$17:$B$77,1))))*J141))))*INDEX(Assumptions!$B:$B,MATCH("DTC demand curve level multiplier",Assumptions!$A$1:$A$257,0)))*J150} -> 41028.563 | K145: {=((IF(K143<=0,0,IF(K143>=INDEX($B$17:$B$77,COUNTA($B$17:$B$77)),INDEX($C$17:$C$77,COUNTA($B$17:$B$77))*K141,IF(K143<INDEX($B$17:$B$77,1),K143/INDEX($B$17:$B$77,1)*INDEX($C$17:$C$77,1)*K141,(INDEX($C$17:$C$77,MATCH(K143,$B$17:$B$77,1))+(K143-INDEX($B$17:$B$77,MATCH(K143,$B$17:$B$77,1)))*(INDEX($C$17:$C$77,MATCH(K143,$B$17:$B$77,1)+1)-INDEX($C$17:$C$77,MATCH(K143,$B$17:$B$77,1)))/(INDEX($B$17:$B$77,MATCH(K143,$B$17:$B$77,1)+1)-INDEX($B$17:$B$77,MATCH(K143,$B$17:$B$77,1))))*K141))))*INDEX(Assumptions!$B:$B,MATCH("DTC demand curve level multiplier",Assumptions!$A$1:$A$257,0)))*K150} -> 49505.313 | ... S145: {=((IF(S143<=0,0,IF(S143>=INDEX($B$17:$B$77,COUNTA($B$17:$B$77)),INDEX($C$17:$C$77,COUNTA($B$17:$B$77))*S141,IF(S143<INDEX($B$17:$B$77,1),S143/INDEX($B$17:$B$77,1)*INDEX($C$17:$C$77,1)*S141,(INDEX($C$17:$C$77,MATCH(S143,$B$17:$B$77,1))+(S143-INDEX($B$17:$B$77,MATCH(S143,$B$17:$B$77,1)))*(INDEX($C$17:$C$77,MATCH(S143,$B$17:$B$77,1)+1)-INDEX($C$17:$C$77,MATCH(S143,$B$17:$B$77,1)))/(INDEX($B$17:$B$77,MATCH(S143,$B$17:$B$77,1)+1)-INDEX($B$17:$B$77,MATCH(S143,$B$17:$B$77,1))))*S141))))*INDEX(Assumptions!$B:$B,MATCH("DTC demand curve level multiplier",Assumptions!$A$1:$A$257,0)))*S150} -> 60513.713
...

Sheet Starlink
A1: Starlink module — real cohorts + total-bandwidth revenue + full waterfall + 4-line OpEx + per-sat IRR
D4: 2025 | E4: 2026 | F4: 2027 | G4: 2028 | H4: 2029 | I4: 2030 | J4: 2031 | K4: 2032 | L4: 2033 | M4: 2034 | N4: 2035 | O4: 2036 | P4: 2037 | Q4: 2038 | R4: 2039 | S4: 2040
D5: 0 | E5: 1 | F5: 2 | G5: 3 | H5: 4 | I5: 5 | J5: 6 | K5: 7 | L5: 8 | M5: 9 | N5: 10 | O5: 11 | P5: 12 | Q5: 13 | R5: 14 | S5: 15
A10: ▸ ALLOCATOR IN (cross-tab reads)
A11: Starlink BB Revenue from curve ($mm) | D11: {=INDEX('Demand Curves'!$D:$AC, MATCH("Starlink BB Revenue from curve ($mm)", 'Demand Curves'!$A$1:$A$167, 0), COLUMN()-COLUMN($D11)+1)} -> 6721.2206 | E11: {=INDEX('Demand Curves'!$D:$AC, MATCH("Starlink BB Revenue from curve ($mm)", 'Demand Curves'!$A$1:$A$167, 0), COLUMN()-COLUMN($D11)+1)} -> 9347.5765 | F11: {=INDEX('Demand Curves'!$D:$AC, MATCH("Starlink BB Revenue from curve ($mm)", 'Demand Curves'!$A$1:$A$167, 0), COLUMN()-COLUMN($D11)+1)} -> 37555.656 | G11: {=INDEX('Demand Curves'!$D:$AC, MATCH("Starlink BB Revenue from curve ($mm)", 'Demand Curves'!$A$1:$A$167, 0), COLUMN()-COLUMN($D11)+1)} -> 80517.71 | H11: {=INDEX('Demand Curves'!$D:$AC, MATCH("Starlink BB Revenue from curve ($mm)", 'Demand Curves'!$A$1:$A$167, 0), COLUMN()-COLUMN($D11)+1)} -> 141004.93 | I11: {=INDEX('Demand Curves'!$D:$AC, MATCH("Starlink BB Revenue from curve ($mm)", 'Demand Curves'!$A$1:$A$167, 0), COLUMN()-COLUMN($D11)+1)} -> 172279.32 | J11: {=INDEX('Demand Curves'!$D:$AC, MATCH("Starlink BB Revenue from curve ($mm)", 'Demand Curves'!$A$1:$A$167, 0), COLUMN()-COLUMN($D11)+1)} -> 205461.3 | K11: {=INDEX('Demand Curves'!$D:$AC, MATCH("Starlink BB Revenue from curve ($mm)", 'Demand Curves'!$A$1:$A$167, 0), COLUMN()-COLUMN($D11)+1)} -> 221249.49 | ... S11: {=INDEX('Demand Curves'!$D:$AC, MATCH("Starlink BB Revenue from curve ($mm)", 'Demand Curves'!$A$1:$A$167, 0), COLUMN()-COLUMN($D11)+1)} -> 304575.99
A12: Starlink DTC Revenue from curve ($mm) | D12: {=INDEX('Demand Curves'!$D:$AC, MATCH("Starlink DTC Revenue from curve ($mm)", 'Demand Curves'!$A$1:$A$167, 0), COLUMN()-COLUMN($D12)+1)} -> 632.0752 | E12: {=INDEX('Demand Curves'!$D:$AC, MATCH("Starlink DTC Revenue from curve ($mm)", 'Demand Curves'!$A$1:$A$167, 0), COLUMN()-COLUMN($D12)+1)} -> 794.38308 | F12: {=INDEX('Demand Curves'!$D:$AC, MATCH("Starlink DTC Revenue from curve ($mm)", 'Demand Curves'!$A$1:$A$167, 0), COLUMN()-COLUMN($D12)+1)} -> 969.01979 | G12: {=INDEX('Demand Curves'!$D:$AC, MATCH("Starlink DTC Revenue from curve ($mm)", 'Demand Curves'!$A$1:$A$167, 0), COLUMN()-COLUMN($D12)+1)} -> 1291.3041 | H12: {=INDEX('Demand Curves'!$D:$AC, MATCH("Starlink DTC Revenue from curve ($mm)", 'Demand Curves'!$A$1:$A$167, 0), COLUMN()-COLUMN($D12)+1)} -> 7146.7257 | I12: {=INDEX('Demand Curves'!$D:$AC, MATCH("Starlink DTC Revenue from curve ($mm)", 'Demand Curves'!$A$1:$A$167, 0), COLUMN()-COLUMN($D12)+1)} -> 33355.216 | J12: {=INDEX('Demand Curves'!$D:$AC, MATCH("Starlink DTC Revenue from curve ($mm)", 'Demand Curves'!$A$1:$A$167, 0), COLUMN()-COLUMN($D12)+1)} -> 41028.563 | K12: {=INDEX('Demand Curves'!$D:$AC, MATCH("Starlink DTC Revenue from curve ($mm)", 'Demand Curves'!$A$1:$A$167, 0), COLUMN()-COLUMN($D12)+1)} -> 49505.313 | ... S12: {=INDEX('Demand Curves'!$D:$AC, MATCH("Starlink DTC Revenue from curve ($mm)", 'Demand Curves'!$A$1:$A$167, 0), COLUMN()-COLUMN($D12)+1)} -> 60513.713
A13: F9 at-cost rate per launch ($mm) | D13: {=INDEX(Assumptions!$D:$S, MATCH("F9 at-cost rate per launch ($mm)", Assumptions!$A$1:$A$257, 0), COLUMN()-COLUMN($D13)+1)} -> 20 | E13: {=INDEX(Assumptions!$D:$S, MATCH("F9 at-cost rate per launch ($mm)", Assumptions!$A$1:$A$257, 0), COLUMN()-COLUMN($D13)+1)} -> 19.6 | F13: {=INDEX(Assumptions!$D:$S, MATCH("F9 at-cost rate per launch ($mm)", Assumptions!$A$1:$A$257, 0), COLUMN()-COLUMN($D13)+1)} -> 19.208 | G13: {=INDEX(Assumptions!$D:$S, MATCH("F9 at-cost rate per launch ($mm)", Assumptions!$A$1:$A$257, 0), COLUMN()-COLUMN($D13)+1)} -> 18.824 | H13: {=INDEX(Assumptions!$D:$S, MATCH("F9 at-cost rate per launch ($mm)", Assumptions!$A$1:$A$257, 0), COLUMN()-COLUMN($D13)+1)} -> 18.447 | I13: {=INDEX(Assumptions!$D:$S, MATCH("F9 at-cost rate per launch ($mm)", Assumptions!$A$1:$A$257, 0), COLUMN()-COLUMN($D13)+1)} -> 18.078 | J13: {=INDEX(Assumptions!$D:$S, MATCH("F9 at-cost rate per launch ($mm)", Assumptions!$A$1:$A$257, 0), COLUMN()-COLUMN($D13)+1)} -> 17.717 | K13: {=INDEX(Assumptions!$D:$S, MATCH("F9 at-cost rate per launch ($mm)", Assumptions!$A$1:$A$257, 0), COLUMN()-COLUMN($D13)+1)} -> 17.363 | ... S13: {=INDEX(Assumptions!$D:$S, MATCH("F9 at-cost rate per launch ($mm)", Assumptions!$A$1:$A$257, 0), COLUMN()-COLUMN($D13)+1)} -> 14.772
A14: Starship at-cost rate per launch ($mm) | D14: {=INDEX(Assumptions!$D:$S, MATCH("Starship at-cost rate per launch ($mm)", Assumptions!$A$1:$A$257, 0), COLUMN()-COLUMN($D14)+1)} -> 0 | E14: {=INDEX(Assumptions!$D:$S, MATCH("Starship at-cost rate per launch ($mm)", Assumptions!$A$1:$A$257, 0), COLUMN()-COLUMN($D14)+1)} -> 0 | F14: {=INDEX(Assumptions!$D:$S, MATCH("Starship at-cost rate per launch ($mm)", Assumptions!$A$1:$A$257, 0), COLUMN()-COLUMN($D14)+1)} -> 25 | G14: {=INDEX(Assumptions!$D:$S, MATCH("Starship at-cost rate per launch ($mm)", Assumptions!$A$1:$A$257, 0), COLUMN()-COLUMN($D14)+1)} -> 23 | H14: {=INDEX(Assumptions!$D:$S, MATCH("Starship at-cost rate per launch ($mm)", Assumptions!$A$1:$A$257, 0), COLUMN()-COLUMN($D14)+1)} -> 21.16 | I14: {=INDEX(Assumptions!$D:$S, MATCH("Starship at-cost rate per launch ($mm)", Assumptions!$A$1:$A$257, 0), COLUMN()-COLUMN($D14)+1)} -> 19.4672 | J14: {=INDEX(Assumptions!$D:$S, MATCH("Starship at-cost rate per launch ($mm)", Assumptions!$A$1:$A$257, 0), COLUMN()-COLUMN($D14)+1)} -> 17.909824 | K14: {=INDEX(Assumptions!$D:$S, MATCH("Starship at-cost rate per launch ($mm)", Assumptions!$A$1:$A$257, 0), COLUMN()-COLUMN($D14)+1)} -> 16.477038 | ... S14: {=INDEX(Assumptions!$D:$S, MATCH("Starship at-cost rate per launch ($mm)", Assumptions!$A$1:$A$257, 0), COLUMN()-COLUMN($D14)+1)} -> 8.4563269
A15: Sat operational life L (years) | D15: =INDEX(Assumptions!$B:$B, MATCH("Sat operational life L (years)", Assumptions!$A$1:$A$257, 0)) -> 5 | E15: =INDEX(Assumptions!$B:$B, MATCH("Sat operational life L (years)", Assumptions!$A$1:$A$257, 0)) -> 5 | F15: =INDEX(Assumptions!$B:$B, MATCH("Sat operational life L (years)", Assumptions!$A$1:$A$257, 0)) -> 5 | G15: =INDEX(Assumptions!$B:$B, MATCH("Sat operational life L (years)", Assumptions!$A$1:$A$257, 0)) -> 5 | H15: =INDEX(Assumptions!$B:$B, MATCH("Sat operational life L (years)", Assumptions!$A$1:$A$257, 0)) -> 5 | I15: =INDEX(Assumptions!$B:$B, MATCH("Sat operational life L (years)", Assumptions!$A$1:$A$257, 0)) -> 5 | J15: =INDEX(Assumptions!$B:$B, MATCH("Sat operational life L (years)", Assumptions!$A$1:$A$257, 0)) -> 5 | K15: =INDEX(Assumptions!$B:$B, MATCH("Sat operational life L (years)", Assumptions!$A$1:$A$257, 0)) -> 5 | ... S15: =INDEX(Assumptions!$B:$B, MATCH("Sat operational life L (years)", Assumptions!$A$1:$A$257, 0)) -> 5
A16: Group WACC | D16: =INDEX(Assumptions!$B:$B, MATCH("Group WACC", Assumptions!$A$1:$A$257, 0)) -> 0.1 | E16: =INDEX(Assumptions!$B:$B, MATCH("Group WACC", Assumptions!$A$1:$A$257, 0)) -> 0.1 | F16: =INDEX(Assumptions!$B:$B, MATCH("Group WACC", Assumptions!$A$1:$A$257, 0)) -> 0.1 | G16: =INDEX(Assumptions!$B:$B, MATCH("Group WACC", Assumptions!$A$1:$A$257, 0)) -> 0.1 | H16: =INDEX(Assumptions!$B:$B, MATCH("Group WACC", Assumptions!$A$1:$A$257, 0)) -> 0.1 | I16: =INDEX(Assumptions!$B:$B, MATCH("Group WACC", Assumptions!$A$1:$A$257, 0)) -> 0.1 | J16: =INDEX(Assumptions!$B:$B, MATCH("Group WACC", Assumptions!$A$1:$A$257, 0)) -> 0.1 | K16: =INDEX(Assumptions!$B:$B, MATCH("Group WACC", Assumptions!$A$1:$A$257, 0)) -> 0.1 | ... S16: =INDEX(Assumptions!$B:$B, MATCH("Group WACC", Assumptions!$A$1:$A$257, 0)) -> 0.1
A18: Starlink R&D as % of revenue (frac) | D18: =INDEX(Assumptions!$B:$B, MATCH("Starlink R&D: start % of (Starlink+Starshield) rev", Assumptions!$A$1:$A$257, 0)) -> 0.053 | E18: =INDEX(Assumptions!$B:$B, MATCH("Starlink R&D: start % of (Starlink+Starshield) rev", Assumptions!$A$1:$A$257, 0)) -> 0.053 | F18: =INDEX(Assumptions!$B:$B, MATCH("Starlink R&D: start % of (Starlink+Starshield) rev", Assumptions!$A$1:$A$257, 0)) -> 0.053 | G18: =INDEX(Assumptions!$B:$B, MATCH("Starlink R&D: start % of (Starlink+Starshield) rev", Assumptions!$A$1:$A$257, 0)) -> 0.053 | H18: =INDEX(Assumptions!$B:$B, MATCH("Starlink R&D: start % of (Starlink+Starshield) rev", Assumptions!$A$1:$A$257, 0)) -> 0.053 | I18: =INDEX(Assumptions!$B:$B, MATCH("Starlink R&D: start % of (Starlink+Starshield) rev", Assumptions!$A$1:$A$257, 0)) -> 0.053 | J18: =INDEX(Assumptions!$B:$B, MATCH("Starlink R&D: start % of (Starlink+Starshield) rev", Assumptions!$A$1:$A$257, 0)) -> 0.053 | K18: =INDEX(Assumptions!$B:$B, MATCH("Starlink R&D: start % of (Starlink+Starshield) rev", Assumptions!$A$1:$A$257, 0)) -> 0.053 | ... S18: =INDEX(Assumptions!$B:$B, MATCH("Starlink R&D: start % of (Starlink+Starshield) rev", Assumptions!$A$1:$A$257, 0)) -> 0.053
A19: Starlink module allocated cash ($mm/yr): live from Cash Allocation Engine | D19: ='Cash Allocation Engine'!D39 -> 0 | E19: ='Cash Allocation Engine'!E39 -> 13695.09 | F19: ='Cash Allocation Engine'!F39 -> 56677.18 | G19: ='Cash Allocation Engine'!G39 -> 57774.103 | H19: ='Cash Allocation Engine'!H39 -> 67795.202 | I19: ='Cash Allocation Engine'!I39 -> 68617.687 | J19: ='Cash Allocation Engine'!J39 -> 68448.419 | K19: ='Cash Allocation Engine'!K39 -> 76570.128 | ... S19: ='Cash Allocation Engine'!S39 -> 35740.836
A20: Starlink deployment 2025 anchor (sats) | D20: =INDEX(Assumptions!$B:$B, MATCH("Starlink deployment 2025 anchor (sats)", Assumptions!$A$1:$A$257, 0)) -> 3840
A21: Sat utilization (frac) | D21: =INDEX(Assumptions!$B:$B, MATCH("Sat utilization (frac)", Assumptions!$A$1:$A$257, 0)) -> 0.7 | E21: =INDEX(Assumptions!$B:$B, MATCH("Sat utilization (frac)", Assumptions!$A$1:$A$257, 0)) -> 0.7 | F21: =INDEX(Assumptions!$B:$B, MATCH("Sat utilization (frac)", Assumptions!$A$1:$A$257, 0)) -> 0.7 | G21: =INDEX(Assumptions!$B:$B, MATCH("Sat utilization (frac)", Assumptions!$A$1:$A$257, 0)) -> 0.7 | H21: =INDEX(Assumptions!$B:$B, MATCH("Sat utilization (frac)", Assumptions!$A$1:$A$257, 0)) -> 0.7 | I21: =INDEX(Assumptions!$B:$B, MATCH("Sat utilization (frac)", Assumptions!$A$1:$A$257, 0)) -> 0.7 | J21: =INDEX(Assumptions!$B:$B, MATCH("Sat utilization (frac)", Assumptions!$A$1:$A$257, 0)) -> 0.7 | K21: =INDEX(Assumptions!$B:$B, MATCH("Sat utilization (frac)", Assumptions!$A$1:$A$257, 0)) -> 0.7 | ... S21: =INDEX(Assumptions!$B:$B, MATCH("Sat utilization (frac)", Assumptions!$A$1:$A$257, 0)) -> 0.7
A22: Starship operational year | D22: =INDEX(Assumptions!$B:$B, MATCH("Starship operational year", Assumptions!$A$1:$A$257, 0)) -> 2026
A23: F9 launches V2-Starlink final year | D23: =INDEX(Assumptions!$B:$B, MATCH("F9 launches V2-Starlink final year", Assumptions!$A$1:$A$257, 0)) -> 2026
A24: F9 payload per launch (kg) | D24: {=INDEX('Vehicle Build'!$D:$AC, MATCH("F9 payload per launch (kg)", 'Vehicle Build'!$A$1:$A$119, 0), COLUMN()-COLUMN($D24)+1)} -> 22800 | E24: {=INDEX('Vehicle Build'!$D:$AC, MATCH("F9 payload per launch (kg)", 'Vehicle Build'!$A$1:$A$119, 0), COLUMN()-COLUMN($D24)+1)} -> 22800 | F24: {=INDEX('Vehicle Build'!$D:$AC, MATCH("F9 payload per launch (kg)", 'Vehicle Build'!$A$1:$A$119, 0), COLUMN()-COLUMN($D24)+1)} -> 22800 | G24: {=INDEX('Vehicle Build'!$D:$AC, MATCH("F9 payload per launch (kg)", 'Vehicle Build'!$A$1:$A$119, 0), COLUMN()-COLUMN($D24)+1)} -> 22800 | H24: {=INDEX('Vehicle Build'!$D:$AC, MATCH("F9 payload per launch (kg)", 'Vehicle Build'!$A$1:$A$119, 0), COLUMN()-COLUMN($D24)+1)} -> 22800 | I24: {=INDEX('Vehicle Build'!$D:$AC, MATCH("F9 payload per launch (kg)", 'Vehicle Build'!$A$1:$A$119, 0), COLUMN()-COLUMN($D24)+1)} -> 22800 | J24: {=INDEX('Vehicle Build'!$D:$AC, MATCH("F9 payload per launch (kg)", 'Vehicle Build'!$A$1:$A$119, 0), COLUMN()-COLUMN($D24)+1)} -> 22800 | K24: {=INDEX('Vehicle Build'!$D:$AC, MATCH("F9 payload per launch (kg)", 'Vehicle Build'!$A$1:$A$119, 0), COLUMN()-COLUMN($D24)+1)} -> 22800 | ... S24: {=INDEX('Vehicle Build'!$D:$AC, MATCH("F9 payload per launch (kg)", 'Vehicle Build'!$A$1:$A$119, 0), COLUMN()-COLUMN($D24)+1)} -> 22800
A25: Starship payload per launch (kg) | D25: {=INDEX('Vehicle Build'!$D:$AC, MATCH("Starship payload per launch (kg)", 'Vehicle Build'!$A$1:$A$119, 0), COLUMN()-COLUMN($D25)+1)} -> 100000 | E25: {=INDEX('Vehicle Build'!$D:$AC, MATCH("Starship payload per launch (kg)", 'Vehicle Build'!$A$1:$A$119, 0), COLUMN()-COLUMN($D25)+1)} -> 114869.84 | F25: {=INDEX('Vehicle Build'!$D:$AC, MATCH("Starship payload per launch (kg)", 'Vehicle Build'!$A$1:$A$119, 0), COLUMN()-COLUMN($D25)+1)} -> 131950.79 | G25: {=INDEX('Vehicle Build'!$D:$AC, MATCH("Starship payload per launch (kg)", 'Vehicle Build'!$A$1:$A$119, 0), COLUMN()-COLUMN($D25)+1)} -> 151571.66 | H25: {=INDEX('Vehicle Build'!$D:$AC, MATCH("Starship payload per launch (kg)", 'Vehicle Build'!$A$1:$A$119, 0), COLUMN()-COLUMN($D25)+1)} -> 174110.11 | I25: {=INDEX('Vehicle Build'!$D:$AC, MATCH("Starship payload per launch (kg)", 'Vehicle Build'!$A$1:$A$119, 0), COLUMN()-COLUMN($D25)+1)} -> 200000 | J25: {=INDEX('Vehicle Build'!$D:$AC, MATCH("Starship payload per launch (kg)", 'Vehicle Build'!$A$1:$A$119, 0), COLUMN()-COLUMN($D25)+1)} -> 200000 | K25: {=INDEX('Vehicle Build'!$D:$AC, MATCH("Starship payload per launch (kg)", 'Vehicle Build'!$A$1:$A$119, 0), COLUMN()-COLUMN($D25)+1)} -> 200000 | ... S25: {=INDEX('Vehicle Build'!$D:$AC, MATCH("Starship payload per launch (kg)", 'Vehicle Build'!$A$1:$A$119, 0), COLUMN()-COLUMN($D25)+1)} -> 200000
A27: ▸ CONSTELLATION BUILD (real cohorts → total bandwidth)
A28: V2 launch window active (1/0) | D28: =IF(D$4<=$D$23, 1, 0) -> 1 | E28: =IF(E$4<=$D$23, 1, 0) -> 1 | F28: =IF(F$4<=$D$23, 1, 0) -> 0 | G28: =IF(G$4<=$D$23, 1, 0) -> 0 | H28: =IF(H$4<=$D$23, 1, 0) -> 0 | I28: =IF(I$4<=$D$23, 1, 0) -> 0 | J28: =IF(J$4<=$D$23, 1, 0) -> 0 | K28: =IF(K$4<=$D$23, 1, 0) -> 0 | ... S28: =IF(S$4<=$D$23, 1, 0) -> 0
A29: V3 deployment active (1/0) | D29: =IF(D$4>=$D$22+1, 1, 0) -> 0 | E29: =IF(E$4>=$D$22+1, 1, 0) -> 0 | F29: =IF(F$4>=$D$22+1, 1, 0) -> 1 | G29: =IF(G$4>=$D$22+1, 1, 0) -> 1 | H29: =IF(H$4>=$D$22+1, 1, 0) -> 1 | I29: =IF(I$4>=$D$22+1, 1, 0) -> 1 | J29: =IF(J$4>=$D$22+1, 1, 0) -> 1 | K29: =IF(K$4>=$D$22+1, 1, 0) -> 1 | ... S29: =IF(S$4>=$D$22+1, 1, 0) -> 1
A31: Total new Starlink deployment (sats/yr) | D31: =SUM(D32:D35) -> 3840 | E31: =SUM(E32:E35) -> 3120 | F31: =SUM(F32:F35) -> 3918.7353 | G31: =SUM(G32:G35) -> 9497.38 | H31: =SUM(H32:H35) -> 27023.504 | I31: =SUM(I32:I35) -> 50339.52 | J31: =SUM(J32:J35) -> 53600.633 | K31: =SUM(K32:K35) -> 63346.234 | ... S31: =SUM(S32:S35) -> 33596.994
A32: New V2 BB deployment (sats/yr) | D32: =IF(D$4=2025, $D$20, IF(D$28=1, D202, 0)) -> 3840 | E32: =IF(E$4=2025, $D$20, IF(E$28=1, E202, 0)) -> 3120 | F32: =IF(F$4=2025, $D$20, IF(F$28=1, F202, 0)) -> 0 | G32: =IF(G$4=2025, $D$20, IF(G$28=1, G202, 0)) -> 0 | H32: =IF(H$4=2025, $D$20, IF(H$28=1, H202, 0)) -> 0 | I32: =IF(I$4=2025, $D$20, IF(I$28=1, I202, 0)) -> 0 | J32: =IF(J$4=2025, $D$20, IF(J$28=1, J202, 0)) -> 0 | K32: =IF(K$4=2025, $D$20, IF(K$28=1, K202, 0)) -> 0 | ... S32: =IF(S$4=2025, $D$20, IF(S$28=1, S202, 0)) -> 0
A33: New V2 DTC deployment (sats/yr) | D33: =0 -> 0 | E33: =0 -> 0 | F33: =0 -> 0 | G33: =0 -> 0 | H33: =0 -> 0 | I33: =0 -> 0 | J33: =0 -> 0 | K33: =0 -> 0 | ... S33: =0 -> 0
A34: New V3 BB deployment (sats/yr) | D34: =IF(D$29=1, D202, 0) -> 0 | E34: =IF(E$29=1, E202, 0) -> 0 | F34: =IF(F$29=1, F202, 0) -> 3916.8534 | G34: =IF(G$29=1, G202, 0) -> 9417.3557 | H34: =IF(H$29=1, H202, 0) -> 23934.562 | I34: =IF(I$29=1, I202, 0) -> 15031.115 | J34: =IF(J$29=1, J202, 0) -> 28946.91 | K34: =IF(K$29=1, K202, 0) -> 16400.059 | ... S34: =IF(S$29=1, S202, 0) -> 17069.962
A35: New V3 DTC deployment (sats/yr) | D35: =IF(D$29=1, D203, 0) -> 0 | E35: =IF(E$29=1, E203, 0) -> 0 | F35: =IF(F$29=1, F203, 0) -> 1.8818572 | G35: =IF(G$29=1, G203, 0) -> 80.024272 | H35: =IF(H$29=1, H203, 0) -> 3088.9424 | I35: =IF(I$29=1, I203, 0) -> 35308.405 | J35: =IF(J$29=1, J203, 0) -> 24653.723 | K35: =IF(K$29=1, K203, 0) -> 46946.175 | ... S35: =IF(S$29=1, S203, 0) -> 16527.032
A36: New Starshield deployment (sats/yr) | D36: =$D$31*0.12 -> 460.8 | E36: =$D$31*0.12 -> 460.8 | F36: =$D$31*0.12 -> 460.8 | G36: =$D$31*0.12 -> 460.8 | H36: =$D$31*0.12 -> 460.8 | I36: =$D$31*0.12 -> 460.8 | J36: =$D$31*0.12 -> 460.8 | K36: =$D$31*0.12 -> 460.8 | ... S36: =$D$31*0.12 -> 460.8
A37: Blended new-sat CapEx slug ($mm/sat): MEMO ONLY (feeds CAE R88 cap; no longer drives deployment) | D37: 1.7 | E37: 1.7 | F37: =IF(F$29=1, INDEX(Assumptions!$B:$B,MATCH("V3 BB share of new deployment (frac)",Assumptions!$A$1:$A$257,0))*F125 + INDEX(Assumptions!$B:$B,MATCH("V3 DTC share of new deployment (frac)",Assumptions!$A$1:$A$257,0))*F131, INDEX(Assumptions!$B:$B,MATCH("V2 BB share of new deployment (frac)",Assumptions!$A$1:$A$257,0))*F113 + INDEX(Assumptions!$B:$B,MATCH("V2 DTC share of new deployment (frac)",Assumptions!$A$1:$A$257,0))*F119 + 0.12*F137) -> 1.6698542 | G37: =IF(G$29=1, INDEX(Assumptions!$B:$B,MATCH("V3 BB share of new deployment (frac)",Assumptions!$A$1:$A$257,0))*G125 + INDEX(Assumptions!$B:$B,MATCH("V3 DTC share of new deployment (frac)",Assumptions!$A$1:$A$257,0))*G131, INDEX(Assumptions!$B:$B,MATCH("V2 BB share of new deployment (frac)",Assumptions!$A$1:$A$257,0))*G113 + INDEX(Assumptions!$B:$B,MATCH("V2 DTC share of new deployment (frac)",Assumptions!$A$1:$A$257,0))*G119 + 0.12*G137) -> 1.5893285 | H37: =IF(H$29=1, INDEX(Assumptions!$B:$B,MATCH("V3 BB share of new deployment (frac)",Assumptions!$A$1:$A$257,0))*H125 + INDEX(Assumptions!$B:$B,MATCH("V3 DTC share of new deployment (frac)",Assumptions!$A$1:$A$257,0))*H131, INDEX(Assumptions!$B:$B,MATCH("V2 BB share of new deployment (frac)",Assumptions!$A$1:$A$257,0))*H113 + INDEX(Assumptions!$B:$B,MATCH("V2 DTC share of new deployment (frac)",Assumptions!$A$1:$A$257,0))*H119 + 0.12*H137) -> 1.4810863 | I37: =IF(I$29=1, INDEX(Assumptions!$B:$B,MATCH("V3 BB share of new deployment (frac)",Assumptions!$A$1:$A$257,0))*I125 + INDEX(Assumptions!$B:$B,MATCH("V3 DTC share of new deployment (frac)",Assumptions!$A$1:$A$257,0))*I131, INDEX(Assumptions!$B:$B,MATCH("V2 BB share of new deployment (frac)",Assumptions!$A$1:$A$257,0))*I113 + INDEX(Assumptions!$B:$B,MATCH("V2 DTC share of new deployment (frac)",Assumptions!$A$1:$A$257,0))*I119 + 0.12*I137) -> 1.3630978 | J37: =IF(J$29=1, INDEX(Assumptions!$B:$B,MATCH("V3 BB share of new deployment (frac)",Assumptions!$A$1:$A$257,0))*J125 + INDEX(Assumptions!$B:$B,MATCH("V3 DTC share of new deployment (frac)",Assumptions!$A$1:$A$257,0))*J131, INDEX(Assumptions!$B:$B,MATCH("V2 BB share of new deployment (frac)",Assumptions!$A$1:$A$257,0))*J113 + INDEX(Assumptions!$B:$B,MATCH("V2 DTC share of new deployment (frac)",Assumptions!$A$1:$A$257,0))*J119 + 0.12*J137) -> 1.2770077 | K37: =IF(K$29=1, INDEX(Assumptions!$B:$B,MATCH("V3 BB share of new deployment (frac)",Assumptions!$A$1:$A$257,0))*K125 + INDEX(Assumptions!$B:$B,MATCH("V3 DTC share of new deployment (frac)",Assumptions!$A$1:$A$257,0))*K131, INDEX(Assumptions!$B:$B,MATCH("V2 BB share of new deployment (frac)",Assumptions!$A$1:$A$257,0))*K113 + INDEX(Assumptions!$B:$B,MATCH("V2 DTC share of new deployment (frac)",Assumptions!$A$1:$A$257,0))*K119 + 0.12*K137) -> 1.2087558 | L37: =IF(L$29=1, INDEX(Assumptions!$B:$B,MATCH("V3 BB share of new deployment (frac)",Assumptions!$A$1:$A$257,0))*L125 + INDEX(Assumptions!$B:$B,MATCH("V3 DTC share of new deployment (frac)",Assumptions!$A$1:$A$257,0))*L131, INDEX(Assumptions!$B:$B,MATCH("V2 BB share of new deployment (frac)",Assumptions!$A$1:$A$257,0))*L113 + INDEX(Assumptions!$B:$B,MATCH("V2 DTC share of new deployment (frac)",Assumptions!$A$1:$A$257,0))*L119 + 0.12*L137) -> 1.1617272 | M37: =IF(M$29=1, INDEX(Assumptions!$B:$B,MATCH("V3 BB share of new deployment (frac)",Assumptions!$A$1:$A$257,0))*M125 + INDEX(Assumptions!$B:$B,MATCH("V3 DTC share of new deployment (frac)",Assumptions!$A$1:$A$257,0))*M131, INDEX(Assumptions!$B:$B,MATCH("V2 BB share of new deployment (frac)",Assumptions!$A$1:$A$257,0))*M113 + INDEX(Assumptions!$B:$B,MATCH("V2 DTC share of new deployment (frac)",Assumptions!$A$1:$A$257,0))*M119 + 0.12*M137) -> 1.1373993 | ... S37: =IF(S$29=1, INDEX(Assumptions!$B:$B,MATCH("V3 BB share of new deployment (frac)",Assumptions!$A$1:$A$257,0))*S125 + INDEX(Assumptions!$B:$B,MATCH("V3 DTC share of new deployment (frac)",Assumptions!$A$1:$A$257,0))*S131, INDEX(Assumptions!$B:$B,MATCH("V2 BB share of new deployment (frac)",Assumptions!$A$1:$A$257,0))*S113 + INDEX(Assumptions!$B:$B,MATCH("V2 DTC share of new deployment (frac)",Assumptions!$A$1:$A$257,0))*S119 + 0.12*S137) -> 0.99913786
A38: Demand-saturation deployment headroom (sats) | D38: =MAX(0,(INDEX('Demand Curves'!$B:$B,MATCH("BB Q breakpoint #56 (Gbps)",'Demand Curves'!$A$1:$A$167,0))-D176)/INDEX(Assumptions!$B:$B,MATCH("V3 BB Gbps per sat",Assumptions!$A$1:$A$257,0))) -> 249585.86 | E38: =MAX(0,(INDEX('Demand Curves'!$B:$B,MATCH("BB Q breakpoint #56 (Gbps)",'Demand Curves'!$A$1:$A$167,0))-D176)/INDEX(Assumptions!$B:$B,MATCH("V3 BB Gbps per sat",Assumptions!$A$1:$A$257,0))) -> 249585.86 | F38: =MAX(0,(INDEX('Demand Curves'!$B:$B,MATCH("BB Q breakpoint #56 (Gbps)",'Demand Curves'!$A$1:$A$167,0))-E176)/INDEX(Assumptions!$B:$B,MATCH("V3 BB Gbps per sat",Assumptions!$A$1:$A$257,0))) -> 249286.34 | G38: =MAX(0,(INDEX('Demand Curves'!$B:$B,MATCH("BB Q breakpoint #56 (Gbps)",'Demand Curves'!$A$1:$A$167,0))-F176)/INDEX(Assumptions!$B:$B,MATCH("V3 BB Gbps per sat",Assumptions!$A$1:$A$257,0))) -> 245369.48 | H38: =MAX(0,(INDEX('Demand Curves'!$B:$B,MATCH("BB Q breakpoint #56 (Gbps)",'Demand Curves'!$A$1:$A$167,0))-G176)/INDEX(Assumptions!$B:$B,MATCH("V3 BB Gbps per sat",Assumptions!$A$1:$A$257,0))) -> 236090.17 | I38: =MAX(0,(INDEX('Demand Curves'!$B:$B,MATCH("BB Q breakpoint #56 (Gbps)",'Demand Curves'!$A$1:$A$167,0))-H176)/INDEX(Assumptions!$B:$B,MATCH("V3 BB Gbps per sat",Assumptions!$A$1:$A$257,0))) -> 212293.66 | J38: =MAX(0,(INDEX('Demand Curves'!$B:$B,MATCH("BB Q breakpoint #56 (Gbps)",'Demand Curves'!$A$1:$A$167,0))-I176)/INDEX(Assumptions!$B:$B,MATCH("V3 BB Gbps per sat",Assumptions!$A$1:$A$257,0))) -> 197400.59 | K38: =MAX(0,(INDEX('Demand Curves'!$B:$B,MATCH("BB Q breakpoint #56 (Gbps)",'Demand Curves'!$A$1:$A$167,0))-J176)/INDEX(Assumptions!$B:$B,MATCH("V3 BB Gbps per sat",Assumptions!$A$1:$A$257,0))) -> 168753.2 | L38: =MAX(0,(INDEX('Demand Curves'!$B:$B,MATCH("BB Q breakpoint #56 (Gbps)",'Demand Curves'!$A$1:$A$167,0))-K176)/INDEX(Assumptions!$B:$B,MATCH("V3 BB Gbps per sat",Assumptions!$A$1:$A$257,0))) -> 156270 | ... S38: =MAX(0,(INDEX('Demand Curves'!$B:$B,MATCH("BB Q breakpoint #56 (Gbps)",'Demand Curves'!$A$1:$A$167,0))-R176)/INDEX(Assumptions!$B:$B,MATCH("V3 BB Gbps per sat",Assumptions!$A$1:$A$257,0))) -> 35771.676
A39: BB FLEET (active sats by cohort)
A40: Legacy V1 active sats | D40: =INDEX(Assumptions!$B:$B,MATCH("Legacy V1 active sats end-2025",Assumptions!$A$1:$A$257,0)) -> 866 | E40: =MAX(0, D40 - IF(AND(E$4>=INDEX(Assumptions!$B:$B,MATCH("Legacy V1 base deorbit start year",Assumptions!$A$1:$A$257,0)),E$4<=INDEX(Assumptions!$B:$B,MATCH("Legacy V1 base deorbit end year",Assumptions!$A$1:$A$257,0))),$D$40/(INDEX(Assumptions!$B:$B,MATCH("Legacy V1 base deorbit end year",Assumptions!$A$1:$A$257,0))-INDEX(Assumptions!$B:$B,MATCH("Legacy V1 base deorbit start year",Assumptions!$A$1:$A$257,0))+1),0)) -> 0 | F40: =MAX(0, E40 - IF(AND(F$4>=INDEX(Assumptions!$B:$B,MATCH("Legacy V1 base deorbit start year",Assumptions!$A$1:$A$257,0)),F$4<=INDEX(Assumptions!$B:$B,MATCH("Legacy V1 base deorbit end year",Assumptions!$A$1:$A$257,0))),$D$40/(INDEX(Assumptions!$B:$B,MATCH("Legacy V1 base deorbit end year",Assumptions!$A$1:$A$257,0))-INDEX(Assumptions!$B:$B,MATCH("Legacy V1 base deorbit start year",Assumptions!$A$1:$A$257,0))+1),0)) -> 0 | G40: =MAX(0, F40 - IF(AND(G$4>=INDEX(Assumptions!$B:$B,MATCH("Legacy V1 base deorbit start year",Assumptions!$A$1:$A$257,0)),G$4<=INDEX(Assumptions!$B:$B,MATCH("Legacy V1 base deorbit end year",Assumptions!$A$1:$A$257,0))),$D$40/(INDEX(Assumptions!$B:$B,MATCH("Legacy V1 base deorbit end year",Assumptions!$A$1:$A$257,0))-INDEX(Assumptions!$B:$B,MATCH("Legacy V1 base deorbit start year",Assumptions!$A$1:$A$257,0))+1),0)) -> 0 | H40: =MAX(0, G40 - IF(AND(H$4>=INDEX(Assumptions!$B:$B,MATCH("Legacy V1 base deorbit start year",Assumptions!$A$1:$A$257,0)),H$4<=INDEX(Assumptions!$B:$B,MATCH("Legacy V1 base deorbit end year",Assumptions!$A$1:$A$257,0))),$D$40/(INDEX(Assumptions!$B:$B,MATCH("Legacy V1 base deorbit end year",Assumptions!$A$1:$A$257,0))-INDEX(Assumptions!$B:$B,MATCH("Legacy V1 base deorbit start year",Assumptions!$A$1:$A$257,0))+1),0)) -> 0 | I40: =MAX(0, H40 - IF(AND(I$4>=INDEX(Assumptions!$B:$B,MATCH("Legacy V1 base deorbit start year",Assumptions!$A$1:$A$257,0)),I$4<=INDEX(Assumptions!$B:$B,MATCH("Legacy V1 base deorbit end year",Assumptions!$A$1:$A$257,0))),$D$40/(INDEX(Assumptions!$B:$B,MATCH("Legacy V1 base deorbit end year",Assumptions!$A$1:$A$257,0))-INDEX(Assumptions!$B:$B,MATCH("Legacy V1 base deorbit start year",Assumptions!$A$1:$A$257,0))+1),0)) -> 0 | J40: =MAX(0, I40 - IF(AND(J$4>=INDEX(Assumptions!$B:$B,MATCH("Legacy V1 base deorbit start year",Assumptions!$A$1:$A$257,0)),J$4<=INDEX(Assumptions!$B:$B,MATCH("Legacy V1 base deorbit end year",Assumptions!$A$1:$A$257,0))),$D$40/(INDEX(Assumptions!$B:$B,MATCH("Legacy V1 base deorbit end year",Assumptions!$A$1:$A$257,0))-INDEX(Assumptions!$B:$B,MATCH("Legacy V1 base deorbit start year",Assumptions!$A$1:$A$257,0))+1),0)) -> 0 | K40: =MAX(0, J40 - IF(AND(K$4>=INDEX(Assumptions!$B:$B,MATCH("Legacy V1 base deorbit start year",Assumptions!$A$1:$A$257,0)),K$4<=INDEX(Assumptions!$B:$B,MATCH("Legacy V1 base deorbit end year",Assumptions!$A$1:$A$257,0))),$D$40/(INDEX(Assumptions!$B:$B,MATCH("Legacy V1 base deorbit end year",Assumptions!$A$1:$A$257,0))-INDEX(Assumptions!$B:$B,MATCH("Legacy V1 base deorbit start year",Assumptions!$A$1:$A$257,0))+1),0)) -> 0 | L40: =MAX(0, K40 - IF(AND(L$4>=INDEX(Assumptions!$B:$B,MATCH("Legacy V1 base deorbit start year",Assumptions!$A$1:$A$257,0)),L$4<=INDEX(Assumptions!$B:$B,MATCH("Legacy V1 base deorbit end year",Assumptions!$A$1:$A$257,0))),$D$40/(INDEX(Assumptions!$B:$B,MATCH("Legacy V1 base deorbit end year",Assumptions!$A$1:$A$257,0))-INDEX(Assumptions!$B:$B,MATCH("Legacy V1 base deorbit start year",Assumptions!$A$1:$A$257,0))+1),0)) -> 0 | ... S40: =MAX(0, R40 - IF(AND(S$4>=INDEX(Assumptions!$B:$B,MATCH("Legacy V1 base deorbit start year",Assumptions!$A$1:$A$257,0)),S$4<=INDEX(Assumptions!$B:$B,MATCH("Legacy V1 base deorbit end year",Assumptions!$A$1:$A$257,0))),$D$40/(INDEX(Assumptions!$B:$B,MATCH("Legacy V1 base deorbit end year",Assumptions!$A$1:$A$257,0))-INDEX(Assumptions!$B:$B,MATCH("Legacy V1 base deorbit start year",Assumptions!$A$1:$A$257,0))+1),0)) -> 0
A41: Legacy V1.5 active sats | D41: =INDEX(Assumptions!$B:$B,MATCH("Legacy V1.5 active sats end-2025",Assumptions!$A$1:$A$257,0)) -> 2692 | E41: =MAX(0, D41 - IF(AND(E$4>=INDEX(Assumptions!$B:$B,MATCH("Legacy V1.5 base deorbit start year",Assumptions!$A$1:$A$257,0)),E$4<=INDEX(Assumptions!$B:$B,MATCH("Legacy V1.5 base deorbit end year",Assumptions!$A$1:$A$257,0))),$D$41/(INDEX(Assumptions!$B:$B,MATCH("Legacy V1.5 base deorbit end year",Assumptions!$A$1:$A$257,0))-INDEX(Assumptions!$B:$B,MATCH("Legacy V1.5 base deorbit start year",Assumptions!$A$1:$A$257,0))+1),0)) -> 1794.6667 | F41: =MAX(0, E41 - IF(AND(F$4>=INDEX(Assumptions!$B:$B,MATCH("Legacy V1.5 base deorbit start year",Assumptions!$A$1:$A$257,0)),F$4<=INDEX(Assumptions!$B:$B,MATCH("Legacy V1.5 base deorbit end year",Assumptions!$A$1:$A$257,0))),$D$41/(INDEX(Assumptions!$B:$B,MATCH("Legacy V1.5 base deorbit end year",Assumptions!$A$1:$A$257,0))-INDEX(Assumptions!$B:$B,MATCH("Legacy V1.5 base deorbit start year",Assumptions!$A$1:$A$257,0))+1),0)) -> 897.33333 | G41: =MAX(0, F41 - IF(AND(G$4>=INDEX(Assumptions!$B:$B,MATCH("Legacy V1.5 base deorbit start year",Assumptions!$A$1:$A$257,0)),G$4<=INDEX(Assumptions!$B:$B,MATCH("Legacy V1.5 base deorbit end year",Assumptions!$A$1:$A$257,0))),$D$41/(INDEX(Assumptions!$B:$B,MATCH("Legacy V1.5 base deorbit end year",Assumptions!$A$1:$A$257,0))-INDEX(Assumptions!$B:$B,MATCH("Legacy V1.5 base deorbit start year",Assumptions!$A$1:$A$257,0))+1),0)) -> 0 | H41: =MAX(0, G41 - IF(AND(H$4>=INDEX(Assumptions!$B:$B,MATCH("Legacy V1.5 base deorbit start year",Assumptions!$A$1:$A$257,0)),H$4<=INDEX(Assumptions!$B:$B,MATCH("Legacy V1.5 base deorbit end year",Assumptions!$A$1:$A$257,0))),$D$41/(INDEX(Assumptions!$B:$B,MATCH("Legacy V1.5 base deorbit end year",Assumptions!$A$1:$A$257,0))-INDEX(Assumptions!$B:$B,MATCH("Legacy V1.5 base deorbit start year",Assumptions!$A$1:$A$257,0))+1),0)) -> 0 | I41: =MAX(0, H41 - IF(AND(I$4>=INDEX(Assumptions!$B:$B,MATCH("Legacy V1.5 base deorbit start year",Assumptions!$A$1:$A$257,0)),I$4<=INDEX(Assumptions!$B:$B,MATCH("Legacy V1.5 base deorbit end year",Assumptions!$A$1:$A$257,0))),$D$41/(INDEX(Assumptions!$B:$B,MATCH("Legacy V1.5 base deorbit end year",Assumptions!$A$1:$A$257,0))-INDEX(Assumptions!$B:$B,MATCH("Legacy V1.5 base deorbit start year",Assumptions!$A$1:$A$257,0))+1),0)) -> 0 | J41: =MAX(0, I41 - IF(AND(J$4>=INDEX(Assumptions!$B:$B,MATCH("Legacy V1.5 base deorbit start year",Assumptions!$A$1:$A$257,0)),J$4<=INDEX(Assumptions!$B:$B,MATCH("Legacy V1.5 base deorbit end year",Assumptions!$A$1:$A$257,0))),$D$41/(INDEX(Assumptions!$B:$B,MATCH("Legacy V1.5 base deorbit end year",Assumptions!$A$1:$A$257,0))-INDEX(Assumptions!$B:$B,MATCH("Legacy V1.5 base deorbit start year",Assumptions!$A$1:$A$257,0))+1),0)) -> 0 | K41: =MAX(0, J41 - IF(AND(K$4>=INDEX(Assumptions!$B:$B,MATCH("Legacy V1.5 base deorbit start year",Assumptions!$A$1:$A$257,0)),K$4<=INDEX(Assumptions!$B:$B,MATCH("Legacy V1.5 base deorbit end year",Assumptions!$A$1:$A$257,0))),$D$41/(INDEX(Assumptions!$B:$B,MATCH("Legacy V1.5 base deorbit end year",Assumptions!$A$1:$A$257,0))-INDEX(Assumptions!$B:$B,MATCH("Legacy V1.5 base deorbit start year",Assumptions!$A$1:$A$257,0))+1),0)) -> 0 | L41: =MAX(0, K41 - IF(AND(L$4>=INDEX(Assumptions!$B:$B,MATCH("Legacy V1.5 base deorbit start year",Assumptions!$A$1:$A$257,0)),L$4<=INDEX(Assumptions!$B:$B,MATCH("Legacy V1.5 base deorbit end year",Assumptions!$A$1:$A$257,0))),$D$41/(INDEX(Assumptions!$B:$B,MATCH("Legacy V1.5 base deorbit end year",Assumptions!$A$1:$A$257,0))-INDEX(Assumptions!$B:$B,MATCH("Legacy V1.5 base deorbit start year",Assumptions!$A$1:$A$257,0))+1),0)) -> 0 | ... S41: =MAX(0, R41 - IF(AND(S$4>=INDEX(Assumptions!$B:$B,MATCH("Legacy V1.5 base deorbit start year",Assumptions!$A$1:$A$257,0)),S$4<=INDEX(Assumptions!$B:$B,MATCH("Legacy V1.5 base deorbit end year",Assumptions!$A$1:$A$257,0))),$D$41/(INDEX(Assumptions!$B:$B,MATCH("Legacy V1.5 base deorbit end year",Assumptions!$A$1:$A$257,0))-INDEX(Assumptions!$B:$B,MATCH("Legacy V1.5 base deorbit start year",Assumptions!$A$1:$A$257,0))+1),0)) -> 0
A42: V2 Mini BB active sats | D42: =INDEX(Assumptions!$B:$B,MATCH("V2 Mini BB sats end-2025",Assumptions!$A$1:$A$257,0)) -> 4314 | E42: {=MAX(0, D42 + E$32 - IFERROR(IF(E$5-$D$15>=1, INDEX($D$32:$AC$32, E$5-$D$15+1), 0),0) - IF(AND(E$4>=INDEX(Assumptions!$B:$B,MATCH("V2 Mini BB base deorbit start year",Assumptions!$A$1:$A$257,0)),E$4<=INDEX(Assumptions!$B:$B,MATCH("V2 Mini BB base deorbit end year",Assumptions!$A$1:$A$257,0))),$D$42/(INDEX(Assumptions!$B:$B,MATCH("V2 Mini BB base deorbit end year",Assumptions!$A$1:$A$257,0))-INDEX(Assumptions!$B:$B,MATCH("V2 Mini BB base deorbit start year",Assumptions!$A$1:$A$257,0))+1),0))} -> 7434 | F42: {=MAX(0, E42 + F$32 - IFERROR(IF(F$5-$D$15>=1, INDEX($D$32:$AC$32, F$5-$D$15+1), 0),0) - IF(AND(F$4>=INDEX(Assumptions!$B:$B,MATCH("V2 Mini BB base deorbit start year",Assumptions!$A$1:$A$257,0)),F$4<=INDEX(Assumptions!$B:$B,MATCH("V2 Mini BB base deorbit end year",Assumptions!$A$1:$A$257,0))),$D$42/(INDEX(Assumptions!$B:$B,MATCH("V2 Mini BB base deorbit end year",Assumptions!$A$1:$A$257,0))-INDEX(Assumptions!$B:$B,MATCH("V2 Mini BB base deorbit start year",Assumptions!$A$1:$A$257,0))+1),0))} -> 7434 | G42: {=MAX(0, F42 + G$32 - IFERROR(IF(G$5-$D$15>=1, INDEX($D$32:$AC$32, G$5-$D$15+1), 0),0) - IF(AND(G$4>=INDEX(Assumptions!$B:$B,MATCH("V2 Mini BB base deorbit start year",Assumptions!$A$1:$A$257,0)),G$4<=INDEX(Assumptions!$B:$B,MATCH("V2 Mini BB base deorbit end year",Assumptions!$A$1:$A$257,0))),$D$42/(INDEX(Assumptions!$B:$B,MATCH("V2 Mini BB base deorbit end year",Assumptions!$A$1:$A$257,0))-INDEX(Assumptions!$B:$B,MATCH("V2 Mini BB base deorbit start year",Assumptions!$A$1:$A$257,0))+1),0))} -> 5996 | H42: {=MAX(0, G42 + H$32 - IFERROR(IF(H$5-$D$15>=1, INDEX($D$32:$AC$32, H$5-$D$15+1), 0),0) - IF(AND(H$4>=INDEX(Assumptions!$B:$B,MATCH("V2 Mini BB base deorbit start year",Assumptions!$A$1:$A$257,0)),H$4<=INDEX(Assumptions!$B:$B,MATCH("V2 Mini BB base deorbit end year",Assumptions!$A$1:$A$257,0))),$D$42/(INDEX(Assumptions!$B:$B,MATCH("V2 Mini BB base deorbit end year",Assumptions!$A$1:$A$257,0))-INDEX(Assumptions!$B:$B,MATCH("V2 Mini BB base deorbit start year",Assumptions!$A$1:$A$257,0))+1),0))} -> 4558 | I42: {=MAX(0, H42 + I$32 - IFERROR(IF(I$5-$D$15>=1, INDEX($D$32:$AC$32, I$5-$D$15+1), 0),0) - IF(AND(I$4>=INDEX(Assumptions!$B:$B,MATCH("V2 Mini BB base deorbit start year",Assumptions!$A$1:$A$257,0)),I$4<=INDEX(Assumptions!$B:$B,MATCH("V2 Mini BB base deorbit end year",Assumptions!$A$1:$A$257,0))),$D$42/(INDEX(Assumptions!$B:$B,MATCH("V2 Mini BB base deorbit end year",Assumptions!$A$1:$A$257,0))-INDEX(Assumptions!$B:$B,MATCH("V2 Mini BB base deorbit start year",Assumptions!$A$1:$A$257,0))+1),0))} -> 3120 | J42: {=MAX(0, I42 + J$32 - IFERROR(IF(J$5-$D$15>=1, INDEX($D$32:$AC$32, J$5-$D$15+1), 0),0) - IF(AND(J$4>=INDEX(Assumptions!$B:$B,MATCH("V2 Mini BB base deorbit start year",Assumptions!$A$1:$A$257,0)),J$4<=INDEX(Assumptions!$B:$B,MATCH("V2 Mini BB base deorbit end year",Assumptions!$A$1:$A$257,0))),$D$42/(INDEX(Assumptions!$B:$B,MATCH("V2 Mini BB base deorbit end year",Assumptions!$A$1:$A$257,0))-INDEX(Assumptions!$B:$B,MATCH("V2 Mini BB base deorbit start year",Assumptions!$A$1:$A$257,0))+1),0))} -> 0 | K42: {=MAX(0, J42 + K$32 - IFERROR(IF(K$5-$D$15>=1, INDEX($D$32:$AC$32, K$5-$D$15+1), 0),0) - IF(AND(K$4>=INDEX(Assumptions!$B:$B,MATCH("V2 Mini BB base deorbit start year",Assumptions!$A$1:$A$257,0)),K$4<=INDEX(Assumptions!$B:$B,MATCH("V2 Mini BB base deorbit end year",Assumptions!$A$1:$A$257,0))),$D$42/(INDEX(Assumptions!$B:$B,MATCH("V2 Mini BB base deorbit end year",Assumptions!$A$1:$A$257,0))-INDEX(Assumptions!$B:$B,MATCH("V2 Mini BB base deorbit start year",Assumptions!$A$1:$A$257,0))+1),0))} -> 0 | L42: {=MAX(0, K42 + L$32 - IFERROR(IF(L$5-$D$15>=1, INDEX($D$32:$AC$32, L$5-$D$15+1), 0),0) - IF(AND(L$4>=INDEX(Assumptions!$B:$B,MATCH("V2 Mini BB base deorbit start year",Assumptions!$A$1:$A$257,0)),L$4<=INDEX(Assumptions!$B:$B,MATCH("V2 Mini BB base deorbit end year",Assumptions!$A$1:$A$257,0))),$D$42/(INDEX(Assumptions!$B:$B,MATCH("V2 Mini BB base deorbit end year",Assumptions!$A$1:$A$257,0))-INDEX(Assumptions!$B:$B,MATCH("V2 Mini BB base deorbit start year",Assumptions!$A$1:$A$257,0))+1),0))} -> 0 | ... S42: {=MAX(0, R42 + S$32 - IFERROR(IF(S$5-$D$15>=1, INDEX($D$32:$AC$32, S$5-$D$15+1), 0),0) - IF(AND(S$4>=INDEX(Assumptions!$B:$B,MATCH("V2 Mini BB base deorbit start year",Assumptions!$A$1:$A$257,0)),S$4<=INDEX(Assumptions!$B:$B,MATCH("V2 Mini BB base deorbit end year",Assumptions!$A$1:$A$257,0))),$D$42/(INDEX(Assumptions!$B:$B,MATCH("V2 Mini BB base deorbit end year",Assumptions!$A$1:$A$257,0))-INDEX(Assumptions!$B:$B,MATCH("V2 Mini BB base deorbit start year",Assumptions!$A$1:$A$257,0))+1),0))} -> 0
A43: V3 BB active sats EoY | D43: =0 -> 0 | E43: {=MAX(0, D43 + E$34 - IFERROR(IF(E$5-$D$15>=1, INDEX($D$34:$AC$34, E$5-$D$15+1), 0),0))} -> 0 | F43: {=MAX(0, E43 + F$34 - IFERROR(IF(F$5-$D$15>=1, INDEX($D$34:$AC$34, F$5-$D$15+1), 0),0))} -> 3916.8534 | G43: {=MAX(0, F43 + G$34 - IFERROR(IF(G$5-$D$15>=1, INDEX($D$34:$AC$34, G$5-$D$15+1), 0),0))} -> 13334.209 | H43: {=MAX(0, G43 + H$34 - IFERROR(IF(H$5-$D$15>=1, INDEX($D$34:$AC$34, H$5-$D$15+1), 0),0))} -> 37268.771 | I43: {=MAX(0, H43 + I$34 - IFERROR(IF(I$5-$D$15>=1, INDEX($D$34:$AC$34, I$5-$D$15+1), 0),0))} -> 52299.886 | J43: {=MAX(0, I43 + J$34 - IFERROR(IF(J$5-$D$15>=1, INDEX($D$34:$AC$34, J$5-$D$15+1), 0),0))} -> 81246.796 | K43: {=MAX(0, J43 + K$34 - IFERROR(IF(K$5-$D$15>=1, INDEX($D$34:$AC$34, K$5-$D$15+1), 0),0))} -> 93730.001 | L43: {=MAX(0, K43 + L$34 - IFERROR(IF(L$5-$D$15>=1, INDEX($D$34:$AC$34, L$5-$D$15+1), 0),0))} -> 89181.52 | ... S43: {=MAX(0, R43 + S$34 - IFERROR(IF(S$5-$D$15>=1, INDEX($D$34:$AC$34, S$5-$D$15+1), 0),0))} -> 188862.32
A45: BB BANDWIDTH (Gbps by cohort)
