Workbook

Sheet Assumptions
D1: 2025 | E1: 2026 | F1: 2027 | G1: 2028 | H1: 2029 | I1: 2030 | J1: 2031 | K1: 2032 | L1: 2033 | M1: 2034 | N1: 2035 | O1: 2036 | P1: 2037 | Q1: 2038 | R1: 2039 | S1: 2040 | T1: 2041 | U1: 2042 | V1: 2043 | W1: 2044 | X1: 2045 | Y1: 2046 | Z1: 2047 | AA1: 2048 | AB1: 2049 | AC1: 2050
A2: GLOBAL | D2: 0 | E2: 1 | F2: 2 | G2: 3 | H2: 4 | I2: 5 | J2: 6 | K2: 7 | L2: 8 | M2: 9 | N2: 10 | O2: 11 | P2: 12 | Q2: 13 | R2: 14 | S2: 15 | T2: 16 | U2: 17 | V2: 18 | W2: 19 | X2: 20 | Y2: 21 | Z2: 22 | AA2: 23 | AB2: 24 | AC2: 25
A3: Tax rate (corporate, US federal + state blended) | B3: 0.21 | C3: Standard US corporate rate; S-1 silent on effective rate split. | AG3: 0.18 | AH3: 0.27 | AI3: triangle | AJ3: NO S-1 DATA: keep 21% federal stat
A4: Demand curve escalator: start rate (annual) | B4: 0.035 | C4: Early willingness-to-pay growth above inflation. Targets 2050 total Starlink revenue of roughly $640–660bn (before direct-to-cell). Monte Carlo range 0.045–0.060. | D4: 2025 | E4: 2026 | F4: 2027 | G4: 2028 | H4: 2029 | I4: 2030 | J4: 2031 | K4: 2032 | L4: 2033 | M4: 2034 | N4: 2035 | O4: 2036 | P4: 2037 | Q4: 2038 | R4: 2039 | S4: 2040 | AG4: 0.025 | AH4: 0.05 | AI4: triangle | AJ4: Escalator start rate; early willingness-to-pay growth above inflation
A5: Demand curve escalator: terminal rate (annual) | B5: 0.025 | C5: Mature-market escalator ≈ inflation. The tapered curve converges here after the taper ends. Monte Carlo range 0.035–0.045. | D5: 0 | E5: 1 | F5: 2 | G5: 3 | H5: 4 | I5: 5 | J5: 6 | K5: 7 | L5: 8 | M5: 9 | N5: 10 | O5: 11 | P5: 12 | Q5: 13 | R5: 14 | S5: 15 | AG5: 0.02 | AH5: 0.03 | AI5: triangle | AJ5: Escalator terminal rate ≈ inflation
A6: ALLOCATOR
A7: ▸ Cash pool boundary inputs
A8: Starting cash position EoY 2024 ($mm) | B8: 11385 | C8: S-1 p.21 BS audited cash & equivalents 12-31-24. Build Plan had $5,000, corrected by S-1. | AG8: 8000 | AH8: 25000 | AI8: triangle | AJ8: S-1 OVERRIDE p.21: MC top widened to capture EoY 2025 = $24,747M
A9: IPO injection amount ($mm) | B9: 45000 | C9: IPO proceeds target not disclosed; placeholder. | AG9: 30000 | AH9: 60000 | AI9: lognormal | AJ9: NO S-1 DATA: refresh on S-1/A pricing range
A10: IPO injection year | B10: 2027 | C10: S-1 filed May 2026 implies pricing 2H 2026 / early 2027. Holding 2027 pending S-1/A. | AG10: 2026 | AH10: 2028 | AI10: discrete | AJ10: S-1 PARTIAL: filed 2026-05-20
A11: ▸ Lunar/Mars strategic carve-out (Monte Carlo variable)
A12: Lunar/Mars carve-out % of prior-year Group FCF | B12: 0.15 | C12: Mars spend is not broken out separately (Starship R&D is co-mingled), so it is held here. | AG12: 0.03 | AH12: 0.35 | AI12: triangle | AJ12: No S-1 data: dedicated spend unknown
A13: Lunar/Mars carve-out floor ($mm/yr) | B13: 1000 | C13: Floor below which carve-out doesn't drop even if prior FCF is small. | AG13: 500 | AH13: 2500 | AI13: triangle | AJ13: NO S-1 DATA: MC-variable
A14: Lunar/Mars carve-out uses prior-year FCF (0/1) | B14: 1 | C14: 1 = prior year (breaks circularity per Principle 22). Structural input. | AI14: fixed | AJ14: Structural lock
A15: Lunar/Mars carve-out pre-first-mission-year R&D-only override ($mm/yr) | B15: 700 | C15: Q4'25 R425 anchored. Pre-2028 no missions; carve-out = R&D-only $700M. | AI15: fixed | AJ15: Q4'25 ANCHOR
A16: ▸ IRR-weighted allocation parameters
A17: Allocation sharpness β (top-level 3-module blend) | B17: 3 | C17: At β = 10, a 10pp IRR gap implies roughly a 73/27 share split — moderate concentration. | AG17: 3 | AH17: 20 | AI17: triangle | AJ17: NO S-1 DATA: MC tunes concentration vs diversification
A18: ▸ Per-module asset life L (canonical IRR formula input)
A19: Asset life L: Customer Launch Starship (years) | B19: 8 | C19: F9 booster analog (lifetime reuses ramp). | AG19: 6 | AH19: 10 | AI19: triangle | AJ19: NO S-1 DATA
A20: Asset life L: Customer Launch F9 (years) | B20: 8 | C20: Customer Launch IRR anchor. | AG20: 6 | AH20: 10 | AI20: triangle | AJ20: NO S-1 DATA
A21: Asset life L: AI/Compute Orbital DC (years) | B21: 5 | C21: Sat-based; matches Starlink sat life. | AG21: 4 | AH21: 7 | AI21: triangle | AJ21: NO S-1 DATA
A22: Asset life L: AI/Compute Terrestrial DC (years) | B22: 15 | C22: Industry norm for DC infrastructure. | AG22: 10 | AH22: 20 | AI22: triangle | AJ22: NO S-1 DATA
A23: Asset life L: AI/Compute AI Apps (years) | B23: 3 | C23: Customer subscription life / CAC payback. | AG23: 2 | AH23: 5 | AI23: triangle | AJ23: NO S-1 DATA
A24: ▸ Customer Launch IRR life clamps
A25: ▸ Vehicle build claim (demand-pulled, one-period lag)
A26: CAPACITY (Starship + F9)
A27: ▸ Starship vehicle physical + cost parameters
A28: Starship 2nd-stage manufacturing cost ($mm/unit, base) | B28: 23.4 | C28: Reusability matrix anchor. | AG28: 18 | AH28: 30 | AI28: triangle | AJ28: NO S-1 DATA
A29: Ship refurb % of manufacturing | B29: 0.02 | C29: Per-reuse refurb cost. | AG29: 0.01 | AH29: 0.05 | AI29: triangle | AJ29: NO S-1 DATA
A30: Payload: booster-only mode (kg-to-LEO) | B30: 150000 | C30: Expendable ship config. S-1 (p.92) confirms 100 mt V3 → 200 mt V4 potentially. 150K kg booster-only sits between V3 and V4. | AG30: 130000 | AH30: 200000 | AI30: triangle | AJ30: S-1 PARTIAL: keep, flag V4 upgrade
A31: Payload: fully reusable mode (kg-to-LEO) | B31: 100000 | C31: S-1 p.92 EXPLICIT: V3 design 100 mt. Match. | AG31: 80000 | AH31: 150000 | AI31: triangle | AJ31: S-1 CONFIRMS p.92
A32: ▸ Starship cadence (Wright's Law on cum upmass)
A33: Base turnaround time per booster (years/flight) | B33: 1 | C33: 2025 starting point. | AG33: 0.8 | AH33: 1.5 | AI33: triangle | AJ33: NO S-1 DATA
A34: WL learning rate: turnaround vs cum upmass doubling | B34: 0.21 | C34: Booster learning rate (0.21). Cumulative experience compounds faster than an annual proxy. Monte Carlo range 0.15–0.28. Holds the rising 6→~22 booster cadence ramp. | AG34: 0.05 | AH34: 0.25 | AI34: triangle | AJ34: NO S-1 DATA: Q4'25 R18 range
A35: Cadence ceiling (flights/booster/year) | B35: 60 | C35: Physical refly ceiling at full maturity. | AG35: 40 | AH35: 100 | AI35: triangle | AJ35: NO S-1 DATA
A36: ▸ Starship time-varying inputs (year-rows)
A37: Lifetime reuses per booster (year cap) | C37: Ramps 5 → 100. S-1 anchors F9 at 34x (p.4); soft-anchor 2025 to ~30-35 for F9-class maturity. | D37: 5 | E37: 8 | F37: 12 | G37: 18 | H37: 25 | I37: 30 | J37: 35 | K37: 42 | L37: 50 | M37: 58 | N37: 65 | O37: 70 | P37: 75 | Q37: 80 | R37: 85 | S37: 90 | AI37: fixed-yearrow | AJ37: S-1 PARTIAL p.4
A38: ▸ Falcon 9 physical + cost parameters
A39: F9 booster (1st stage) mfg cost ($mm/unit) | B39: 30 | C39: 60% of total per reusability matrix source notes. S-1 silent. | AG39: 25 | AH39: 35 | AI39: triangle | AJ39: NO S-1 DATA
A40: F9 2nd stage mfg cost ($mm/unit) | B40: 10 | C40: Expendable each flight. | AG40: 8 | AH40: 13 | AI40: triangle | AJ40: NO S-1 DATA
...

Sheet Demand Curves
A1: Demand Curves: Starlink BB + DTC piecewise-linear lookup
A2: Lookup form: INDEX/MATCH(..., 1) bracket-find + manual linear interp. NO FORECAST / TREND. Per Memory Snapshot v3 §2.4.
D4: 2025 | E4: 2026 | F4: 2027 | G4: 2028 | H4: 2029 | I4: 2030 | J4: 2031 | K4: 2032 | L4: 2033 | M4: 2034 | N4: 2035 | O4: 2036 | P4: 2037 | Q4: 2038 | R4: 2039 | S4: 2040
D5: 0 | E5: 1 | F5: 2 | G5: 3 | H5: 4 | I5: 5 | J5: 6 | K5: 7 | L5: 8 | M5: 9 | N5: 10 | O5: 11 | P5: 12 | Q5: 13 | R5: 14 | S5: 15
A15: DTC DEMAND CURVE (piecewise-linear Q→Revenue lookup)
A16: Constellation Bandwidth (Gbps) | B16: Q (Gbps) | C16: Annual DTC Revenue ($mm)
A17: DTC Q breakpoint #1 (Gbps) | B17: 280.2 | C17: 307
A18: DTC Q breakpoint #2 (Gbps) | B18: 560.3 | C18: 613
A19: DTC Q breakpoint #3 (Gbps) | B19: 840.5 | C19: 920
A20: DTC Q breakpoint #4 (Gbps) | B20: 1120.6 | C20: 1227
A21: DTC Q breakpoint #5 (Gbps) | B21: 1400.8 | C21: 1534
A22: DTC Q breakpoint #6 (Gbps) | B22: 1680.9 | C22: 1840
A23: DTC Q breakpoint #7 (Gbps) | B23: 1961.1 | C23: 2147
A24: DTC Q breakpoint #8 (Gbps) | B24: 2241.2 | C24: 2454
A25: DTC Q breakpoint #9 (Gbps) | B25: 2521.4 | C25: 2760
A26: DTC Q breakpoint #10 (Gbps) | B26: 2801.5 | C26: 3067
A27: DTC Q breakpoint #11 (Gbps) | B27: 3501.9 | C27: 3827
A28: DTC Q breakpoint #12 (Gbps) | B28: 4202.3 | C28: 4587
... A77: DTC Q breakpoint #61 (Gbps) | B77: 84046.3 | C77: 15920
A80: BB DEMAND CURVE (piecewise-linear Q→Revenue lookup)
A81: Capacity (Gbps) | B81: Q (Gbps) | C81: BB TAM/Revenue ($mm)
A82: BB Q breakpoint #1 (Gbps) | B82: 100000 | C82: 2936
A83: BB Q breakpoint #2 (Gbps) | B83: 200000 | C83: 3748
A84: BB Q breakpoint #3 (Gbps) | B84: 300000 | C84: 4559
A85: BB Q breakpoint #4 (Gbps) | B85: 400000 | C85: 5370
A86: BB Q breakpoint #5 (Gbps) | B86: 500000 | C86: 6157
A87: BB Q breakpoint #6 (Gbps) | B87: 1000000 | C87: 10055
A88: BB Q breakpoint #7 (Gbps) | B88: 2000000 | C88: 17173
A89: BB Q breakpoint #8 (Gbps) | B89: 3000000 | C89: 23037
A90: BB Q breakpoint #9 (Gbps) | B90: 4000000 | C90: 28430
A91: BB Q breakpoint #10 (Gbps) | B91: 5000000 | C91: 33451
A92: BB Q breakpoint #11 (Gbps) | B92: 6000000 | C92: 38244
A93: BB Q breakpoint #12 (Gbps) | B93: 7000000 | C93: 42520
... A137: BB Q breakpoint #56 (Gbps) | B137: 250000000 | C137: 187819
A140: ▸ Curve evaluators (year-row, read by the Starlink module)
A141: Annual TAM shift multiplier | D141: =1 -> 1 | E141: =D141*(1+E149) -> 1.035 | F141: =E141*(1+F149) -> 1.070075 | G141: =F141*(1+G149) -> 1.1051497 | H141: =G141*(1+H149) -> 1.1401461 | I141: =H141*(1+I149) -> 1.1749839 | J141: =I141*(1+J149) -> 1.2095806 | K141: =J141*(1+K149) -> 1.2438521 | L141: =K141*(1+L149) -> 1.2777125 | ... S141: =R141*(1+S149) -> 1.520445
A142: Starlink BB capacity input (Gbps) | D142: {=IFERROR(INDEX(Starlink!$D:$AC,MATCH("BB Gbps available for external Starlink revenue",Starlink!$A$1:$A$205,0),COLUMN()-COLUMN($D142)+1),0)} -> 489144 | E142: {=IFERROR(INDEX(Starlink!$D:$AC,MATCH("BB Gbps available for external Starlink revenue",Starlink!$A$1:$A$205,0),COLUMN()-COLUMN($D142)+1),0)} -> 756736 | F142: {=IFERROR(INDEX(Starlink!$D:$AC,MATCH("BB Gbps available for external Starlink revenue",Starlink!$A$1:$A$205,0),COLUMN()-COLUMN($D142)+1),0)} -> 4652054.4 | G142: {=IFERROR(INDEX(Starlink!$D:$AC,MATCH("BB Gbps available for external Starlink revenue",Starlink!$A$1:$A$205,0),COLUMN()-COLUMN($D142)+1),0)} -> 13909803 | H142: {=IFERROR(INDEX(Starlink!$D:$AC,MATCH("BB Gbps available for external Starlink revenue",Starlink!$A$1:$A$205,0),COLUMN()-COLUMN($D142)+1),0)} -> 34094523 | I142: {=IFERROR(INDEX(Starlink!$D:$AC,MATCH("BB Gbps available for external Starlink revenue",Starlink!$A$1:$A$205,0),COLUMN()-COLUMN($D142)+1),0)} -> 46320469 | J142: {=IFERROR(INDEX(Starlink!$D:$AC,MATCH("BB Gbps available for external Starlink revenue",Starlink!$A$1:$A$205,0),COLUMN()-COLUMN($D142)+1),0)} -> 73672560 | K142: {=IFERROR(INDEX(Starlink!$D:$AC,MATCH("BB Gbps available for external Starlink revenue",Starlink!$A$1:$A$205,0),COLUMN()-COLUMN($D142)+1),0)} -> 82297889 | ... S142: {=IFERROR(INDEX(Starlink!$D:$AC,MATCH("BB Gbps available for external Starlink revenue",Starlink!$A$1:$A$205,0),COLUMN()-COLUMN($D142)+1),0)} -> 1.9521171e+08
A143: Starlink DTC capacity input (Gbps) | D143: {=IFERROR(INDEX(Starlink!$D:$AC,MATCH("DTC Gbps available for external Starlink revenue",Starlink!$A$1:$A$205,0),COLUMN()-COLUMN($D143)+1),0)} -> 577.71 | E143: {=IFERROR(INDEX(Starlink!$D:$AC,MATCH("DTC Gbps available for external Starlink revenue",Starlink!$A$1:$A$205,0),COLUMN()-COLUMN($D143)+1),0)} -> 577.71 | F143: {=IFERROR(INDEX(Starlink!$D:$AC,MATCH("DTC Gbps available for external Starlink revenue",Starlink!$A$1:$A$205,0),COLUMN()-COLUMN($D143)+1),0)} -> 579.36898 | G143: {=IFERROR(INDEX(Starlink!$D:$AC,MATCH("DTC Gbps available for external Starlink revenue",Starlink!$A$1:$A$205,0),COLUMN()-COLUMN($D143)+1),0)} -> 649.97109 | H143: {=IFERROR(INDEX(Starlink!$D:$AC,MATCH("DTC Gbps available for external Starlink revenue",Starlink!$A$1:$A$205,0),COLUMN()-COLUMN($D143)+1),0)} -> 2675.9981 | I143: {=IFERROR(INDEX(Starlink!$D:$AC,MATCH("DTC Gbps available for external Starlink revenue",Starlink!$A$1:$A$205,0),COLUMN()-COLUMN($D143)+1),0)} -> 22412.908 | J143: {=IFERROR(INDEX(Starlink!$D:$AC,MATCH("DTC Gbps available for external Starlink revenue",Starlink!$A$1:$A$205,0),COLUMN()-COLUMN($D143)+1),0)} -> 47287.791 | K143: {=IFERROR(INDEX(Starlink!$D:$AC,MATCH("DTC Gbps available for external Starlink revenue",Starlink!$A$1:$A$205,0),COLUMN()-COLUMN($D143)+1),0)} -> 71156.613 | ... S143: {=IFERROR(INDEX(Starlink!$D:$AC,MATCH("DTC Gbps available for external Starlink revenue",Starlink!$A$1:$A$205,0),COLUMN()-COLUMN($D143)+1),0)} -> 136991.06
A144: Starlink BB Revenue from curve ($mm) | D144: {=((IF(D142>=INDEX($B$82:$B$137,COUNTA($B$82:$B$137)),INDEX($C$82:$C$137,COUNTA($B$82:$B$137))*D141,IF(D142<=INDEX($B$82:$B$137,1),INDEX($C$82:$C$137,1)*D141,(INDEX($C$82:$C$137,MATCH(D142,$B$82:$B$137,1))+(D142-INDEX($B$82:$B$137,MATCH(D142,$B$82:$B$137,1)))*(INDEX($C$82:$C$137,MATCH(D142,$B$82:$B$137,1)+1)-INDEX($C$82:$C$137,MATCH(D142,$B$82:$B$137,1)))/(INDEX($B$82:$B$137,MATCH(D142,$B$82:$B$137,1)+1)-INDEX($B$82:$B$137,MATCH(D142,$B$82:$B$137,1))))*D141)))*INDEX(Assumptions!$B:$B,MATCH("BB demand curve level multiplier",Assumptions!$A$1:$A$327,0)))*D151} -> 6721.2206 | E144: {=((IF(E142>=INDEX($B$82:$B$137,COUNTA($B$82:$B$137)),INDEX($C$82:$C$137,COUNTA($B$82:$B$137))*E141,IF(E142<=INDEX($B$82:$B$137,1),INDEX($C$82:$C$137,1)*E141,(INDEX($C$82:$C$137,MATCH(E142,$B$82:$B$137,1))+(E142-INDEX($B$82:$B$137,MATCH(E142,$B$82:$B$137,1)))*(INDEX($C$82:$C$137,MATCH(E142,$B$82:$B$137,1)+1)-INDEX($C$82:$C$137,MATCH(E142,$B$82:$B$137,1)))/(INDEX($B$82:$B$137,MATCH(E142,$B$82:$B$137,1)+1)-INDEX($B$82:$B$137,MATCH(E142,$B$82:$B$137,1))))*E141)))*INDEX(Assumptions!$B:$B,MATCH("BB demand curve level multiplier",Assumptions!$A$1:$A$327,0)))*E151} -> 9347.5765 | F144: {=((IF(F142>=INDEX($B$82:$B$137,COUNTA($B$82:$B$137)),INDEX($C$82:$C$137,COUNTA($B$82:$B$137))*F141,IF(F142<=INDEX($B$82:$B$137,1),INDEX($C$82:$C$137,1)*F141,(INDEX($C$82:$C$137,MATCH(F142,$B$82:$B$137,1))+(F142-INDEX($B$82:$B$137,MATCH(F142,$B$82:$B$137,1)))*(INDEX($C$82:$C$137,MATCH(F142,$B$82:$B$137,1)+1)-INDEX($C$82:$C$137,MATCH(F142,$B$82:$B$137,1)))/(INDEX($B$82:$B$137,MATCH(F142,$B$82:$B$137,1)+1)-INDEX($B$82:$B$137,MATCH(F142,$B$82:$B$137,1))))*F141)))*INDEX(Assumptions!$B:$B,MATCH("BB demand curve level multiplier",Assumptions!$A$1:$A$327,0)))*F151} -> 37555.662 | G144: {=((IF(G142>=INDEX($B$82:$B$137,COUNTA($B$82:$B$137)),INDEX($C$82:$C$137,COUNTA($B$82:$B$137))*G141,IF(G142<=INDEX($B$82:$B$137,1),INDEX($C$82:$C$137,1)*G141,(INDEX($C$82:$C$137,MATCH(G142,$B$82:$B$137,1))+(G142-INDEX($B$82:$B$137,MATCH(G142,$B$82:$B$137,1)))*(INDEX($C$82:$C$137,MATCH(G142,$B$82:$B$137,1)+1)-INDEX($C$82:$C$137,MATCH(G142,$B$82:$B$137,1)))/(INDEX($B$82:$B$137,MATCH(G142,$B$82:$B$137,1)+1)-INDEX($B$82:$B$137,MATCH(G142,$B$82:$B$137,1))))*G141)))*INDEX(Assumptions!$B:$B,MATCH("BB demand curve level multiplier",Assumptions!$A$1:$A$327,0)))*G151} -> 80517.638 | H144: {=((IF(H142>=INDEX($B$82:$B$137,COUNTA($B$82:$B$137)),INDEX($C$82:$C$137,COUNTA($B$82:$B$137))*H141,IF(H142<=INDEX($B$82:$B$137,1),INDEX($C$82:$C$137,1)*H141,(INDEX($C$82:$C$137,MATCH(H142,$B$82:$B$137,1))+(H142-INDEX($B$82:$B$137,MATCH(H142,$B$82:$B$137,1)))*(INDEX($C$82:$C$137,MATCH(H142,$B$82:$B$137,1)+1)-INDEX($C$82:$C$137,MATCH(H142,$B$82:$B$137,1)))/(INDEX($B$82:$B$137,MATCH(H142,$B$82:$B$137,1)+1)-INDEX($B$82:$B$137,MATCH(H142,$B$82:$B$137,1))))*H141)))*INDEX(Assumptions!$B:$B,MATCH("BB demand curve level multiplier",Assumptions!$A$1:$A$327,0)))*H151} -> 133572.61 | I144: {=((IF(I142>=INDEX($B$82:$B$137,COUNTA($B$82:$B$137)),INDEX($C$82:$C$137,COUNTA($B$82:$B$137))*I141,IF(I142<=INDEX($B$82:$B$137,1),INDEX($C$82:$C$137,1)*I141,(INDEX($C$82:$C$137,MATCH(I142,$B$82:$B$137,1))+(I142-INDEX($B$82:$B$137,MATCH(I142,$B$82:$B$137,1)))*(INDEX($C$82:$C$137,MATCH(I142,$B$82:$B$137,1)+1)-INDEX($C$82:$C$137,MATCH(I142,$B$82:$B$137,1)))/(INDEX($B$82:$B$137,MATCH(I142,$B$82:$B$137,1)+1)-INDEX($B$82:$B$137,MATCH(I142,$B$82:$B$137,1))))*I141)))*INDEX(Assumptions!$B:$B,MATCH("BB demand curve level multiplier",Assumptions!$A$1:$A$327,0)))*I151} -> 162366.46 | J144: {=((IF(J142>=INDEX($B$82:$B$137,COUNTA($B$82:$B$137)),INDEX($C$82:$C$137,COUNTA($B$82:$B$137))*J141,IF(J142<=INDEX($B$82:$B$137,1),INDEX($C$82:$C$137,1)*J141,(INDEX($C$82:$C$137,MATCH(J142,$B$82:$B$137,1))+(J142-INDEX($B$82:$B$137,MATCH(J142,$B$82:$B$137,1)))*(INDEX($C$82:$C$137,MATCH(J142,$B$82:$B$137,1)+1)-INDEX($C$82:$C$137,MATCH(J142,$B$82:$B$137,1)))/(INDEX($B$82:$B$137,MATCH(J142,$B$82:$B$137,1)+1)-INDEX($B$82:$B$137,MATCH(J142,$B$82:$B$137,1))))*J141)))*INDEX(Assumptions!$B:$B,MATCH("BB demand curve level multiplier",Assumptions!$A$1:$A$327,0)))*J151} -> 198728.63 | K144: {=((IF(K142>=INDEX($B$82:$B$137,COUNTA($B$82:$B$137)),INDEX($C$82:$C$137,COUNTA($B$82:$B$137))*K141,IF(K142<=INDEX($B$82:$B$137,1),INDEX($C$82:$C$137,1)*K141,(INDEX($C$82:$C$137,MATCH(K142,$B$82:$B$137,1))+(K142-INDEX($B$82:$B$137,MATCH(K142,$B$82:$B$137,1)))*(INDEX($C$82:$C$137,MATCH(K142,$B$82:$B$137,1)+1)-INDEX($C$82:$C$137,MATCH(K142,$B$82:$B$137,1)))/(INDEX($B$82:$B$137,MATCH(K142,$B$82:$B$137,1)+1)-INDEX($B$82:$B$137,MATCH(K142,$B$82:$B$137,1))))*K141)))*INDEX(Assumptions!$B:$B,MATCH("BB demand curve level multiplier",Assumptions!$A$1:$A$327,0)))*K151} -> 212218.52 | ... S144: {=((IF(S142>=INDEX($B$82:$B$137,COUNTA($B$82:$B$137)),INDEX($C$82:$C$137,COUNTA($B$82:$B$137))*S141,IF(S142<=INDEX($B$82:$B$137,1),INDEX($C$82:$C$137,1)*S141,(INDEX($C$82:$C$137,MATCH(S142,$B$82:$B$137,1))+(S142-INDEX($B$82:$B$137,MATCH(S142,$B$82:$B$137,1)))*(INDEX($C$82:$C$137,MATCH(S142,$B$82:$B$137,1)+1)-INDEX($C$82:$C$137,MATCH(S142,$B$82:$B$137,1)))/(INDEX($B$82:$B$137,MATCH(S142,$B$82:$B$137,1)+1)-INDEX($B$82:$B$137,MATCH(S142,$B$82:$B$137,1))))*S141)))*INDEX(Assumptions!$B:$B,MATCH("BB demand curve level multiplier",Assumptions!$A$1:$A$327,0)))*S151} -> 305981.36
A145: Starlink DTC Revenue from curve ($mm) | D145: {=((IF(D143<=0,0,IF(D143>=INDEX($B$17:$B$77,COUNTA($B$17:$B$77)),INDEX($C$17:$C$77,COUNTA($B$17:$B$77))*D141,IF(D143<INDEX($B$17:$B$77,1),D143/INDEX($B$17:$B$77,1)*INDEX($C$17:$C$77,1)*D141,(INDEX($C$17:$C$77,MATCH(D143,$B$17:$B$77,1))+(D143-INDEX($B$17:$B$77,MATCH(D143,$B$17:$B$77,1)))*(INDEX($C$17:$C$77,MATCH(D143,$B$17:$B$77,1)+1)-INDEX($C$17:$C$77,MATCH(D143,$B$17:$B$77,1)))/(INDEX($B$17:$B$77,MATCH(D143,$B$17:$B$77,1)+1)-INDEX($B$17:$B$77,MATCH(D143,$B$17:$B$77,1))))*D141))))*INDEX(Assumptions!$B:$B,MATCH("DTC demand curve level multiplier",Assumptions!$A$1:$A$327,0)))*D150} -> 632.0752 | E145: {=((IF(E143<=0,0,IF(E143>=INDEX($B$17:$B$77,COUNTA($B$17:$B$77)),INDEX($C$17:$C$77,COUNTA($B$17:$B$77))*E141,IF(E143<INDEX($B$17:$B$77,1),E143/INDEX($B$17:$B$77,1)*INDEX($C$17:$C$77,1)*E141,(INDEX($C$17:$C$77,MATCH(E143,$B$17:$B$77,1))+(E143-INDEX($B$17:$B$77,MATCH(E143,$B$17:$B$77,1)))*(INDEX($C$17:$C$77,MATCH(E143,$B$17:$B$77,1)+1)-INDEX($C$17:$C$77,MATCH(E143,$B$17:$B$77,1)))/(INDEX($B$17:$B$77,MATCH(E143,$B$17:$B$77,1)+1)-INDEX($B$17:$B$77,MATCH(E143,$B$17:$B$77,1))))*E141))))*INDEX(Assumptions!$B:$B,MATCH("DTC demand curve level multiplier",Assumptions!$A$1:$A$327,0)))*E150} -> 794.38308 | F145: {=((IF(F143<=0,0,IF(F143>=INDEX($B$17:$B$77,COUNTA($B$17:$B$77)),INDEX($C$17:$C$77,COUNTA($B$17:$B$77))*F141,IF(F143<INDEX($B$17:$B$77,1),F143/INDEX($B$17:$B$77,1)*INDEX($C$17:$C$77,1)*F141,(INDEX($C$17:$C$77,MATCH(F143,$B$17:$B$77,1))+(F143-INDEX($B$17:$B$77,MATCH(F143,$B$17:$B$77,1)))*(INDEX($C$17:$C$77,MATCH(F143,$B$17:$B$77,1)+1)-INDEX($C$17:$C$77,MATCH(F143,$B$17:$B$77,1)))/(INDEX($B$17:$B$77,MATCH(F143,$B$17:$B$77,1)+1)-INDEX($B$17:$B$77,MATCH(F143,$B$17:$B$77,1))))*F141))))*INDEX(Assumptions!$B:$B,MATCH("DTC demand curve level multiplier",Assumptions!$A$1:$A$327,0)))*F150} -> 969.01841 | G145: {=((IF(G143<=0,0,IF(G143>=INDEX($B$17:$B$77,COUNTA($B$17:$B$77)),INDEX($C$17:$C$77,COUNTA($B$17:$B$77))*G141,IF(G143<INDEX($B$17:$B$77,1),G143/INDEX($B$17:$B$77,1)*INDEX($C$17:$C$77,1)*G141,(INDEX($C$17:$C$77,MATCH(G143,$B$17:$B$77,1))+(G143-INDEX($B$17:$B$77,MATCH(G143,$B$17:$B$77,1)))*(INDEX($C$17:$C$77,MATCH(G143,$B$17:$B$77,1)+1)-INDEX($C$17:$C$77,MATCH(G143,$B$17:$B$77,1)))/(INDEX($B$17:$B$77,MATCH(G143,$B$17:$B$77,1)+1)-INDEX($B$17:$B$77,MATCH(G143,$B$17:$B$77,1))))*G141))))*INDEX(Assumptions!$B:$B,MATCH("DTC demand curve level multiplier",Assumptions!$A$1:$A$327,0)))*G150} -> 1291.3436 | H145: {=((IF(H143<=0,0,IF(H143>=INDEX($B$17:$B$77,COUNTA($B$17:$B$77)),INDEX($C$17:$C$77,COUNTA($B$17:$B$77))*H141,IF(H143<INDEX($B$17:$B$77,1),H143/INDEX($B$17:$B$77,1)*INDEX($C$17:$C$77,1)*H141,(INDEX($C$17:$C$77,MATCH(H143,$B$17:$B$77,1))+(H143-INDEX($B$17:$B$77,MATCH(H143,$B$17:$B$77,1)))*(INDEX($C$17:$C$77,MATCH(H143,$B$17:$B$77,1)+1)-INDEX($C$17:$C$77,MATCH(H143,$B$17:$B$77,1)))/(INDEX($B$17:$B$77,MATCH(H143,$B$17:$B$77,1)+1)-INDEX($B$17:$B$77,MATCH(H143,$B$17:$B$77,1))))*H141))))*INDEX(Assumptions!$B:$B,MATCH("DTC demand curve level multiplier",Assumptions!$A$1:$A$327,0)))*H150} -> 6202.8488 | I145: {=((IF(I143<=0,0,IF(I143>=INDEX($B$17:$B$77,COUNTA($B$17:$B$77)),INDEX($C$17:$C$77,COUNTA($B$17:$B$77))*I141,IF(I143<INDEX($B$17:$B$77,1),I143/INDEX($B$17:$B$77,1)*INDEX($C$17:$C$77,1)*I141,(INDEX($C$17:$C$77,MATCH(I143,$B$17:$B$77,1))+(I143-INDEX($B$17:$B$77,MATCH(I143,$B$17:$B$77,1)))*(INDEX($C$17:$C$77,MATCH(I143,$B$17:$B$77,1)+1)-INDEX($C$17:$C$77,MATCH(I143,$B$17:$B$77,1)))/(INDEX($B$17:$B$77,MATCH(I143,$B$17:$B$77,1)+1)-INDEX($B$17:$B$77,MATCH(I143,$B$17:$B$77,1))))*I141))))*INDEX(Assumptions!$B:$B,MATCH("DTC demand curve level multiplier",Assumptions!$A$1:$A$327,0)))*I150} -> 30569.893 | J145: {=((IF(J143<=0,0,IF(J143>=INDEX($B$17:$B$77,COUNTA($B$17:$B$77)),INDEX($C$17:$C$77,COUNTA($B$17:$B$77))*J141,IF(J143<INDEX($B$17:$B$77,1),J143/INDEX($B$17:$B$77,1)*INDEX($C$17:$C$77,1)*J141,(INDEX($C$17:$C$77,MATCH(J143,$B$17:$B$77,1))+(J143-INDEX($B$17:$B$77,MATCH(J143,$B$17:$B$77,1)))*(INDEX($C$17:$C$77,MATCH(J143,$B$17:$B$77,1)+1)-INDEX($C$17:$C$77,MATCH(J143,$B$17:$B$77,1)))/(INDEX($B$17:$B$77,MATCH(J143,$B$17:$B$77,1)+1)-INDEX($B$17:$B$77,MATCH(J143,$B$17:$B$77,1))))*J141))))*INDEX(Assumptions!$B:$B,MATCH("DTC demand curve level multiplier",Assumptions!$A$1:$A$327,0)))*J150} -> 40144.794 | K145: {=((IF(K143<=0,0,IF(K143>=INDEX($B$17:$B$77,COUNTA($B$17:$B$77)),INDEX($C$17:$C$77,COUNTA($B$17:$B$77))*K141,IF(K143<INDEX($B$17:$B$77,1),K143/INDEX($B$17:$B$77,1)*INDEX($C$17:$C$77,1)*K141,(INDEX($C$17:$C$77,MATCH(K143,$B$17:$B$77,1))+(K143-INDEX($B$17:$B$77,MATCH(K143,$B$17:$B$77,1)))*(INDEX($C$17:$C$77,MATCH(K143,$B$17:$B$77,1)+1)-INDEX($C$17:$C$77,MATCH(K143,$B$17:$B$77,1)))/(INDEX($B$17:$B$77,MATCH(K143,$B$17:$B$77,1)+1)-INDEX($B$17:$B$77,MATCH(K143,$B$17:$B$77,1))))*K141))))*INDEX(Assumptions!$B:$B,MATCH("DTC demand curve level multiplier",Assumptions!$A$1:$A$327,0)))*K150} -> 47979.431 | ... S145: {=((IF(S143<=0,0,IF(S143>=INDEX($B$17:$B$77,COUNTA($B$17:$B$77)),INDEX($C$17:$C$77,COUNTA($B$17:$B$77))*S141,IF(S143<INDEX($B$17:$B$77,1),S143/INDEX($B$17:$B$77,1)*INDEX($C$17:$C$77,1)*S141,(INDEX($C$17:$C$77,MATCH(S143,$B$17:$B$77,1))+(S143-INDEX($B$17:$B$77,MATCH(S143,$B$17:$B$77,1)))*(INDEX($C$17:$C$77,MATCH(S143,$B$17:$B$77,1)+1)-INDEX($C$17:$C$77,MATCH(S143,$B$17:$B$77,1)))/(INDEX($B$17:$B$77,MATCH(S143,$B$17:$B$77,1)+1)-INDEX($B$17:$B$77,MATCH(S143,$B$17:$B$77,1))))*S141))))*INDEX(Assumptions!$B:$B,MATCH("DTC demand curve level multiplier",Assumptions!$A$1:$A$327,0)))*S150} -> 60513.713
...

Sheet Starlink
A1: Starlink module — real cohorts + total-bandwidth revenue + full waterfall + 4-line OpEx + per-sat IRR
D4: 2025 | E4: 2026 | F4: 2027 | G4: 2028 | H4: 2029 | I4: 2030 | J4: 2031 | K4: 2032 | L4: 2033 | M4: 2034 | N4: 2035 | O4: 2036 | P4: 2037 | Q4: 2038 | R4: 2039 | S4: 2040
D5: 0 | E5: 1 | F5: 2 | G5: 3 | H5: 4 | I5: 5 | J5: 6 | K5: 7 | L5: 8 | M5: 9 | N5: 10 | O5: 11 | P5: 12 | Q5: 13 | R5: 14 | S5: 15
A10: ▸ ALLOCATOR IN (cross-tab reads)
A11: Starlink BB Revenue from curve ($mm) | D11: {=INDEX('Demand Curves'!$D:$AC, MATCH("Starlink BB Revenue from curve ($mm)", 'Demand Curves'!$A$1:$A$167, 0), COLUMN()-COLUMN($D11)+1)} -> 6721.2206 | E11: {=INDEX('Demand Curves'!$D:$AC, MATCH("Starlink BB Revenue from curve ($mm)", 'Demand Curves'!$A$1:$A$167, 0), COLUMN()-COLUMN($D11)+1)} -> 9347.5765 | F11: {=INDEX('Demand Curves'!$D:$AC, MATCH("Starlink BB Revenue from curve ($mm)", 'Demand Curves'!$A$1:$A$167, 0), COLUMN()-COLUMN($D11)+1)} -> 37555.662 | G11: {=INDEX('Demand Curves'!$D:$AC, MATCH("Starlink BB Revenue from curve ($mm)", 'Demand Curves'!$A$1:$A$167, 0), COLUMN()-COLUMN($D11)+1)} -> 80517.638 | H11: {=INDEX('Demand Curves'!$D:$AC, MATCH("Starlink BB Revenue from curve ($mm)", 'Demand Curves'!$A$1:$A$167, 0), COLUMN()-COLUMN($D11)+1)} -> 133572.61 | I11: {=INDEX('Demand Curves'!$D:$AC, MATCH("Starlink BB Revenue from curve ($mm)", 'Demand Curves'!$A$1:$A$167, 0), COLUMN()-COLUMN($D11)+1)} -> 162366.46 | J11: {=INDEX('Demand Curves'!$D:$AC, MATCH("Starlink BB Revenue from curve ($mm)", 'Demand Curves'!$A$1:$A$167, 0), COLUMN()-COLUMN($D11)+1)} -> 198728.63 | K11: {=INDEX('Demand Curves'!$D:$AC, MATCH("Starlink BB Revenue from curve ($mm)", 'Demand Curves'!$A$1:$A$167, 0), COLUMN()-COLUMN($D11)+1)} -> 212218.52 | ... S11: {=INDEX('Demand Curves'!$D:$AC, MATCH("Starlink BB Revenue from curve ($mm)", 'Demand Curves'!$A$1:$A$167, 0), COLUMN()-COLUMN($D11)+1)} -> 305981.36
A12: Starlink DTC Revenue from curve ($mm) | D12: {=INDEX('Demand Curves'!$D:$AC, MATCH("Starlink DTC Revenue from curve ($mm)", 'Demand Curves'!$A$1:$A$167, 0), COLUMN()-COLUMN($D12)+1)} -> 632.0752 | E12: {=INDEX('Demand Curves'!$D:$AC, MATCH("Starlink DTC Revenue from curve ($mm)", 'Demand Curves'!$A$1:$A$167, 0), COLUMN()-COLUMN($D12)+1)} -> 794.38308 | F12: {=INDEX('Demand Curves'!$D:$AC, MATCH("Starlink DTC Revenue from curve ($mm)", 'Demand Curves'!$A$1:$A$167, 0), COLUMN()-COLUMN($D12)+1)} -> 969.01841 | G12: {=INDEX('Demand Curves'!$D:$AC, MATCH("Starlink DTC Revenue from curve ($mm)", 'Demand Curves'!$A$1:$A$167, 0), COLUMN()-COLUMN($D12)+1)} -> 1291.3436 | H12: {=INDEX('Demand Curves'!$D:$AC, MATCH("Starlink DTC Revenue from curve ($mm)", 'Demand Curves'!$A$1:$A$167, 0), COLUMN()-COLUMN($D12)+1)} -> 6202.8488 | I12: {=INDEX('Demand Curves'!$D:$AC, MATCH("Starlink DTC Revenue from curve ($mm)", 'Demand Curves'!$A$1:$A$167, 0), COLUMN()-COLUMN($D12)+1)} -> 30569.893 | J12: {=INDEX('Demand Curves'!$D:$AC, MATCH("Starlink DTC Revenue from curve ($mm)", 'Demand Curves'!$A$1:$A$167, 0), COLUMN()-COLUMN($D12)+1)} -> 40144.794 | K12: {=INDEX('Demand Curves'!$D:$AC, MATCH("Starlink DTC Revenue from curve ($mm)", 'Demand Curves'!$A$1:$A$167, 0), COLUMN()-COLUMN($D12)+1)} -> 47979.431 | ... S12: {=INDEX('Demand Curves'!$D:$AC, MATCH("Starlink DTC Revenue from curve ($mm)", 'Demand Curves'!$A$1:$A$167, 0), COLUMN()-COLUMN($D12)+1)} -> 60513.713
A13: F9 at-cost rate per launch ($mm) | D13: {=INDEX(Assumptions!$D:$AC, MATCH("F9 at-cost rate per launch ($mm)", Assumptions!$A$1:$A$327, 0), COLUMN()-COLUMN($D13)+1)} -> 20 | E13: {=INDEX(Assumptions!$D:$AC, MATCH("F9 at-cost rate per launch ($mm)", Assumptions!$A$1:$A$327, 0), COLUMN()-COLUMN($D13)+1)} -> 19.6 | F13: {=INDEX(Assumptions!$D:$AC, MATCH("F9 at-cost rate per launch ($mm)", Assumptions!$A$1:$A$327, 0), COLUMN()-COLUMN($D13)+1)} -> 19.208 | G13: {=INDEX(Assumptions!$D:$AC, MATCH("F9 at-cost rate per launch ($mm)", Assumptions!$A$1:$A$327, 0), COLUMN()-COLUMN($D13)+1)} -> 18.824 | H13: {=INDEX(Assumptions!$D:$AC, MATCH("F9 at-cost rate per launch ($mm)", Assumptions!$A$1:$A$327, 0), COLUMN()-COLUMN($D13)+1)} -> 18.447 | I13: {=INDEX(Assumptions!$D:$AC, MATCH("F9 at-cost rate per launch ($mm)", Assumptions!$A$1:$A$327, 0), COLUMN()-COLUMN($D13)+1)} -> 18.078 | J13: {=INDEX(Assumptions!$D:$AC, MATCH("F9 at-cost rate per launch ($mm)", Assumptions!$A$1:$A$327, 0), COLUMN()-COLUMN($D13)+1)} -> 17.717 | K13: {=INDEX(Assumptions!$D:$AC, MATCH("F9 at-cost rate per launch ($mm)", Assumptions!$A$1:$A$327, 0), COLUMN()-COLUMN($D13)+1)} -> 17.363 | ... S13: {=INDEX(Assumptions!$D:$AC, MATCH("F9 at-cost rate per launch ($mm)", Assumptions!$A$1:$A$327, 0), COLUMN()-COLUMN($D13)+1)} -> 14.772
A14: Starship at-cost rate per launch ($mm) | D14: {=INDEX(Assumptions!$D:$AC, MATCH("Starship at-cost rate per launch ($mm)", Assumptions!$A$1:$A$327, 0), COLUMN()-COLUMN($D14)+1)} -> 0 | E14: {=INDEX(Assumptions!$D:$AC, MATCH("Starship at-cost rate per launch ($mm)", Assumptions!$A$1:$A$327, 0), COLUMN()-COLUMN($D14)+1)} -> 0 | F14: {=INDEX(Assumptions!$D:$AC, MATCH("Starship at-cost rate per launch ($mm)", Assumptions!$A$1:$A$327, 0), COLUMN()-COLUMN($D14)+1)} -> 25 | G14: {=INDEX(Assumptions!$D:$AC, MATCH("Starship at-cost rate per launch ($mm)", Assumptions!$A$1:$A$327, 0), COLUMN()-COLUMN($D14)+1)} -> 23 | H14: {=INDEX(Assumptions!$D:$AC, MATCH("Starship at-cost rate per launch ($mm)", Assumptions!$A$1:$A$327, 0), COLUMN()-COLUMN($D14)+1)} -> 21.16 | I14: {=INDEX(Assumptions!$D:$AC, MATCH("Starship at-cost rate per launch ($mm)", Assumptions!$A$1:$A$327, 0), COLUMN()-COLUMN($D14)+1)} -> 19.467 | J14: {=INDEX(Assumptions!$D:$AC, MATCH("Starship at-cost rate per launch ($mm)", Assumptions!$A$1:$A$327, 0), COLUMN()-COLUMN($D14)+1)} -> 17.91 | K14: {=INDEX(Assumptions!$D:$AC, MATCH("Starship at-cost rate per launch ($mm)", Assumptions!$A$1:$A$327, 0), COLUMN()-COLUMN($D14)+1)} -> 16.477 | ... S14: {=INDEX(Assumptions!$D:$AC, MATCH("Starship at-cost rate per launch ($mm)", Assumptions!$A$1:$A$327, 0), COLUMN()-COLUMN($D14)+1)} -> 8.456
A15: Sat operational life L (years) | D15: =INDEX(Assumptions!$B:$B, MATCH("Sat operational life L (years)", Assumptions!$A$1:$A$327, 0)) -> 5 | E15: =INDEX(Assumptions!$B:$B, MATCH("Sat operational life L (years)", Assumptions!$A$1:$A$327, 0)) -> 5 | F15: =INDEX(Assumptions!$B:$B, MATCH("Sat operational life L (years)", Assumptions!$A$1:$A$327, 0)) -> 5 | G15: =INDEX(Assumptions!$B:$B, MATCH("Sat operational life L (years)", Assumptions!$A$1:$A$327, 0)) -> 5 | H15: =INDEX(Assumptions!$B:$B, MATCH("Sat operational life L (years)", Assumptions!$A$1:$A$327, 0)) -> 5 | I15: =INDEX(Assumptions!$B:$B, MATCH("Sat operational life L (years)", Assumptions!$A$1:$A$327, 0)) -> 5 | J15: =INDEX(Assumptions!$B:$B, MATCH("Sat operational life L (years)", Assumptions!$A$1:$A$327, 0)) -> 5 | K15: =INDEX(Assumptions!$B:$B, MATCH("Sat operational life L (years)", Assumptions!$A$1:$A$327, 0)) -> 5 | ... S15: =INDEX(Assumptions!$B:$B, MATCH("Sat operational life L (years)", Assumptions!$A$1:$A$327, 0)) -> 5
A16: Group WACC | D16: =INDEX(Assumptions!$B:$B, MATCH("Group WACC", Assumptions!$A$1:$A$327, 0)) -> 0.1 | E16: =INDEX(Assumptions!$B:$B, MATCH("Group WACC", Assumptions!$A$1:$A$327, 0)) -> 0.1 | F16: =INDEX(Assumptions!$B:$B, MATCH("Group WACC", Assumptions!$A$1:$A$327, 0)) -> 0.1 | G16: =INDEX(Assumptions!$B:$B, MATCH("Group WACC", Assumptions!$A$1:$A$327, 0)) -> 0.1 | H16: =INDEX(Assumptions!$B:$B, MATCH("Group WACC", Assumptions!$A$1:$A$327, 0)) -> 0.1 | I16: =INDEX(Assumptions!$B:$B, MATCH("Group WACC", Assumptions!$A$1:$A$327, 0)) -> 0.1 | J16: =INDEX(Assumptions!$B:$B, MATCH("Group WACC", Assumptions!$A$1:$A$327, 0)) -> 0.1 | K16: =INDEX(Assumptions!$B:$B, MATCH("Group WACC", Assumptions!$A$1:$A$327, 0)) -> 0.1 | ... S16: =INDEX(Assumptions!$B:$B, MATCH("Group WACC", Assumptions!$A$1:$A$327, 0)) -> 0.1
A18: Starlink R&D as % of revenue (frac) | D18: =INDEX(Assumptions!$B:$B, MATCH("Starlink R&D: start % of (Starlink+Starshield) rev", Assumptions!$A$1:$A$327, 0)) -> 0.053 | E18: =INDEX(Assumptions!$B:$B, MATCH("Starlink R&D: start % of (Starlink+Starshield) rev", Assumptions!$A$1:$A$327, 0)) -> 0.053 | F18: =INDEX(Assumptions!$B:$B, MATCH("Starlink R&D: start % of (Starlink+Starshield) rev", Assumptions!$A$1:$A$327, 0)) -> 0.053 | G18: =INDEX(Assumptions!$B:$B, MATCH("Starlink R&D: start % of (Starlink+Starshield) rev", Assumptions!$A$1:$A$327, 0)) -> 0.053 | H18: =INDEX(Assumptions!$B:$B, MATCH("Starlink R&D: start % of (Starlink+Starshield) rev", Assumptions!$A$1:$A$327, 0)) -> 0.053 | I18: =INDEX(Assumptions!$B:$B, MATCH("Starlink R&D: start % of (Starlink+Starshield) rev", Assumptions!$A$1:$A$327, 0)) -> 0.053 | J18: =INDEX(Assumptions!$B:$B, MATCH("Starlink R&D: start % of (Starlink+Starshield) rev", Assumptions!$A$1:$A$327, 0)) -> 0.053 | K18: =INDEX(Assumptions!$B:$B, MATCH("Starlink R&D: start % of (Starlink+Starshield) rev", Assumptions!$A$1:$A$327, 0)) -> 0.053 | ... S18: =INDEX(Assumptions!$B:$B, MATCH("Starlink R&D: start % of (Starlink+Starshield) rev", Assumptions!$A$1:$A$327, 0)) -> 0.053
A19: Starlink module allocated cash ($mm/yr): live from Cash Allocation Engine | D19: =INDEX('Cash Allocation Engine'!D:D,MATCH("Allocated cash to Starlink ($mm)",'Cash Allocation Engine'!$A$1:$A$91,0)) -> 0 | E19: =INDEX('Cash Allocation Engine'!E:E,MATCH("Allocated cash to Starlink ($mm)",'Cash Allocation Engine'!$A$1:$A$91,0)) -> 25727.691 | F19: =INDEX('Cash Allocation Engine'!F:F,MATCH("Allocated cash to Starlink ($mm)",'Cash Allocation Engine'!$A$1:$A$91,0)) -> 48421.835 | G19: =INDEX('Cash Allocation Engine'!G:G,MATCH("Allocated cash to Starlink ($mm)",'Cash Allocation Engine'!$A$1:$A$91,0)) -> 35963.545 | H19: =INDEX('Cash Allocation Engine'!H:H,MATCH("Allocated cash to Starlink ($mm)",'Cash Allocation Engine'!$A$1:$A$91,0)) -> 33987.007 | I19: =INDEX('Cash Allocation Engine'!I:I,MATCH("Allocated cash to Starlink ($mm)",'Cash Allocation Engine'!$A$1:$A$91,0)) -> 47929.441 | J19: =INDEX('Cash Allocation Engine'!J:J,MATCH("Allocated cash to Starlink ($mm)",'Cash Allocation Engine'!$A$1:$A$91,0)) -> 71941.235 | K19: =INDEX('Cash Allocation Engine'!K:K,MATCH("Allocated cash to Starlink ($mm)",'Cash Allocation Engine'!$A$1:$A$91,0)) -> 48539.514 | L19: =INDEX('Cash Allocation Engine'!L:L,MATCH("Allocated cash to Starlink ($mm)",'Cash Allocation Engine'!$A$1:$A$91,0)) -> 56781.092 | M19: =INDEX('Cash Allocation Engine'!M:M,MATCH("Allocated cash to Starlink ($mm)",'Cash Allocation Engine'!$A$1:$A$91,0)) -> 79229.122 | N19: =INDEX('Cash Allocation Engine'!N:N,MATCH("Allocated cash to Starlink ($mm)",'Cash Allocation Engine'!$A$1:$A$91,0)) -> 91052.019 | O19: =INDEX('Cash Allocation Engine'!O:O,MATCH("Allocated cash to Starlink ($mm)",'Cash Allocation Engine'!$A$1:$A$91,0)) -> 123606.93 | P19: =INDEX('Cash Allocation Engine'!P:P,MATCH("Allocated cash to Starlink ($mm)",'Cash Allocation Engine'!$A$1:$A$91,0)) -> 106796.38 | Q19: =INDEX('Cash Allocation Engine'!Q:Q,MATCH("Allocated cash to Starlink ($mm)",'Cash Allocation Engine'!$A$1:$A$91,0)) -> 57814.378 | R19: =INDEX('Cash Allocation Engine'!R:R,MATCH("Allocated cash to Starlink ($mm)",'Cash Allocation Engine'!$A$1:$A$91,0)) -> 39109.523 | S19: =INDEX('Cash Allocation Engine'!S:S,MATCH("Allocated cash to Starlink ($mm)",'Cash Allocation Engine'!$A$1:$A$91,0)) -> 41495.9
A20: Starlink deployment 2025 anchor (sats) | D20: =INDEX(Assumptions!$B:$B, MATCH("Starlink deployment 2025 anchor (sats)", Assumptions!$A$1:$A$327, 0)) -> 3840
A21: Sat utilization (frac) | D21: =INDEX(Assumptions!$B:$B, MATCH("Sat utilization (frac)", Assumptions!$A$1:$A$327, 0)) -> 0.7 | E21: =INDEX(Assumptions!$B:$B, MATCH("Sat utilization (frac)", Assumptions!$A$1:$A$327, 0)) -> 0.7 | F21: =INDEX(Assumptions!$B:$B, MATCH("Sat utilization (frac)", Assumptions!$A$1:$A$327, 0)) -> 0.7 | G21: =INDEX(Assumptions!$B:$B, MATCH("Sat utilization (frac)", Assumptions!$A$1:$A$327, 0)) -> 0.7 | H21: =INDEX(Assumptions!$B:$B, MATCH("Sat utilization (frac)", Assumptions!$A$1:$A$327, 0)) -> 0.7 | I21: =INDEX(Assumptions!$B:$B, MATCH("Sat utilization (frac)", Assumptions!$A$1:$A$327, 0)) -> 0.7 | J21: =INDEX(Assumptions!$B:$B, MATCH("Sat utilization (frac)", Assumptions!$A$1:$A$327, 0)) -> 0.7 | K21: =INDEX(Assumptions!$B:$B, MATCH("Sat utilization (frac)", Assumptions!$A$1:$A$327, 0)) -> 0.7 | ... S21: =INDEX(Assumptions!$B:$B, MATCH("Sat utilization (frac)", Assumptions!$A$1:$A$327, 0)) -> 0.7
A22: Starship operational year | D22: =INDEX(Assumptions!$B:$B, MATCH("Starship operational year", Assumptions!$A$1:$A$327, 0)) -> 2026
A23: F9 launches V2-Starlink final year | D23: =INDEX(Assumptions!$B:$B, MATCH("F9 launches V2-Starlink final year", Assumptions!$A$1:$A$327, 0)) -> 2026
A24: F9 payload per launch (kg) | D24: {=INDEX('Vehicle Build'!$D:$AC, MATCH("F9 payload per launch (kg)", 'Vehicle Build'!$A$1:$A$119, 0), COLUMN()-COLUMN($D24)+1)} -> 22800 | E24: {=INDEX('Vehicle Build'!$D:$AC, MATCH("F9 payload per launch (kg)", 'Vehicle Build'!$A$1:$A$119, 0), COLUMN()-COLUMN($D24)+1)} -> 22800 | F24: {=INDEX('Vehicle Build'!$D:$AC, MATCH("F9 payload per launch (kg)", 'Vehicle Build'!$A$1:$A$119, 0), COLUMN()-COLUMN($D24)+1)} -> 22800 | G24: {=INDEX('Vehicle Build'!$D:$AC, MATCH("F9 payload per launch (kg)", 'Vehicle Build'!$A$1:$A$119, 0), COLUMN()-COLUMN($D24)+1)} -> 22800 | H24: {=INDEX('Vehicle Build'!$D:$AC, MATCH("F9 payload per launch (kg)", 'Vehicle Build'!$A$1:$A$119, 0), COLUMN()-COLUMN($D24)+1)} -> 22800 | I24: {=INDEX('Vehicle Build'!$D:$AC, MATCH("F9 payload per launch (kg)", 'Vehicle Build'!$A$1:$A$119, 0), COLUMN()-COLUMN($D24)+1)} -> 22800 | J24: {=INDEX('Vehicle Build'!$D:$AC, MATCH("F9 payload per launch (kg)", 'Vehicle Build'!$A$1:$A$119, 0), COLUMN()-COLUMN($D24)+1)} -> 22800 | K24: {=INDEX('Vehicle Build'!$D:$AC, MATCH("F9 payload per launch (kg)", 'Vehicle Build'!$A$1:$A$119, 0), COLUMN()-COLUMN($D24)+1)} -> 22800 | ... S24: {=INDEX('Vehicle Build'!$D:$AC, MATCH("F9 payload per launch (kg)", 'Vehicle Build'!$A$1:$A$119, 0), COLUMN()-COLUMN($D24)+1)} -> 22800
A25: Starship payload per launch (kg) | D25: {=INDEX('Vehicle Build'!$D:$AC, MATCH("Starship payload per launch (kg)", 'Vehicle Build'!$A$1:$A$119, 0), COLUMN()-COLUMN($D25)+1)} -> 100000 | E25: {=INDEX('Vehicle Build'!$D:$AC, MATCH("Starship payload per launch (kg)", 'Vehicle Build'!$A$1:$A$119, 0), COLUMN()-COLUMN($D25)+1)} -> 114869.84 | F25: {=INDEX('Vehicle Build'!$D:$AC, MATCH("Starship payload per launch (kg)", 'Vehicle Build'!$A$1:$A$119, 0), COLUMN()-COLUMN($D25)+1)} -> 131950.79 | G25: {=INDEX('Vehicle Build'!$D:$AC, MATCH("Starship payload per launch (kg)", 'Vehicle Build'!$A$1:$A$119, 0), COLUMN()-COLUMN($D25)+1)} -> 151571.66 | H25: {=INDEX('Vehicle Build'!$D:$AC, MATCH("Starship payload per launch (kg)", 'Vehicle Build'!$A$1:$A$119, 0), COLUMN()-COLUMN($D25)+1)} -> 174110.11 | I25: {=INDEX('Vehicle Build'!$D:$AC, MATCH("Starship payload per launch (kg)", 'Vehicle Build'!$A$1:$A$119, 0), COLUMN()-COLUMN($D25)+1)} -> 200000 | J25: {=INDEX('Vehicle Build'!$D:$AC, MATCH("Starship payload per launch (kg)", 'Vehicle Build'!$A$1:$A$119, 0), COLUMN()-COLUMN($D25)+1)} -> 200000 | K25: {=INDEX('Vehicle Build'!$D:$AC, MATCH("Starship payload per launch (kg)", 'Vehicle Build'!$A$1:$A$119, 0), COLUMN()-COLUMN($D25)+1)} -> 200000 | ... S25: {=INDEX('Vehicle Build'!$D:$AC, MATCH("Starship payload per launch (kg)", 'Vehicle Build'!$A$1:$A$119, 0), COLUMN()-COLUMN($D25)+1)} -> 200000
A27: ▸ CONSTELLATION BUILD (real cohorts → total bandwidth)
A28: V2 launch window active (1/0) | D28: =IF(D$4<=$D$23, 1, 0) -> 1 | E28: =IF(E$4<=$D$23, 1, 0) -> 1 | F28: =IF(F$4<=$D$23, 1, 0) -> 0 | G28: =IF(G$4<=$D$23, 1, 0) -> 0 | H28: =IF(H$4<=$D$23, 1, 0) -> 0 | I28: =IF(I$4<=$D$23, 1, 0) -> 0 | J28: =IF(J$4<=$D$23, 1, 0) -> 0 | K28: =IF(K$4<=$D$23, 1, 0) -> 0 | ... S28: =IF(S$4<=$D$23, 1, 0) -> 0
A29: V3 deployment active (1/0) | D29: =IF(D$4>=$D$22+1, 1, 0) -> 0 | E29: =IF(E$4>=$D$22+1, 1, 0) -> 0 | F29: =IF(F$4>=$D$22+1, 1, 0) -> 1 | G29: =IF(G$4>=$D$22+1, 1, 0) -> 1 | H29: =IF(H$4>=$D$22+1, 1, 0) -> 1 | I29: =IF(I$4>=$D$22+1, 1, 0) -> 1 | J29: =IF(J$4>=$D$22+1, 1, 0) -> 1 | K29: =IF(K$4>=$D$22+1, 1, 0) -> 1 | ... S29: =IF(S$4>=$D$22+1, 1, 0) -> 1
A31: Total new Starlink deployment (sats/yr) | D31: =SUM(D32:D35) -> 3840 | E31: =SUM(E32:E35) -> 3120 | F31: =SUM(F32:F35) -> 3918.7353 | G31: =SUM(G32:G35) -> 9497.38 | H31: =SUM(H32:H35) -> 22947.351 | I31: =SUM(I32:I35) -> 35068.944 | J31: =SUM(J32:J35) -> 55854.425 | K31: =SUM(K32:K35) -> 39606.221 | ... S31: =SUM(S32:S35) -> 39441.628
A32: New V2 BB deployment (sats/yr) | D32: =IF(D$4=2025, $D$20, IF(D$28=1, D203, 0)) -> 3840 | E32: =IF(E$4=2025, $D$20, IF(E$28=1, E203, 0)) -> 3120 | F32: =IF(F$4=2025, $D$20, IF(F$28=1, F203, 0)) -> 0 | G32: =IF(G$4=2025, $D$20, IF(G$28=1, G203, 0)) -> 0 | H32: =IF(H$4=2025, $D$20, IF(H$28=1, H203, 0)) -> 0 | I32: =IF(I$4=2025, $D$20, IF(I$28=1, I203, 0)) -> 0 | J32: =IF(J$4=2025, $D$20, IF(J$28=1, J203, 0)) -> 0 | K32: =IF(K$4=2025, $D$20, IF(K$28=1, K203, 0)) -> 0 | ... S32: =IF(S$4=2025, $D$20, IF(S$28=1, S203, 0)) -> 0
A33: New V2 DTC deployment (sats/yr) | D33: =0 -> 0 | E33: =0 -> 0 | F33: =0 -> 0 | G33: =0 -> 0 | H33: =0 -> 0 | I33: =0 -> 0 | J33: =0 -> 0 | K33: =0 -> 0 | ... S33: =0 -> 0
A34: New V3 BB deployment (sats/yr) | D34: =IF(D$29=1, D203, 0) -> 0 | E34: =IF(E$29=1, E203, 0) -> 0 | F34: =IF(F$29=1, F203, 0) -> 3916.8544 | G34: =IF(G$29=1, G203, 0) -> 9417.3322 | H34: =IF(H$29=1, H203, 0) -> 20322.768 | I34: =IF(I$29=1, I203, 0) -> 12363.994 | J34: =IF(J$29=1, J203, 0) -> 27651.611 | K34: =IF(K$29=1, K203, 0) -> 12542.183 | ... S34: =IF(S$29=1, S203, 0) -> 20227.328
A35: New V3 DTC deployment (sats/yr) | D35: =IF(D$29=1, D204, 0) -> 0 | E35: =IF(E$29=1, E204, 0) -> 0 | F35: =IF(F$29=1, F204, 0) -> 1.8809254 | G35: =IF(G$29=1, G204, 0) -> 80.047746 | H35: =IF(H$29=1, H204, 0) -> 2624.5828 | I35: =IF(I$29=1, I204, 0) -> 22704.949 | J35: =IF(J$29=1, J204, 0) -> 28202.814 | K35: =IF(K$29=1, K204, 0) -> 27064.038 | ... S35: =IF(S$29=1, S204, 0) -> 19214.3
A36: New Starshield deployment (sats/yr) | D36: =$D$31*0.12 -> 460.8 | E36: =$D$31*0.12 -> 460.8 | F36: =$D$31*0.12 -> 460.8 | G36: =$D$31*0.12 -> 460.8 | H36: =$D$31*0.12 -> 460.8 | I36: =$D$31*0.12 -> 460.8 | J36: =$D$31*0.12 -> 460.8 | K36: =$D$31*0.12 -> 460.8 | ... S36: =$D$31*0.12 -> 460.8
A37: Blended new-sat CapEx slug ($mm/sat): MEMO ONLY (feeds CAE R88 cap; no longer drives deployment) | D37: =IF(D$29=1, INDEX(Assumptions!$B:$B,MATCH("V3 BB share of new deployment (frac)",Assumptions!$A$1:$A$327,0))*D125 + INDEX(Assumptions!$B:$B,MATCH("V3 DTC share of new deployment (frac)",Assumptions!$A$1:$A$327,0))*D131, INDEX(Assumptions!$B:$B,MATCH("V2 BB share of new deployment (frac)",Assumptions!$A$1:$A$327,0))*D113 + INDEX(Assumptions!$B:$B,MATCH("V2 DTC share of new deployment (frac)",Assumptions!$A$1:$A$327,0))*D119 + 0.12*D137) -> 1.1597909 | E37: =IF(E$29=1, INDEX(Assumptions!$B:$B,MATCH("V3 BB share of new deployment (frac)",Assumptions!$A$1:$A$327,0))*E125 + INDEX(Assumptions!$B:$B,MATCH("V3 DTC share of new deployment (frac)",Assumptions!$A$1:$A$327,0))*E131, INDEX(Assumptions!$B:$B,MATCH("V2 BB share of new deployment (frac)",Assumptions!$A$1:$A$327,0))*E113 + INDEX(Assumptions!$B:$B,MATCH("V2 DTC share of new deployment (frac)",Assumptions!$A$1:$A$327,0))*E119 + 0.12*E137) -> 1.1722996 | F37: =IF(F$29=1, INDEX(Assumptions!$B:$B,MATCH("V3 BB share of new deployment (frac)",Assumptions!$A$1:$A$327,0))*F125 + INDEX(Assumptions!$B:$B,MATCH("V3 DTC share of new deployment (frac)",Assumptions!$A$1:$A$327,0))*F131, INDEX(Assumptions!$B:$B,MATCH("V2 BB share of new deployment (frac)",Assumptions!$A$1:$A$327,0))*F113 + INDEX(Assumptions!$B:$B,MATCH("V2 DTC share of new deployment (frac)",Assumptions!$A$1:$A$327,0))*F119 + 0.12*F137) -> 1.6698542 | G37: =IF(G$29=1, INDEX(Assumptions!$B:$B,MATCH("V3 BB share of new deployment (frac)",Assumptions!$A$1:$A$327,0))*G125 + INDEX(Assumptions!$B:$B,MATCH("V3 DTC share of new deployment (frac)",Assumptions!$A$1:$A$327,0))*G131, INDEX(Assumptions!$B:$B,MATCH("V2 BB share of new deployment (frac)",Assumptions!$A$1:$A$327,0))*G113 + INDEX(Assumptions!$B:$B,MATCH("V2 DTC share of new deployment (frac)",Assumptions!$A$1:$A$327,0))*G119 + 0.12*G137) -> 1.5893285 | H37: =IF(H$29=1, INDEX(Assumptions!$B:$B,MATCH("V3 BB share of new deployment (frac)",Assumptions!$A$1:$A$327,0))*H125 + INDEX(Assumptions!$B:$B,MATCH("V3 DTC share of new deployment (frac)",Assumptions!$A$1:$A$327,0))*H131, INDEX(Assumptions!$B:$B,MATCH("V2 BB share of new deployment (frac)",Assumptions!$A$1:$A$327,0))*H113 + INDEX(Assumptions!$B:$B,MATCH("V2 DTC share of new deployment (frac)",Assumptions!$A$1:$A$327,0))*H119 + 0.12*H137) -> 1.4810863 | I37: =IF(I$29=1, INDEX(Assumptions!$B:$B,MATCH("V3 BB share of new deployment (frac)",Assumptions!$A$1:$A$327,0))*I125 + INDEX(Assumptions!$B:$B,MATCH("V3 DTC share of new deployment (frac)",Assumptions!$A$1:$A$327,0))*I131, INDEX(Assumptions!$B:$B,MATCH("V2 BB share of new deployment (frac)",Assumptions!$A$1:$A$327,0))*I113 + INDEX(Assumptions!$B:$B,MATCH("V2 DTC share of new deployment (frac)",Assumptions!$A$1:$A$327,0))*I119 + 0.12*I137) -> 1.3667204 | J37: =IF(J$29=1, INDEX(Assumptions!$B:$B,MATCH("V3 BB share of new deployment (frac)",Assumptions!$A$1:$A$327,0))*J125 + INDEX(Assumptions!$B:$B,MATCH("V3 DTC share of new deployment (frac)",Assumptions!$A$1:$A$327,0))*J131, INDEX(Assumptions!$B:$B,MATCH("V2 BB share of new deployment (frac)",Assumptions!$A$1:$A$327,0))*J113 + INDEX(Assumptions!$B:$B,MATCH("V2 DTC share of new deployment (frac)",Assumptions!$A$1:$A$327,0))*J119 + 0.12*J137) -> 1.2880132 | K37: =IF(K$29=1, INDEX(Assumptions!$B:$B,MATCH("V3 BB share of new deployment (frac)",Assumptions!$A$1:$A$327,0))*K125 + INDEX(Assumptions!$B:$B,MATCH("V3 DTC share of new deployment (frac)",Assumptions!$A$1:$A$327,0))*K131, INDEX(Assumptions!$B:$B,MATCH("V2 BB share of new deployment (frac)",Assumptions!$A$1:$A$327,0))*K113 + INDEX(Assumptions!$B:$B,MATCH("V2 DTC share of new deployment (frac)",Assumptions!$A$1:$A$327,0))*K119 + 0.12*K137) -> 1.2255528 | ... S37: =IF(S$29=1, INDEX(Assumptions!$B:$B,MATCH("V3 BB share of new deployment (frac)",Assumptions!$A$1:$A$327,0))*S125 + INDEX(Assumptions!$B:$B,MATCH("V3 DTC share of new deployment (frac)",Assumptions!$A$1:$A$327,0))*S131, INDEX(Assumptions!$B:$B,MATCH("V2 BB share of new deployment (frac)",Assumptions!$A$1:$A$327,0))*S113 + INDEX(Assumptions!$B:$B,MATCH("V2 DTC share of new deployment (frac)",Assumptions!$A$1:$A$327,0))*S119 + 0.12*S137) -> 0.99762931
A38: Demand-saturation deployment headroom (sats) | D38: =MAX(0,(INDEX('Demand Curves'!$B:$B,MATCH("BB Q breakpoint #56 (Gbps)",'Demand Curves'!$A$1:$A$167,0))-D176)/INDEX(Assumptions!$B:$B,MATCH("V3 BB Gbps per sat",Assumptions!$A$1:$A$327,0))) -> 249585.86 | E38: =MAX(0,(INDEX('Demand Curves'!$B:$B,MATCH("BB Q breakpoint #56 (Gbps)",'Demand Curves'!$A$1:$A$167,0))-D176)/INDEX(Assumptions!$B:$B,MATCH("V3 BB Gbps per sat",Assumptions!$A$1:$A$327,0))) -> 249585.86 | F38: =MAX(0,(INDEX('Demand Curves'!$B:$B,MATCH("BB Q breakpoint #56 (Gbps)",'Demand Curves'!$A$1:$A$167,0))-E176)/INDEX(Assumptions!$B:$B,MATCH("V3 BB Gbps per sat",Assumptions!$A$1:$A$327,0))) -> 249286.34 | G38: =MAX(0,(INDEX('Demand Curves'!$B:$B,MATCH("BB Q breakpoint #56 (Gbps)",'Demand Curves'!$A$1:$A$167,0))-F176)/INDEX(Assumptions!$B:$B,MATCH("V3 BB Gbps per sat",Assumptions!$A$1:$A$327,0))) -> 245369.48 | H38: =MAX(0,(INDEX('Demand Curves'!$B:$B,MATCH("BB Q breakpoint #56 (Gbps)",'Demand Curves'!$A$1:$A$167,0))-G176)/INDEX(Assumptions!$B:$B,MATCH("V3 BB Gbps per sat",Assumptions!$A$1:$A$327,0))) -> 236090.2 | I38: =MAX(0,(INDEX('Demand Curves'!$B:$B,MATCH("BB Q breakpoint #56 (Gbps)",'Demand Curves'!$A$1:$A$167,0))-H176)/INDEX(Assumptions!$B:$B,MATCH("V3 BB Gbps per sat",Assumptions!$A$1:$A$327,0))) -> 215905.48 | J38: =MAX(0,(INDEX('Demand Curves'!$B:$B,MATCH("BB Q breakpoint #56 (Gbps)",'Demand Curves'!$A$1:$A$167,0))-I176)/INDEX(Assumptions!$B:$B,MATCH("V3 BB Gbps per sat",Assumptions!$A$1:$A$327,0))) -> 203679.53 | K38: =MAX(0,(INDEX('Demand Curves'!$B:$B,MATCH("BB Q breakpoint #56 (Gbps)",'Demand Curves'!$A$1:$A$167,0))-J176)/INDEX(Assumptions!$B:$B,MATCH("V3 BB Gbps per sat",Assumptions!$A$1:$A$327,0))) -> 176327.44 | L38: =MAX(0,(INDEX('Demand Curves'!$B:$B,MATCH("BB Q breakpoint #56 (Gbps)",'Demand Curves'!$A$1:$A$167,0))-K176)/INDEX(Assumptions!$B:$B,MATCH("V3 BB Gbps per sat",Assumptions!$A$1:$A$327,0))) -> 167702.11 | ... S38: =MAX(0,(INDEX('Demand Curves'!$B:$B,MATCH("BB Q breakpoint #56 (Gbps)",'Demand Curves'!$A$1:$A$167,0))-R176)/INDEX(Assumptions!$B:$B,MATCH("V3 BB Gbps per sat",Assumptions!$A$1:$A$327,0))) -> 41594.508
A39: BB FLEET (active sats by cohort)
A40: Legacy V1 active sats | D40: =INDEX(Assumptions!$B:$B,MATCH("Legacy V1 active sats end-2025",Assumptions!$A$1:$A$327,0)) -> 866 | E40: =MAX(0, D40 - IF(AND(E$4>=INDEX(Assumptions!$B:$B,MATCH("Legacy V1 base deorbit start year",Assumptions!$A$1:$A$327,0)),E$4<=INDEX(Assumptions!$B:$B,MATCH("Legacy V1 base deorbit end year",Assumptions!$A$1:$A$327,0))),$D$40/(INDEX(Assumptions!$B:$B,MATCH("Legacy V1 base deorbit end year",Assumptions!$A$1:$A$327,0))-INDEX(Assumptions!$B:$B,MATCH("Legacy V1 base deorbit start year",Assumptions!$A$1:$A$327,0))+1),0)) -> 0 | F40: =MAX(0, E40 - IF(AND(F$4>=INDEX(Assumptions!$B:$B,MATCH("Legacy V1 base deorbit start year",Assumptions!$A$1:$A$327,0)),F$4<=INDEX(Assumptions!$B:$B,MATCH("Legacy V1 base deorbit end year",Assumptions!$A$1:$A$327,0))),$D$40/(INDEX(Assumptions!$B:$B,MATCH("Legacy V1 base deorbit end year",Assumptions!$A$1:$A$327,0))-INDEX(Assumptions!$B:$B,MATCH("Legacy V1 base deorbit start year",Assumptions!$A$1:$A$327,0))+1),0)) -> 0 | G40: =MAX(0, F40 - IF(AND(G$4>=INDEX(Assumptions!$B:$B,MATCH("Legacy V1 base deorbit start year",Assumptions!$A$1:$A$327,0)),G$4<=INDEX(Assumptions!$B:$B,MATCH("Legacy V1 base deorbit end year",Assumptions!$A$1:$A$327,0))),$D$40/(INDEX(Assumptions!$B:$B,MATCH("Legacy V1 base deorbit end year",Assumptions!$A$1:$A$327,0))-INDEX(Assumptions!$B:$B,MATCH("Legacy V1 base deorbit start year",Assumptions!$A$1:$A$327,0))+1),0)) -> 0 | H40: =MAX(0, G40 - IF(AND(H$4>=INDEX(Assumptions!$B:$B,MATCH("Legacy V1 base deorbit start year",Assumptions!$A$1:$A$327,0)),H$4<=INDEX(Assumptions!$B:$B,MATCH("Legacy V1 base deorbit end year",Assumptions!$A$1:$A$327,0))),$D$40/(INDEX(Assumptions!$B:$B,MATCH("Legacy V1 base deorbit end year",Assumptions!$A$1:$A$327,0))-INDEX(Assumptions!$B:$B,MATCH("Legacy V1 base deorbit start year",Assumptions!$A$1:$A$327,0))+1),0)) -> 0 | I40: =MAX(0, H40 - IF(AND(I$4>=INDEX(Assumptions!$B:$B,MATCH("Legacy V1 base deorbit start year",Assumptions!$A$1:$A$327,0)),I$4<=INDEX(Assumptions!$B:$B,MATCH("Legacy V1 base deorbit end year",Assumptions!$A$1:$A$327,0))),$D$40/(INDEX(Assumptions!$B:$B,MATCH("Legacy V1 base deorbit end year",Assumptions!$A$1:$A$327,0))-INDEX(Assumptions!$B:$B,MATCH("Legacy V1 base deorbit start year",Assumptions!$A$1:$A$327,0))+1),0)) -> 0 | J40: =MAX(0, I40 - IF(AND(J$4>=INDEX(Assumptions!$B:$B,MATCH("Legacy V1 base deorbit start year",Assumptions!$A$1:$A$327,0)),J$4<=INDEX(Assumptions!$B:$B,MATCH("Legacy V1 base deorbit end year",Assumptions!$A$1:$A$327,0))),$D$40/(INDEX(Assumptions!$B:$B,MATCH("Legacy V1 base deorbit end year",Assumptions!$A$1:$A$327,0))-INDEX(Assumptions!$B:$B,MATCH("Legacy V1 base deorbit start year",Assumptions!$A$1:$A$327,0))+1),0)) -> 0 | K40: =MAX(0, J40 - IF(AND(K$4>=INDEX(Assumptions!$B:$B,MATCH("Legacy V1 base deorbit start year",Assumptions!$A$1:$A$327,0)),K$4<=INDEX(Assumptions!$B:$B,MATCH("Legacy V1 base deorbit end year",Assumptions!$A$1:$A$327,0))),$D$40/(INDEX(Assumptions!$B:$B,MATCH("Legacy V1 base deorbit end year",Assumptions!$A$1:$A$327,0))-INDEX(Assumptions!$B:$B,MATCH("Legacy V1 base deorbit start year",Assumptions!$A$1:$A$327,0))+1),0)) -> 0 | L40: =MAX(0, K40 - IF(AND(L$4>=INDEX(Assumptions!$B:$B,MATCH("Legacy V1 base deorbit start year",Assumptions!$A$1:$A$327,0)),L$4<=INDEX(Assumptions!$B:$B,MATCH("Legacy V1 base deorbit end year",Assumptions!$A$1:$A$327,0))),$D$40/(INDEX(Assumptions!$B:$B,MATCH("Legacy V1 base deorbit end year",Assumptions!$A$1:$A$327,0))-INDEX(Assumptions!$B:$B,MATCH("Legacy V1 base deorbit start year",Assumptions!$A$1:$A$327,0))+1),0)) -> 0 | ... S40: =MAX(0, R40 - IF(AND(S$4>=INDEX(Assumptions!$B:$B,MATCH("Legacy V1 base deorbit start year",Assumptions!$A$1:$A$327,0)),S$4<=INDEX(Assumptions!$B:$B,MATCH("Legacy V1 base deorbit end year",Assumptions!$A$1:$A$327,0))),$D$40/(INDEX(Assumptions!$B:$B,MATCH("Legacy V1 base deorbit end year",Assumptions!$A$1:$A$327,0))-INDEX(Assumptions!$B:$B,MATCH("Legacy V1 base deorbit start year",Assumptions!$A$1:$A$327,0))+1),0)) -> 0
A41: Legacy V1.5 active sats | D41: =INDEX(Assumptions!$B:$B,MATCH("Legacy V1.5 active sats end-2025",Assumptions!$A$1:$A$327,0)) -> 2692 | E41: =MAX(0, D41 - IF(AND(E$4>=INDEX(Assumptions!$B:$B,MATCH("Legacy V1.5 base deorbit start year",Assumptions!$A$1:$A$327,0)),E$4<=INDEX(Assumptions!$B:$B,MATCH("Legacy V1.5 base deorbit end year",Assumptions!$A$1:$A$327,0))),$D$41/(INDEX(Assumptions!$B:$B,MATCH("Legacy V1.5 base deorbit end year",Assumptions!$A$1:$A$327,0))-INDEX(Assumptions!$B:$B,MATCH("Legacy V1.5 base deorbit start year",Assumptions!$A$1:$A$327,0))+1),0)) -> 1794.6667 | F41: =MAX(0, E41 - IF(AND(F$4>=INDEX(Assumptions!$B:$B,MATCH("Legacy V1.5 base deorbit start year",Assumptions!$A$1:$A$327,0)),F$4<=INDEX(Assumptions!$B:$B,MATCH("Legacy V1.5 base deorbit end year",Assumptions!$A$1:$A$327,0))),$D$41/(INDEX(Assumptions!$B:$B,MATCH("Legacy V1.5 base deorbit end year",Assumptions!$A$1:$A$327,0))-INDEX(Assumptions!$B:$B,MATCH("Legacy V1.5 base deorbit start year",Assumptions!$A$1:$A$327,0))+1),0)) -> 897.33333 | G41: =MAX(0, F41 - IF(AND(G$4>=INDEX(Assumptions!$B:$B,MATCH("Legacy V1.5 base deorbit start year",Assumptions!$A$1:$A$327,0)),G$4<=INDEX(Assumptions!$B:$B,MATCH("Legacy V1.5 base deorbit end year",Assumptions!$A$1:$A$327,0))),$D$41/(INDEX(Assumptions!$B:$B,MATCH("Legacy V1.5 base deorbit end year",Assumptions!$A$1:$A$327,0))-INDEX(Assumptions!$B:$B,MATCH("Legacy V1.5 base deorbit start year",Assumptions!$A$1:$A$327,0))+1),0)) -> 0 | H41: =MAX(0, G41 - IF(AND(H$4>=INDEX(Assumptions!$B:$B,MATCH("Legacy V1.5 base deorbit start year",Assumptions!$A$1:$A$327,0)),H$4<=INDEX(Assumptions!$B:$B,MATCH("Legacy V1.5 base deorbit end year",Assumptions!$A$1:$A$327,0))),$D$41/(INDEX(Assumptions!$B:$B,MATCH("Legacy V1.5 base deorbit end year",Assumptions!$A$1:$A$327,0))-INDEX(Assumptions!$B:$B,MATCH("Legacy V1.5 base deorbit start year",Assumptions!$A$1:$A$327,0))+1),0)) -> 0 | I41: =MAX(0, H41 - IF(AND(I$4>=INDEX(Assumptions!$B:$B,MATCH("Legacy V1.5 base deorbit start year",Assumptions!$A$1:$A$327,0)),I$4<=INDEX(Assumptions!$B:$B,MATCH("Legacy V1.5 base deorbit end year",Assumptions!$A$1:$A$327,0))),$D$41/(INDEX(Assumptions!$B:$B,MATCH("Legacy V1.5 base deorbit end year",Assumptions!$A$1:$A$327,0))-INDEX(Assumptions!$B:$B,MATCH("Legacy V1.5 base deorbit start year",Assumptions!$A$1:$A$327,0))+1),0)) -> 0 | J41: =MAX(0, I41 - IF(AND(J$4>=INDEX(Assumptions!$B:$B,MATCH("Legacy V1.5 base deorbit start year",Assumptions!$A$1:$A$327,0)),J$4<=INDEX(Assumptions!$B:$B,MATCH("Legacy V1.5 base deorbit end year",Assumptions!$A$1:$A$327,0))),$D$41/(INDEX(Assumptions!$B:$B,MATCH("Legacy V1.5 base deorbit end year",Assumptions!$A$1:$A$327,0))-INDEX(Assumptions!$B:$B,MATCH("Legacy V1.5 base deorbit start year",Assumptions!$A$1:$A$327,0))+1),0)) -> 0 | K41: =MAX(0, J41 - IF(AND(K$4>=INDEX(Assumptions!$B:$B,MATCH("Legacy V1.5 base deorbit start year",Assumptions!$A$1:$A$327,0)),K$4<=INDEX(Assumptions!$B:$B,MATCH("Legacy V1.5 base deorbit end year",Assumptions!$A$1:$A$327,0))),$D$41/(INDEX(Assumptions!$B:$B,MATCH("Legacy V1.5 base deorbit end year",Assumptions!$A$1:$A$327,0))-INDEX(Assumptions!$B:$B,MATCH("Legacy V1.5 base deorbit start year",Assumptions!$A$1:$A$327,0))+1),0)) -> 0 | L41: =MAX(0, K41 - IF(AND(L$4>=INDEX(Assumptions!$B:$B,MATCH("Legacy V1.5 base deorbit start year",Assumptions!$A$1:$A$327,0)),L$4<=INDEX(Assumptions!$B:$B,MATCH("Legacy V1.5 base deorbit end year",Assumptions!$A$1:$A$327,0))),$D$41/(INDEX(Assumptions!$B:$B,MATCH("Legacy V1.5 base deorbit end year",Assumptions!$A$1:$A$327,0))-INDEX(Assumptions!$B:$B,MATCH("Legacy V1.5 base deorbit start year",Assumptions!$A$1:$A$327,0))+1),0)) -> 0 | ... S41: =MAX(0, R41 - IF(AND(S$4>=INDEX(Assumptions!$B:$B,MATCH("Legacy V1.5 base deorbit start year",Assumptions!$A$1:$A$327,0)),S$4<=INDEX(Assumptions!$B:$B,MATCH("Legacy V1.5 base deorbit end year",Assumptions!$A$1:$A$327,0))),$D$41/(INDEX(Assumptions!$B:$B,MATCH("Legacy V1.5 base deorbit end year",Assumptions!$A$1:$A$327,0))-INDEX(Assumptions!$B:$B,MATCH("Legacy V1.5 base deorbit start year",Assumptions!$A$1:$A$327,0))+1),0)) -> 0
