Workbook

Sheet Assumptions
D1: 2025 | E1: 2026 | F1: 2027 | G1: 2028 | H1: 2029 | I1: 2030 | J1: 2031 | K1: 2032 | L1: 2033 | M1: 2034 | N1: 2035 | O1: 2036 | P1: 2037 | Q1: 2038 | R1: 2039 | S1: 2040 | T1: 2041 | U1: 2042 | V1: 2043 | W1: 2044 | X1: 2045 | Y1: 2046 | Z1: 2047 | AA1: 2048 | AB1: 2049 | AC1: 2050
A2: §1 GLOBAL | D2: 0 | E2: 1 | F2: 2 | G2: 3 | H2: 4 | I2: 5 | J2: 6 | K2: 7 | L2: 8 | M2: 9 | N2: 10 | O2: 11 | P2: 12 | Q2: 13 | R2: 14 | S2: 15 | T2: 16 | U2: 17 | V2: 18 | W2: 19 | X2: 20 | Y2: 21 | Z2: 22 | AA2: 23 | AB2: 24 | AC2: 25
A3: Tax rate (corporate, US federal + state blended) | B3: 0.21 | C3: Standard US corporate rate; Q4'25 confirms. | AG3: 0.18 | AH3: 0.27 | AI3: triangle | AJ3: MC range covers blue-state vs Trump-era tax reform variability
A4: TAM inflation rate (annual) | B4: 0.025 | C4: TAM growth; industry standard. V30.5 R56 + Q4'25 confirms. | AG4: 0.01 | AH4: 0.05 | AI4: triangle | AJ4: MC range per Q4'25 Valuation Inputs
A5: GNI per capita growth rate (annual) | B5: 0.03 | C5: Used in Starlink demand-curve scaling. | AG5: 0.01 | AH5: 0.06 | AI5: triangle
A6: §2 ALLOCATOR
A7: ▸ Cash pool boundary inputs
A8: Starting cash position EoY 2024 ($mm) | B8: 5000 | C8: Q4'25 anchored ($4.70B rounded). V30.5 had $20B — corrected. | AG8: 3000 | AH8: 7000 | AI8: triangle | AJ8: Q4'25 Valuation Inputs central was within this range
A9: IPO injection amount ($mm) | B9: 30000 | C9: Q4'25 Valuation Inputs R31 central $40B; using $30B as Vlad-locked Base Case. | AG9: 15000 | AH9: 60000 | AI9: lognormal | AJ9: Q4'25 spread; tail upside is meaningful for terminal valuation
A10: IPO injection year | B10: 2027 | C10: Vlad-locked. | AG10: 2026 | AH10: 2028 | AI10: discrete | AJ10: Q4'25 had 2027/2028 split; discrete sample
A11: ▸ Moon/Mars strategic carve-out (Vlad-confirmed MC-variable)
A12: Mars carve-out % of prior-year Group FCF | B12: 0.15 | C12: Spec 06+07 stub. Vlad lock 2026-05-19: central uncertainty on how much SpaceX dedicates to Mars vs terrestrial IRR lines. MC-WIDE. | AG12: 0.03 | AH12: 0.35 | AI12: triangle | AJ12: Wide range — Vlad: 'we don't know how much they'll dedicate'
A13: Mars carve-out floor ($mm/yr) | B13: 1000 | C13: Floor below which carve-out doesn't drop even if prior FCF is small. | AG13: 500 | AH13: 2500 | AI13: triangle | AJ13: MC-variable
A14: Mars carve-out uses prior-year FCF (0/1) | B14: 1 | C14: 1 = prior year (breaks circularity per Principle 22). Structural input. | AI14: fixed
A15: ▸ IRR engine + sigmoid blend parameters
A16: Sigmoid IRR-blend exponent k | B16: 2 | C16: Spec 09 §2.1. Default k=2 across all sigmoid queues. | AG16: 1 | AH16: 3 | AI16: triangle | AJ16: MC tunes allocator concentration vs diversification
A17: Forward IRR weight w (Blended = (1-w)·Spot + w·Forward) | B17: 0.7 | C17: Spec 09 §2.10 unified. V30.5 B82 = 0.7. Same value used at module + vehicle level. | AG17: 0.5 | AH17: 0.85 | AI17: triangle | AJ17: MC tunes forward-looking vs current-period weight
A18: Forward IRR look-ahead horizon (years) | B18: 2 | C18: Y+2 throughout. Spec 09 kept; Y+5 not introduced. | AI18: fixed | AJ18: Structural
A19: MFW-IRR — Starlink economic life N (years) | B19: 5 | C19: Per-vehicle marginal IRR window. Sat useful life. | AG19: 4 | AH19: 7 | AI19: triangle
A20: MFW-IRR — ODC economic life N (years) | B20: 5 | C20: Per-sat marginal IRR window. Compute hardware life. | AG20: 4 | AH20: 7 | AI20: triangle
A21: MFW-IRR — AI Stack economic life N (years) | B21: 5 | C21: Per-product marginal IRR window. | AG21: 3 | AH21: 7 | AI21: triangle
A22: MFW-IRR — Customer Launch economic life clamp MIN (years) | B22: 1 | C22: Lower bound on endogenous N (cadence × lifetime reuses). | AI22: fixed
A23: MFW-IRR — Customer Launch economic life clamp MAX (years) | B23: 10 | C23: Upper bound on endogenous N. | AI23: fixed
A24: ▸ Vehicle build claim (Spec 09 architecture)
A25: Vehicle build claim toggle (0=legacy mode, 1=forward-demand-sized non-module claim) | B25: 1 | C25: Spec 09 architecture. Locked = 1. | AI25: fixed | AJ25: Structural
A26: Vehicle build lead time (years) | B26: 2 | C26: Matches Forward IRR Y+2 horizon. | AG26: 1 | AH26: 3 | AI26: discrete
A27: Launches per Starship vehicle per year (cadence × variant blend, used for sizing) | B27: 24 | C27: Spec 09 stub. ~30 cadence × ~80% variant blend. | AG27: 18 | AH27: 36 | AI27: triangle
A28: Vehicle masked-demand large default (sats; effectively uncapped) | B28: 1000000 | C28: Spec 09 mechanic. Vehicle eligibility binds at pool sizing, not internal ask. | AI28: fixed | AJ28: Structural
A29: Forward aggregate kg demand growth cap (× current capacity) | B29: 2 | C29: Cap on year-over-year demand growth used to size vehicle build claim. | AG29: 1.5 | AH29: 3 | AI29: triangle
A30: §3 CAPACITY (Starship + F9)
A31: ▸ Starship vehicle physical + cost parameters
A32: Super Heavy manufacturing cost ($mm/unit, base year) | B32: 54 | C32: Mach33: booster 60% × $90M total mfg = $54M today. ±25% MC range. Updated Sprint 3 Patch E §6.13. | AG32: 42 | AH32: 70 | AI32: triangle
A33: Starship 2nd-stage manufacturing cost ($mm/unit, base) | B33: 36 | C33: Mach33: ship 40% × $90M total mfg = $36M today. ±25% MC range. Updated Sprint 3 Patch E §6.13. | AG33: 27 | AH33: 50 | AI33: triangle
A34: Payload — booster-only mode (kg-to-LEO) | B34: 150000 | C34: Expendable ship config. Higher because no landing margin. | AG34: 130000 | AH34: 200000 | AI34: triangle | AJ34: Q4'25 Valuation Inputs R19 central 187K — covers MC
A35: Payload — fully reusable mode (kg-to-LEO) | B35: 100000 | C35: Reusable both stages. | AG35: 80000 | AH35: 150000 | AI35: triangle
A36: Lifetime reuses per ship (cap) | B36: 30 | C36: Ship useful life cap. | AG36: 20 | AH36: 50 | AI36: triangle
A37: Manufacturing learning rate (per doubling of cum units) | B37: 0.1 | C37: 10% per doubling. Q4'25 Valuation Inputs R18 central 0.145. | AG37: 0.05 | AH37: 0.2 | AI37: triangle
A38: ▸ Starship cadence (Wright's Law on cum upmass)
A39: Base turnaround time per booster (years/flight) | B39: 1 | C39: 2025 starting point. | AG39: 0.8 | AH39: 1.5 | AI39: triangle
A40: WL learning rate — turnaround vs cum upmass doubling | B40: 0.145 | C40: Legacy model midpoint. Q4'25 confirms. | AG40: 0.05 | AH40: 0.25 | AI40: triangle | AJ40: Q4'25 Valuation Inputs R18 range
...

Sheet Allocator
AE2: =IFERROR(MATCH("Vehicle build claim ($mm)", $A:$A, 0), "NOT FOUND") -> 23
AE3: =IFERROR(MATCH("Vehicle build claim", $A:$A, 0), "NOT FOUND") -> NOT FOUND
D4: 2025 | E4: 2026 | F4: 2027 | G4: 2028 | H4: 2029 | I4: 2030 | J4: 2031 | K4: 2032 | L4: 2033 | M4: 2034 | N4: 2035 | O4: 2036 | P4: 2037 | Q4: 2038 | R4: 2039 | S4: 2040 | T4: 2041 | U4: 2042 | V4: 2043 | W4: 2044 | X4: 2045 | Y4: 2046 | Z4: 2047 | AA4: 2048 | AB4: 2049 | AC4: 2050 | AE4: =IFERROR(MATCH("Required vehicles ($mm)", $A:$A, 0), "NOT FOUND") -> NOT FOUND
D5: 0 | E5: 1 | F5: 2 | G5: 3 | H5: 4 | I5: 5 | J5: 6 | K5: 7 | L5: 8 | M5: 9 | N5: 10 | O5: 11 | P5: 12 | Q5: 13 | R5: 14 | S5: 15 | T5: 16 | U5: 17 | V5: 18 | W5: 19 | X5: 20 | Y5: 21 | Z5: 22 | AA5: 23 | AB5: 24 | AC5: 25 | AE5: =IFERROR(MATCH("Total vehicle build claim ($mm)", $A:$A, 0), "NOT FOUND") -> NOT FOUND
A7: §1 CASH POOL TRACKER
A8: Starting cash position EoY 2024 ($mm) | D8: =IF(D$5=0, INDEX(Assumptions!$B:$B, MATCH("Starting cash position EoY 2024 ($mm)", Assumptions!$A:$A, 0)), 0) -> 5000 | E8: =0 -> 0 | F8: =0 -> 0 | G8: =0 -> 0 | H8: =0 -> 0 | I8: =0 -> 0 | J8: =0 -> 0 | K8: =0 -> 0 | L8: =0 -> 0 | ... AC8: =0 -> 0
A9: IPO injection this year ($mm) | D9: =IF(D$4=INDEX(Assumptions!$B:$B, MATCH("IPO injection year", Assumptions!$A:$A, 0)), INDEX(Assumptions!$B:$B, MATCH("IPO injection amount ($mm)", Assumptions!$A:$A, 0)), 0) -> 0 | E9: =IF(E$4=INDEX(Assumptions!$B:$B, MATCH("IPO injection year", Assumptions!$A:$A, 0)), INDEX(Assumptions!$B:$B, MATCH("IPO injection amount ($mm)", Assumptions!$A:$A, 0)), 0) -> 0 | F9: =IF(F$4=INDEX(Assumptions!$B:$B, MATCH("IPO injection year", Assumptions!$A:$A, 0)), INDEX(Assumptions!$B:$B, MATCH("IPO injection amount ($mm)", Assumptions!$A:$A, 0)), 0) -> 30000 | G9: =IF(G$4=INDEX(Assumptions!$B:$B, MATCH("IPO injection year", Assumptions!$A:$A, 0)), INDEX(Assumptions!$B:$B, MATCH("IPO injection amount ($mm)", Assumptions!$A:$A, 0)), 0) -> 0 | H9: =IF(H$4=INDEX(Assumptions!$B:$B, MATCH("IPO injection year", Assumptions!$A:$A, 0)), INDEX(Assumptions!$B:$B, MATCH("IPO injection amount ($mm)", Assumptions!$A:$A, 0)), 0) -> 0 | I9: =IF(I$4=INDEX(Assumptions!$B:$B, MATCH("IPO injection year", Assumptions!$A:$A, 0)), INDEX(Assumptions!$B:$B, MATCH("IPO injection amount ($mm)", Assumptions!$A:$A, 0)), 0) -> 0 | J9: =IF(J$4=INDEX(Assumptions!$B:$B, MATCH("IPO injection year", Assumptions!$A:$A, 0)), INDEX(Assumptions!$B:$B, MATCH("IPO injection amount ($mm)", Assumptions!$A:$A, 0)), 0) -> 0 | K9: =IF(K$4=INDEX(Assumptions!$B:$B, MATCH("IPO injection year", Assumptions!$A:$A, 0)), INDEX(Assumptions!$B:$B, MATCH("IPO injection amount ($mm)", Assumptions!$A:$A, 0)), 0) -> 0 | ... AC9: =IF(AC$4=INDEX(Assumptions!$B:$B, MATCH("IPO injection year", Assumptions!$A:$A, 0)), INDEX(Assumptions!$B:$B, MATCH("IPO injection amount ($mm)", Assumptions!$A:$A, 0)), 0) -> 0
A10: Prior-year Group FCF read ($mm) | D10: {=IFERROR(IF(D$5=0, 0, INDEX('Group P&L'!$D:$AC, MATCH("GROUP FCF ($mm)", 'Group P&L'!$A:$A, 0), D$5)), 0)} -> 0 | E10: {=IFERROR(IF(E$5=0, 0, INDEX('Group P&L'!$D:$AC, MATCH("GROUP FCF ($mm)", 'Group P&L'!$A:$A, 0), E$5)), 0)} -> -2982.4363 | F10: {=IFERROR(IF(F$5=0, 0, INDEX('Group P&L'!$D:$AC, MATCH("GROUP FCF ($mm)", 'Group P&L'!$A:$A, 0), F$5)), 0)} -> -3764.0125 | G10: {=IFERROR(IF(G$5=0, 0, INDEX('Group P&L'!$D:$AC, MATCH("GROUP FCF ($mm)", 'Group P&L'!$A:$A, 0), G$5)), 0)} -> -1752.1013 | H10: {=IFERROR(IF(H$5=0, 0, INDEX('Group P&L'!$D:$AC, MATCH("GROUP FCF ($mm)", 'Group P&L'!$A:$A, 0), H$5)), 0)} -> -560.14791 | I10: {=IFERROR(IF(I$5=0, 0, INDEX('Group P&L'!$D:$AC, MATCH("GROUP FCF ($mm)", 'Group P&L'!$A:$A, 0), I$5)), 0)} -> 693.5007 | J10: {=IFERROR(IF(J$5=0, 0, INDEX('Group P&L'!$D:$AC, MATCH("GROUP FCF ($mm)", 'Group P&L'!$A:$A, 0), J$5)), 0)} -> 552.68545 | K10: {=IFERROR(IF(K$5=0, 0, INDEX('Group P&L'!$D:$AC, MATCH("GROUP FCF ($mm)", 'Group P&L'!$A:$A, 0), K$5)), 0)} -> 732.04703 | ... AC10: {=IFERROR(IF(AC$5=0, 0, INDEX('Group P&L'!$D:$AC, MATCH("GROUP FCF ($mm)", 'Group P&L'!$A:$A, 0), AC$5)), 0)} -> 7872.0421
A15: Cash BoY ($mm) | D15: =D8+D9+D10 -> 5000 | E15: =D15+E10+E9 -> 2017.5637 | F15: =E15+F10+F9 -> 28253.551 | G15: =F15+G10+G9 -> 26501.45 | H15: =G15+H10+H9 -> 25941.302 | I15: =H15+I10+I9 -> 26634.803 | J15: =I15+J10+J9 -> 27187.488 | K15: =J15+K10+K9 -> 27919.535 | L15: =K15+L10+L9 -> 28477.906 | ... AC15: =AB15+AC10+AC9 -> 82182.842
A17: §2 QUEUE GATE
A18: OpEx claim ($mm) | D18: {=IFERROR(INDEX(OpEx!$D:$AC, MATCH("Total OpEx ($mm)", OpEx!$A:$A, 0), D$5+1), 0)} -> 4309.6782 | E18: {=IFERROR(INDEX(OpEx!$D:$AC, MATCH("Total OpEx ($mm)", OpEx!$A:$A, 0), E$5+1), 0)} -> 3948.6144 | F18: {=IFERROR(INDEX(OpEx!$D:$AC, MATCH("Total OpEx ($mm)", OpEx!$A:$A, 0), F$5+1), 0)} -> 3884.7616 | G18: {=IFERROR(INDEX(OpEx!$D:$AC, MATCH("Total OpEx ($mm)", OpEx!$A:$A, 0), G$5+1), 0)} -> 3657.8936 | H18: {=IFERROR(INDEX(OpEx!$D:$AC, MATCH("Total OpEx ($mm)", OpEx!$A:$A, 0), H$5+1), 0)} -> 3414.6507 | I18: {=IFERROR(INDEX(OpEx!$D:$AC, MATCH("Total OpEx ($mm)", OpEx!$A:$A, 0), I$5+1), 0)} -> 3435.6386 | J18: {=IFERROR(INDEX(OpEx!$D:$AC, MATCH("Total OpEx ($mm)", OpEx!$A:$A, 0), J$5+1), 0)} -> 3525.0708 | K18: {=IFERROR(INDEX(OpEx!$D:$AC, MATCH("Total OpEx ($mm)", OpEx!$A:$A, 0), K$5+1), 0)} -> 3568.6303 | ... AC18: {=IFERROR(INDEX(OpEx!$D:$AC, MATCH("Total OpEx ($mm)", OpEx!$A:$A, 0), AC$5+1), 0)} -> 2471.9799
A19: Corporate CapEx claim ($mm) | D19: {=IFERROR(INDEX(CapEx!$D:$AC, MATCH("Total Corporate CapEx ($mm)", CapEx!$A:$A, 0), D$5+1), 0)} -> 110 | E19: {=IFERROR(INDEX(CapEx!$D:$AC, MATCH("Total Corporate CapEx ($mm)", CapEx!$A:$A, 0), E$5+1), 0)} -> 110 | F19: {=IFERROR(INDEX(CapEx!$D:$AC, MATCH("Total Corporate CapEx ($mm)", CapEx!$A:$A, 0), F$5+1), 0)} -> 110 | G19: {=IFERROR(INDEX(CapEx!$D:$AC, MATCH("Total Corporate CapEx ($mm)", CapEx!$A:$A, 0), G$5+1), 0)} -> 110 | H19: {=IFERROR(INDEX(CapEx!$D:$AC, MATCH("Total Corporate CapEx ($mm)", CapEx!$A:$A, 0), H$5+1), 0)} -> 110 | I19: {=IFERROR(INDEX(CapEx!$D:$AC, MATCH("Total Corporate CapEx ($mm)", CapEx!$A:$A, 0), I$5+1), 0)} -> 110 | J19: {=IFERROR(INDEX(CapEx!$D:$AC, MATCH("Total Corporate CapEx ($mm)", CapEx!$A:$A, 0), J$5+1), 0)} -> 110 | K19: {=IFERROR(INDEX(CapEx!$D:$AC, MATCH("Total Corporate CapEx ($mm)", CapEx!$A:$A, 0), K$5+1), 0)} -> 110 | ... AC19: {=IFERROR(INDEX(CapEx!$D:$AC, MATCH("Total Corporate CapEx ($mm)", CapEx!$A:$A, 0), AC$5+1), 0)} -> 110
A20: Spectrum CapEx claim ($mm) | D20: {=IFERROR(INDEX(CapEx!$D:$AC, MATCH("EchoStar mid-band CapEx ($mm)", CapEx!$A:$A, 0), D$5+1), 0)} -> 5000 | E20: {=IFERROR(INDEX(CapEx!$D:$AC, MATCH("EchoStar mid-band CapEx ($mm)", CapEx!$A:$A, 0), E$5+1), 0)} -> 8000 | F20: {=IFERROR(INDEX(CapEx!$D:$AC, MATCH("EchoStar mid-band CapEx ($mm)", CapEx!$A:$A, 0), F$5+1), 0)} -> 5000 | G20: {=IFERROR(INDEX(CapEx!$D:$AC, MATCH("EchoStar mid-band CapEx ($mm)", CapEx!$A:$A, 0), G$5+1), 0)} -> 2000 | H20: {=IFERROR(INDEX(CapEx!$D:$AC, MATCH("EchoStar mid-band CapEx ($mm)", CapEx!$A:$A, 0), H$5+1), 0)} -> 0 | I20: {=IFERROR(INDEX(CapEx!$D:$AC, MATCH("EchoStar mid-band CapEx ($mm)", CapEx!$A:$A, 0), I$5+1), 0)} -> 0 | J20: {=IFERROR(INDEX(CapEx!$D:$AC, MATCH("EchoStar mid-band CapEx ($mm)", CapEx!$A:$A, 0), J$5+1), 0)} -> 0 | K20: {=IFERROR(INDEX(CapEx!$D:$AC, MATCH("EchoStar mid-band CapEx ($mm)", CapEx!$A:$A, 0), K$5+1), 0)} -> 0 | ... AC20: {=IFERROR(INDEX(CapEx!$D:$AC, MATCH("EchoStar mid-band CapEx ($mm)", CapEx!$A:$A, 0), AC$5+1), 0)} -> 0
A21: Taxes claim ($mm) | D21: {=IFERROR(INDEX('Group P&L'!$D:$AC, MATCH("Taxes ($mm)", 'Group P&L'!$A:$A, 0), D$5+1), 0)} -> 819.83327 | E21: {=IFERROR(INDEX('Group P&L'!$D:$AC, MATCH("Taxes ($mm)", 'Group P&L'!$A:$A, 0), E$5+1), 0)} -> 1023.0916 | F21: {=IFERROR(INDEX('Group P&L'!$D:$AC, MATCH("Taxes ($mm)", 'Group P&L'!$A:$A, 0), F$5+1), 0)} -> 710.21719 | G21: {=IFERROR(INDEX('Group P&L'!$D:$AC, MATCH("Taxes ($mm)", 'Group P&L'!$A:$A, 0), G$5+1), 0)} -> 492.51791 | H21: {=IFERROR(INDEX('Group P&L'!$D:$AC, MATCH("Taxes ($mm)", 'Group P&L'!$A:$A, 0), H$5+1), 0)} -> 285.70274 | I21: {=IFERROR(INDEX('Group P&L'!$D:$AC, MATCH("Taxes ($mm)", 'Group P&L'!$A:$A, 0), I$5+1), 0)} -> 226.45926 | J21: {=IFERROR(INDEX('Group P&L'!$D:$AC, MATCH("Taxes ($mm)", 'Group P&L'!$A:$A, 0), J$5+1), 0)} -> 190.39148 | K21: {=IFERROR(INDEX('Group P&L'!$D:$AC, MATCH("Taxes ($mm)", 'Group P&L'!$A:$A, 0), K$5+1), 0)} -> 11.024267 | ... AC21: {=IFERROR(INDEX('Group P&L'!$D:$AC, MATCH("Taxes ($mm)", 'Group P&L'!$A:$A, 0), AC$5+1), 0)} -> 0
A22: Mars/Moon carve-out claim ($mm) | D22: =D35 -> 1000 | E22: =E35 -> 1000 | F22: =F35 -> 1000 | G22: =G35 -> 1000 | H22: =H35 -> 1000 | I22: =I35 -> 1000 | J22: =J35 -> 1000 | K22: =K35 -> 1000 | ... AC22: =AC35 -> 1000
A23: Vehicle build claim ($mm) | D23: =D156 -> 0 | E23: =E156 -> 83.711001 | F23: =F156 -> 126.98606 | G23: =G156 -> 126.48848 | H23: =H156 -> 152.67406 | I23: =I156 -> 97.909678 | J23: =J156 -> 185.01994 | K23: =K156 -> 152.23353 | ... AC23: =AC156 -> 0
A28: Year-N non-module claims ($mm) | D28: =SUM(D18:D23) -> 11239.512 | E28: =SUM(E18:E23) -> 14165.417 | F28: =SUM(F18:F23) -> 10831.965 | G28: =SUM(G18:G23) -> 7386.8999 | H28: =SUM(H18:H23) -> 4963.0275 | I28: =SUM(I18:I23) -> 4870.0075 | J28: =SUM(J18:J23) -> 5010.4822 | K28: =SUM(K18:K23) -> 4841.8881 | ... AC28: =SUM(AC18:AC23) -> 3581.9799
A29: Available cash for IRR queue ($mm) | D29: =MAX(0, D15-D28) -> 0 | E29: =MAX(0, E15-E28) -> 0 | F29: =MAX(0, F15-F28) -> 17421.586 | G29: =MAX(0, G15-G28) -> 19114.55 | H29: =MAX(0, H15-H28) -> 20978.275 | I29: =MAX(0, I15-I28) -> 21764.795 | J29: =MAX(0, J15-J28) -> 22177.006 | K29: =MAX(0, K15-K28) -> 23077.647 | ... AC29: =MAX(0, AC15-AC28) -> 78600.862
A31: §3 MARS/MOON STRATEGIC CARVE-OUT
A32: Mars carve-out % of prior-year Group FCF (input) | C32: Reads Assumptions R12 by canonical label. Base Case 15%; MC [3%, 35%] triangle. | D32: =INDEX(Assumptions!$B:$B, MATCH("Mars carve-out % of prior-year Group FCF", Assumptions!$A:$A, 0)) -> 0.15 | E32: =INDEX(Assumptions!$B:$B, MATCH("Mars carve-out % of prior-year Group FCF", Assumptions!$A:$A, 0)) -> 0.15 | F32: =INDEX(Assumptions!$B:$B, MATCH("Mars carve-out % of prior-year Group FCF", Assumptions!$A:$A, 0)) -> 0.15 | G32: =INDEX(Assumptions!$B:$B, MATCH("Mars carve-out % of prior-year Group FCF", Assumptions!$A:$A, 0)) -> 0.15 | H32: =INDEX(Assumptions!$B:$B, MATCH("Mars carve-out % of prior-year Group FCF", Assumptions!$A:$A, 0)) -> 0.15 | I32: =INDEX(Assumptions!$B:$B, MATCH("Mars carve-out % of prior-year Group FCF", Assumptions!$A:$A, 0)) -> 0.15 | J32: =INDEX(Assumptions!$B:$B, MATCH("Mars carve-out % of prior-year Group FCF", Assumptions!$A:$A, 0)) -> 0.15 | K32: =INDEX(Assumptions!$B:$B, MATCH("Mars carve-out % of prior-year Group FCF", Assumptions!$A:$A, 0)) -> 0.15 | ... AC32: =INDEX(Assumptions!$B:$B, MATCH("Mars carve-out % of prior-year Group FCF", Assumptions!$A:$A, 0)) -> 0.15
A33: Mars carve-out floor ($mm/yr) (input) | C33: Reads Assumptions R13. Base Case $1,000M; MC [$500M, $2,500M] triangle. | D33: =INDEX(Assumptions!$B:$B, MATCH("Mars carve-out floor ($mm/yr)", Assumptions!$A:$A, 0)) -> 1000 | E33: =INDEX(Assumptions!$B:$B, MATCH("Mars carve-out floor ($mm/yr)", Assumptions!$A:$A, 0)) -> 1000 | F33: =INDEX(Assumptions!$B:$B, MATCH("Mars carve-out floor ($mm/yr)", Assumptions!$A:$A, 0)) -> 1000 | G33: =INDEX(Assumptions!$B:$B, MATCH("Mars carve-out floor ($mm/yr)", Assumptions!$A:$A, 0)) -> 1000 | H33: =INDEX(Assumptions!$B:$B, MATCH("Mars carve-out floor ($mm/yr)", Assumptions!$A:$A, 0)) -> 1000 | I33: =INDEX(Assumptions!$B:$B, MATCH("Mars carve-out floor ($mm/yr)", Assumptions!$A:$A, 0)) -> 1000 | J33: =INDEX(Assumptions!$B:$B, MATCH("Mars carve-out floor ($mm/yr)", Assumptions!$A:$A, 0)) -> 1000 | K33: =INDEX(Assumptions!$B:$B, MATCH("Mars carve-out floor ($mm/yr)", Assumptions!$A:$A, 0)) -> 1000 | ... AC33: =INDEX(Assumptions!$B:$B, MATCH("Mars carve-out floor ($mm/yr)", Assumptions!$A:$A, 0)) -> 1000
A34: Prior-year Group FCF read ($mm/yr) | C34: Sprint 9 fix: (1) label drift Sprint 7 used 'GROUP FCF' → Sprint 9 publishes 'GROUP FCF ($mm)' canonical; (2) column reference bug Sprint 7 used E$5 (next column year-offset) → Sprint 9 uses D$5 (current column year-offset) for correct prior-year lookback. D34 (2025) reads INDEX col_num=0 → IFERROR returns 0; E34 (2026) reads col_num=1 = 2025 FCF; ... AC34 (2050) reads col_num=25 = 2049 FCF. | D34: {=IFERROR(IF(D$5=0, 0, INDEX('Group P&L'!$D:$AC, MATCH("GROUP FCF ($mm)", 'Group P&L'!$A:$A, 0), D$5)), 0)} -> 0 | E34: {=IFERROR(IF(E$5=0, 0, INDEX('Group P&L'!$D:$AC, MATCH("GROUP FCF ($mm)", 'Group P&L'!$A:$A, 0), E$5)), 0)} -> -2982.4363 | F34: {=IFERROR(IF(F$5=0, 0, INDEX('Group P&L'!$D:$AC, MATCH("GROUP FCF ($mm)", 'Group P&L'!$A:$A, 0), F$5)), 0)} -> -3764.0125 | G34: {=IFERROR(IF(G$5=0, 0, INDEX('Group P&L'!$D:$AC, MATCH("GROUP FCF ($mm)", 'Group P&L'!$A:$A, 0), G$5)), 0)} -> -1752.1013 | H34: {=IFERROR(IF(H$5=0, 0, INDEX('Group P&L'!$D:$AC, MATCH("GROUP FCF ($mm)", 'Group P&L'!$A:$A, 0), H$5)), 0)} -> -560.14791 | I34: {=IFERROR(IF(I$5=0, 0, INDEX('Group P&L'!$D:$AC, MATCH("GROUP FCF ($mm)", 'Group P&L'!$A:$A, 0), I$5)), 0)} -> 693.5007 | J34: {=IFERROR(IF(J$5=0, 0, INDEX('Group P&L'!$D:$AC, MATCH("GROUP FCF ($mm)", 'Group P&L'!$A:$A, 0), J$5)), 0)} -> 552.68545 | K34: {=IFERROR(IF(K$5=0, 0, INDEX('Group P&L'!$D:$AC, MATCH("GROUP FCF ($mm)", 'Group P&L'!$A:$A, 0), K$5)), 0)} -> 732.04703 | ... AC34: {=IFERROR(IF(AC$5=0, 0, INDEX('Group P&L'!$D:$AC, MATCH("GROUP FCF ($mm)", 'Group P&L'!$A:$A, 0), AC$5)), 0)} -> 7872.0421
A35: Mars/Moon strategic carve-out ($mm/yr) | C35: Architecture §11.1: MAX(floor, prior-year FCF × pct). Pre-Sprint-9: prior FCF=0 → carve-out hits floor. CANONICAL ROW Sprint 10 Queue Gate subtracts + Lunar Mars module reads. | D35: =MAX(D33, D32*D34) -> 1000 | E35: =MAX(E33, E32*E34) -> 1000 | F35: =MAX(F33, F32*F34) -> 1000 | G35: =MAX(G33, G32*G34) -> 1000 | H35: =MAX(H33, H32*H34) -> 1000 | I35: =MAX(I33, I32*I34) -> 1000 | J35: =MAX(J33, J32*J34) -> 1000 | K35: =MAX(K33, K32*K34) -> 1000 | ... AC35: =MAX(AC33, AC32*AC34) -> 1180.8063
A36: Lunar share of carve-out (% — year-row) | C36: Reads Assumptions R226 year-row by canonical label. | D36: {=INDEX(Assumptions!$D:$AC, MATCH("Lunar share of Mars/Moon carve-out cash — year-row", Assumptions!$A:$A, 0), D$5+1)} -> 1 | E36: {=INDEX(Assumptions!$D:$AC, MATCH("Lunar share of Mars/Moon carve-out cash — year-row", Assumptions!$A:$A, 0), E$5+1)} -> 1 | F36: {=INDEX(Assumptions!$D:$AC, MATCH("Lunar share of Mars/Moon carve-out cash — year-row", Assumptions!$A:$A, 0), F$5+1)} -> 1 | G36: {=INDEX(Assumptions!$D:$AC, MATCH("Lunar share of Mars/Moon carve-out cash — year-row", Assumptions!$A:$A, 0), G$5+1)} -> 0.7 | H36: {=INDEX(Assumptions!$D:$AC, MATCH("Lunar share of Mars/Moon carve-out cash — year-row", Assumptions!$A:$A, 0), H$5+1)} -> 0.7 | I36: {=INDEX(Assumptions!$D:$AC, MATCH("Lunar share of Mars/Moon carve-out cash — year-row", Assumptions!$A:$A, 0), I$5+1)} -> 0.7 | J36: {=INDEX(Assumptions!$D:$AC, MATCH("Lunar share of Mars/Moon carve-out cash — year-row", Assumptions!$A:$A, 0), J$5+1)} -> 0.7 | K36: {=INDEX(Assumptions!$D:$AC, MATCH("Lunar share of Mars/Moon carve-out cash — year-row", Assumptions!$A:$A, 0), K$5+1)} -> 0.7 | ... AC36: {=INDEX(Assumptions!$D:$AC, MATCH("Lunar share of Mars/Moon carve-out cash — year-row", Assumptions!$A:$A, 0), AC$5+1)} -> 0.7
A37: Mars share of carve-out (% — year-row) | C37: Reads Assumptions R227 year-row by canonical label. | D37: {=INDEX(Assumptions!$D:$AC, MATCH("Mars share of carve-out cash — year-row", Assumptions!$A:$A, 0), D$5+1)} -> 0 | E37: {=INDEX(Assumptions!$D:$AC, MATCH("Mars share of carve-out cash — year-row", Assumptions!$A:$A, 0), E$5+1)} -> 0 | F37: {=INDEX(Assumptions!$D:$AC, MATCH("Mars share of carve-out cash — year-row", Assumptions!$A:$A, 0), F$5+1)} -> 0 | G37: {=INDEX(Assumptions!$D:$AC, MATCH("Mars share of carve-out cash — year-row", Assumptions!$A:$A, 0), G$5+1)} -> 0.3 | H37: {=INDEX(Assumptions!$D:$AC, MATCH("Mars share of carve-out cash — year-row", Assumptions!$A:$A, 0), H$5+1)} -> 0.3 | I37: {=INDEX(Assumptions!$D:$AC, MATCH("Mars share of carve-out cash — year-row", Assumptions!$A:$A, 0), I$5+1)} -> 0.3 | J37: {=INDEX(Assumptions!$D:$AC, MATCH("Mars share of carve-out cash — year-row", Assumptions!$A:$A, 0), J$5+1)} -> 0.3 | K37: {=INDEX(Assumptions!$D:$AC, MATCH("Mars share of carve-out cash — year-row", Assumptions!$A:$A, 0), K$5+1)} -> 0.3 | ... AC37: {=INDEX(Assumptions!$D:$AC, MATCH("Mars share of carve-out cash — year-row", Assumptions!$A:$A, 0), AC$5+1)} -> 0.3
A39: §4 CASH IRR-PRIORITY SIGMOID QUEUE
A41: ▸ Customer Launch (in-queue module)
A42: Customer Launch Blended IRR | D42: {=IFERROR(INDEX('Customer Launch'!$D:$AC, MATCH("Blended IRR", 'Customer Launch'!$A:$A, 0), D$5+1), 0)} -> 2.672961 | E42: {=IFERROR(INDEX('Customer Launch'!$D:$AC, MATCH("Blended IRR", 'Customer Launch'!$A:$A, 0), E$5+1), 0)} -> 2.5531329 | F42: {=IFERROR(INDEX('Customer Launch'!$D:$AC, MATCH("Blended IRR", 'Customer Launch'!$A:$A, 0), F$5+1), 0)} -> 2.3854104 | G42: {=IFERROR(INDEX('Customer Launch'!$D:$AC, MATCH("Blended IRR", 'Customer Launch'!$A:$A, 0), G$5+1), 0)} -> 2.2397201 | H42: {=IFERROR(INDEX('Customer Launch'!$D:$AC, MATCH("Blended IRR", 'Customer Launch'!$A:$A, 0), H$5+1), 0)} -> 2.1144672 | I42: {=IFERROR(INDEX('Customer Launch'!$D:$AC, MATCH("Blended IRR", 'Customer Launch'!$A:$A, 0), I$5+1), 0)} -> 1.8066341 | J42: {=IFERROR(INDEX('Customer Launch'!$D:$AC, MATCH("Blended IRR", 'Customer Launch'!$A:$A, 0), J$5+1), 0)} -> 1.8979413 | K42: {=IFERROR(INDEX('Customer Launch'!$D:$AC, MATCH("Blended IRR", 'Customer Launch'!$A:$A, 0), K$5+1), 0)} -> 1.4068518 | ... AC42: {=IFERROR(INDEX('Customer Launch'!$D:$AC, MATCH("Blended IRR", 'Customer Launch'!$A:$A, 0), AC$5+1), 0)} -> -0.0050735922
A43: Customer Launch cash demand ($mm) | D43: {=IFERROR(INDEX('Customer Launch'!$D:$AC, MATCH("Module CapEx ($mm)", 'Customer Launch'!$A:$A, 0), D$5+1), 0)} -> 32.86065 | E43: {=IFERROR(INDEX('Customer Launch'!$D:$AC, MATCH("Module CapEx ($mm)", 'Customer Launch'!$A:$A, 0), E$5+1), 0)} -> 21.80802 | F43: {=IFERROR(INDEX('Customer Launch'!$D:$AC, MATCH("Module CapEx ($mm)", 'Customer Launch'!$A:$A, 0), F$5+1), 0)} -> 21.780008 | G43: {=IFERROR(INDEX('Customer Launch'!$D:$AC, MATCH("Module CapEx ($mm)", 'Customer Launch'!$A:$A, 0), G$5+1), 0)} -> 21.752738 | H43: {=IFERROR(INDEX('Customer Launch'!$D:$AC, MATCH("Module CapEx ($mm)", 'Customer Launch'!$A:$A, 0), H$5+1), 0)} -> 21.278337 | I43: {=IFERROR(INDEX('Customer Launch'!$D:$AC, MATCH("Module CapEx ($mm)", 'Customer Launch'!$A:$A, 0), I$5+1), 0)} -> 20.738221 | J43: {=IFERROR(INDEX('Customer Launch'!$D:$AC, MATCH("Module CapEx ($mm)", 'Customer Launch'!$A:$A, 0), J$5+1), 0)} -> 20.554165 | K43: {=IFERROR(INDEX('Customer Launch'!$D:$AC, MATCH("Module CapEx ($mm)", 'Customer Launch'!$A:$A, 0), K$5+1), 0)} -> 17.606898 | ... AC43: {=IFERROR(INDEX('Customer Launch'!$D:$AC, MATCH("Module CapEx ($mm)", 'Customer Launch'!$A:$A, 0), AC$5+1), 0)} -> 9.1984314
A44: Customer Launch weight | D44: =MAX(D42, 0)^INDEX(Assumptions!$B:$B, MATCH("Sigmoid IRR-blend exponent k", Assumptions!$A:$A, 0)) * IF(D43 > 0, 1, 0) -> 7.1447205 | E44: =MAX(E42, 0)^INDEX(Assumptions!$B:$B, MATCH("Sigmoid IRR-blend exponent k", Assumptions!$A:$A, 0)) * IF(E43 > 0, 1, 0) -> 6.5184874 | F44: =MAX(F42, 0)^INDEX(Assumptions!$B:$B, MATCH("Sigmoid IRR-blend exponent k", Assumptions!$A:$A, 0)) * IF(F43 > 0, 1, 0) -> 5.6901826 | G44: =MAX(G42, 0)^INDEX(Assumptions!$B:$B, MATCH("Sigmoid IRR-blend exponent k", Assumptions!$A:$A, 0)) * IF(G43 > 0, 1, 0) -> 5.0163459 | H44: =MAX(H42, 0)^INDEX(Assumptions!$B:$B, MATCH("Sigmoid IRR-blend exponent k", Assumptions!$A:$A, 0)) * IF(H43 > 0, 1, 0) -> 4.4709717 | I44: =MAX(I42, 0)^INDEX(Assumptions!$B:$B, MATCH("Sigmoid IRR-blend exponent k", Assumptions!$A:$A, 0)) * IF(I43 > 0, 1, 0) -> 3.2639266 | J44: =MAX(J42, 0)^INDEX(Assumptions!$B:$B, MATCH("Sigmoid IRR-blend exponent k", Assumptions!$A:$A, 0)) * IF(J43 > 0, 1, 0) -> 3.6021813 | K44: =MAX(K42, 0)^INDEX(Assumptions!$B:$B, MATCH("Sigmoid IRR-blend exponent k", Assumptions!$A:$A, 0)) * IF(K43 > 0, 1, 0) -> 1.9792321 | ... AC44: =MAX(AC42, 0)^INDEX(Assumptions!$B:$B, MATCH("Sigmoid IRR-blend exponent k", Assumptions!$A:$A, 0)) * IF(AC43 > 0, 1, 0) -> 0
A45: Customer Launch proposed allocation ($mm) | D45: =MIN(IF(D42 > 0, D43, 0), $D$29 * D44 / IF($D$80 > 0, $D$80, 1)) -> 0 | E45: =MIN(IF(E42 > 0, E43, 0), $D$29 * E44 / IF($D$80 > 0, $D$80, 1)) -> 0 | F45: =MIN(IF(F42 > 0, F43, 0), $D$29 * F44 / IF($D$80 > 0, $D$80, 1)) -> 0 | G45: =MIN(IF(G42 > 0, G43, 0), $D$29 * G44 / IF($D$80 > 0, $D$80, 1)) -> 0 | H45: =MIN(IF(H42 > 0, H43, 0), $D$29 * H44 / IF($D$80 > 0, $D$80, 1)) -> 0 | I45: =MIN(IF(I42 > 0, I43, 0), $D$29 * I44 / IF($D$80 > 0, $D$80, 1)) -> 0 | J45: =MIN(IF(J42 > 0, J43, 0), $D$29 * J44 / IF($D$80 > 0, $D$80, 1)) -> 0 | K45: =MIN(IF(K42 > 0, K43, 0), $D$29 * K44 / IF($D$80 > 0, $D$80, 1)) -> 0 | ... AC45: =MIN(IF(AC42 > 0, AC43, 0), $D$29 * AC44 / IF($D$80 > 0, $D$80, 1)) -> 0
A46: ▸ Starlink V2 BB
A47: Starlink V2 BB Blended IRR | D47: {=IFERROR(INDEX(Starlink!$D:$AC, MATCH("Memo: V2 BB Blended IRR", Starlink!$A:$A, 0), D$5+1), 0)} -> 1.0015767 | E47: {=IFERROR(INDEX(Starlink!$D:$AC, MATCH("Memo: V2 BB Blended IRR", Starlink!$A:$A, 0), E$5+1), 0)} -> 1.3773794 | F47: {=IFERROR(INDEX(Starlink!$D:$AC, MATCH("Memo: V2 BB Blended IRR", Starlink!$A:$A, 0), F$5+1), 0)} -> 1.827446 | G47: {=IFERROR(INDEX(Starlink!$D:$AC, MATCH("Memo: V2 BB Blended IRR", Starlink!$A:$A, 0), G$5+1), 0)} -> -0.21617069 | H47: {=IFERROR(INDEX(Starlink!$D:$AC, MATCH("Memo: V2 BB Blended IRR", Starlink!$A:$A, 0), H$5+1), 0)} -> -0.07171016 | I47: {=IFERROR(INDEX(Starlink!$D:$AC, MATCH("Memo: V2 BB Blended IRR", Starlink!$A:$A, 0), I$5+1), 0)} -> -1 | J47: {=IFERROR(INDEX(Starlink!$D:$AC, MATCH("Memo: V2 BB Blended IRR", Starlink!$A:$A, 0), J$5+1), 0)} -> -1 | K47: {=IFERROR(INDEX(Starlink!$D:$AC, MATCH("Memo: V2 BB Blended IRR", Starlink!$A:$A, 0), K$5+1), 0)} -> -1 | ... AC47: {=IFERROR(INDEX(Starlink!$D:$AC, MATCH("Memo: V2 BB Blended IRR", Starlink!$A:$A, 0), AC$5+1), 0)} -> -1
A48: Starlink V2 BB cash demand ($mm) | D48: {=IF(D$4 >= INDEX(Assumptions!$B:$B, MATCH("V2 phase-out year (no V2 BB / V2 DTC launches from this year)", Assumptions!$A:$A, 0)), 0, IFERROR(INDEX(Starlink!$D:$AC, MATCH("V2 BB sat CapEx ($mm)", Starlink!$A:$A, 0), D$5+1) + INDEX(Starlink!$D:$AC, MATCH("V2 BB facility CapEx ($mm)", Starlink!$A:$A, 0), D$5+1), 0))} -> 1116.3913 | E48: {=IF(E$4 >= INDEX(Assumptions!$B:$B, MATCH("V2 phase-out year (no V2 BB / V2 DTC launches from this year)", Assumptions!$A:$A, 0)), 0, IFERROR(INDEX(Starlink!$D:$AC, MATCH("V2 BB sat CapEx ($mm)", Starlink!$A:$A, 0), E$5+1) + INDEX(Starlink!$D:$AC, MATCH("V2 BB facility CapEx ($mm)", Starlink!$A:$A, 0), E$5+1), 0))} -> 0 | F48: {=IF(F$4 >= INDEX(Assumptions!$B:$B, MATCH("V2 phase-out year (no V2 BB / V2 DTC launches from this year)", Assumptions!$A:$A, 0)), 0, IFERROR(INDEX(Starlink!$D:$AC, MATCH("V2 BB sat CapEx ($mm)", Starlink!$A:$A, 0), F$5+1) + INDEX(Starlink!$D:$AC, MATCH("V2 BB facility CapEx ($mm)", Starlink!$A:$A, 0), F$5+1), 0))} -> 0 | G48: {=IF(G$4 >= INDEX(Assumptions!$B:$B, MATCH("V2 phase-out year (no V2 BB / V2 DTC launches from this year)", Assumptions!$A:$A, 0)), 0, IFERROR(INDEX(Starlink!$D:$AC, MATCH("V2 BB sat CapEx ($mm)", Starlink!$A:$A, 0), G$5+1) + INDEX(Starlink!$D:$AC, MATCH("V2 BB facility CapEx ($mm)", Starlink!$A:$A, 0), G$5+1), 0))} -> 0 | H48: {=IF(H$4 >= INDEX(Assumptions!$B:$B, MATCH("V2 phase-out year (no V2 BB / V2 DTC launches from this year)", Assumptions!$A:$A, 0)), 0, IFERROR(INDEX(Starlink!$D:$AC, MATCH("V2 BB sat CapEx ($mm)", Starlink!$A:$A, 0), H$5+1) + INDEX(Starlink!$D:$AC, MATCH("V2 BB facility CapEx ($mm)", Starlink!$A:$A, 0), H$5+1), 0))} -> 0 | I48: {=IF(I$4 >= INDEX(Assumptions!$B:$B, MATCH("V2 phase-out year (no V2 BB / V2 DTC launches from this year)", Assumptions!$A:$A, 0)), 0, IFERROR(INDEX(Starlink!$D:$AC, MATCH("V2 BB sat CapEx ($mm)", Starlink!$A:$A, 0), I$5+1) + INDEX(Starlink!$D:$AC, MATCH("V2 BB facility CapEx ($mm)", Starlink!$A:$A, 0), I$5+1), 0))} -> 0 | J48: {=IF(J$4 >= INDEX(Assumptions!$B:$B, MATCH("V2 phase-out year (no V2 BB / V2 DTC launches from this year)", Assumptions!$A:$A, 0)), 0, IFERROR(INDEX(Starlink!$D:$AC, MATCH("V2 BB sat CapEx ($mm)", Starlink!$A:$A, 0), J$5+1) + INDEX(Starlink!$D:$AC, MATCH("V2 BB facility CapEx ($mm)", Starlink!$A:$A, 0), J$5+1), 0))} -> 0 | K48: {=IF(K$4 >= INDEX(Assumptions!$B:$B, MATCH("V2 phase-out year (no V2 BB / V2 DTC launches from this year)", Assumptions!$A:$A, 0)), 0, IFERROR(INDEX(Starlink!$D:$AC, MATCH("V2 BB sat CapEx ($mm)", Starlink!$A:$A, 0), K$5+1) + INDEX(Starlink!$D:$AC, MATCH("V2 BB facility CapEx ($mm)", Starlink!$A:$A, 0), K$5+1), 0))} -> 0 | ... AC48: {=IF(AC$4 >= INDEX(Assumptions!$B:$B, MATCH("V2 phase-out year (no V2 BB / V2 DTC launches from this year)", Assumptions!$A:$A, 0)), 0, IFERROR(INDEX(Starlink!$D:$AC, MATCH("V2 BB sat CapEx ($mm)", Starlink!$A:$A, 0), AC$5+1) + INDEX(Starlink!$D:$AC, MATCH("V2 BB facility CapEx ($mm)", Starlink!$A:$A, 0), AC$5+1), 0))} -> 0
A49: Starlink V2 BB weight | D49: =MAX(D47, 0)^INDEX(Assumptions!$B:$B, MATCH("Sigmoid IRR-blend exponent k", Assumptions!$A:$A, 0)) * IF(D48 > 0, 1, 0) -> 1.0031558 | E49: =MAX(E47, 0)^INDEX(Assumptions!$B:$B, MATCH("Sigmoid IRR-blend exponent k", Assumptions!$A:$A, 0)) * IF(E48 > 0, 1, 0) -> 0 | F49: =MAX(F47, 0)^INDEX(Assumptions!$B:$B, MATCH("Sigmoid IRR-blend exponent k", Assumptions!$A:$A, 0)) * IF(F48 > 0, 1, 0) -> 0 | G49: =MAX(G47, 0)^INDEX(Assumptions!$B:$B, MATCH("Sigmoid IRR-blend exponent k", Assumptions!$A:$A, 0)) * IF(G48 > 0, 1, 0) -> 0 | H49: =MAX(H47, 0)^INDEX(Assumptions!$B:$B, MATCH("Sigmoid IRR-blend exponent k", Assumptions!$A:$A, 0)) * IF(H48 > 0, 1, 0) -> 0 | I49: =MAX(I47, 0)^INDEX(Assumptions!$B:$B, MATCH("Sigmoid IRR-blend exponent k", Assumptions!$A:$A, 0)) * IF(I48 > 0, 1, 0) -> 0 | J49: =MAX(J47, 0)^INDEX(Assumptions!$B:$B, MATCH("Sigmoid IRR-blend exponent k", Assumptions!$A:$A, 0)) * IF(J48 > 0, 1, 0) -> 0 | K49: =MAX(K47, 0)^INDEX(Assumptions!$B:$B, MATCH("Sigmoid IRR-blend exponent k", Assumptions!$A:$A, 0)) * IF(K48 > 0, 1, 0) -> 0 | ... AC49: =MAX(AC47, 0)^INDEX(Assumptions!$B:$B, MATCH("Sigmoid IRR-blend exponent k", Assumptions!$A:$A, 0)) * IF(AC48 > 0, 1, 0) -> 0
A50: Starlink V2 BB proposed allocation ($mm) | D50: =MIN(IF(D47 > 0, D48, 0), $D$29 * D49 / IF($D$80 > 0, $D$80, 1)) -> 0 | E50: =MIN(IF(E47 > 0, E48, 0), $D$29 * E49 / IF($D$80 > 0, $D$80, 1)) -> 0 | F50: =MIN(IF(F47 > 0, F48, 0), $D$29 * F49 / IF($D$80 > 0, $D$80, 1)) -> 0 | G50: =MIN(IF(G47 > 0, G48, 0), $D$29 * G49 / IF($D$80 > 0, $D$80, 1)) -> 0 | H50: =MIN(IF(H47 > 0, H48, 0), $D$29 * H49 / IF($D$80 > 0, $D$80, 1)) -> 0 | I50: =MIN(IF(I47 > 0, I48, 0), $D$29 * I49 / IF($D$80 > 0, $D$80, 1)) -> 0 | J50: =MIN(IF(J47 > 0, J48, 0), $D$29 * J49 / IF($D$80 > 0, $D$80, 1)) -> 0 | K50: =MIN(IF(K47 > 0, K48, 0), $D$29 * K49 / IF($D$80 > 0, $D$80, 1)) -> 0 | ... AC50: =MIN(IF(AC47 > 0, AC48, 0), $D$29 * AC49 / IF($D$80 > 0, $D$80, 1)) -> 0
A51: ▸ Starlink V2 DTC
A52: Starlink V2 DTC Blended IRR | D52: {=IFERROR(INDEX(Starlink!$D:$AC, MATCH("Memo: V2 DTC Blended IRR", Starlink!$A:$A, 0), D$5+1), 0)} -> 0.13805576 | E52: {=IFERROR(INDEX(Starlink!$D:$AC, MATCH("Memo: V2 DTC Blended IRR", Starlink!$A:$A, 0), E$5+1), 0)} -> 0.27607671 | F52: {=IFERROR(INDEX(Starlink!$D:$AC, MATCH("Memo: V2 DTC Blended IRR", Starlink!$A:$A, 0), F$5+1), 0)} -> 0.42717676 | G52: {=IFERROR(INDEX(Starlink!$D:$AC, MATCH("Memo: V2 DTC Blended IRR", Starlink!$A:$A, 0), G$5+1), 0)} -> 0.52736311 | H52: {=IFERROR(INDEX(Starlink!$D:$AC, MATCH("Memo: V2 DTC Blended IRR", Starlink!$A:$A, 0), H$5+1), 0)} -> 0.63751435 | I52: {=IFERROR(INDEX(Starlink!$D:$AC, MATCH("Memo: V2 DTC Blended IRR", Starlink!$A:$A, 0), I$5+1), 0)} -> 0.73028364 | J52: {=IFERROR(INDEX(Starlink!$D:$AC, MATCH("Memo: V2 DTC Blended IRR", Starlink!$A:$A, 0), J$5+1), 0)} -> 0.83195988 | K52: {=IFERROR(INDEX(Starlink!$D:$AC, MATCH("Memo: V2 DTC Blended IRR", Starlink!$A:$A, 0), K$5+1), 0)} -> 0.94366019 | ... AC52: {=IFERROR(INDEX(Starlink!$D:$AC, MATCH("Memo: V2 DTC Blended IRR", Starlink!$A:$A, 0), AC$5+1), 0)} -> 0.15189202
A53: Starlink V2 DTC cash demand ($mm) | D53: {=IF(D$4 >= INDEX(Assumptions!$B:$B, MATCH("V2 phase-out year (no V2 BB / V2 DTC launches from this year)", Assumptions!$A:$A, 0)), 0, IFERROR(INDEX(Starlink!$D:$AC, MATCH("V2 DTC sat CapEx ($mm)", Starlink!$A:$A, 0), D$5+1) + INDEX(Starlink!$D:$AC, MATCH("V2 DTC facility CapEx ($mm)", Starlink!$A:$A, 0), D$5+1), 0))} -> 68.0225 | E53: {=IF(E$4 >= INDEX(Assumptions!$B:$B, MATCH("V2 phase-out year (no V2 BB / V2 DTC launches from this year)", Assumptions!$A:$A, 0)), 0, IFERROR(INDEX(Starlink!$D:$AC, MATCH("V2 DTC sat CapEx ($mm)", Starlink!$A:$A, 0), E$5+1) + INDEX(Starlink!$D:$AC, MATCH("V2 DTC facility CapEx ($mm)", Starlink!$A:$A, 0), E$5+1), 0))} -> 0 | F53: {=IF(F$4 >= INDEX(Assumptions!$B:$B, MATCH("V2 phase-out year (no V2 BB / V2 DTC launches from this year)", Assumptions!$A:$A, 0)), 0, IFERROR(INDEX(Starlink!$D:$AC, MATCH("V2 DTC sat CapEx ($mm)", Starlink!$A:$A, 0), F$5+1) + INDEX(Starlink!$D:$AC, MATCH("V2 DTC facility CapEx ($mm)", Starlink!$A:$A, 0), F$5+1), 0))} -> 0 | G53: {=IF(G$4 >= INDEX(Assumptions!$B:$B, MATCH("V2 phase-out year (no V2 BB / V2 DTC launches from this year)", Assumptions!$A:$A, 0)), 0, IFERROR(INDEX(Starlink!$D:$AC, MATCH("V2 DTC sat CapEx ($mm)", Starlink!$A:$A, 0), G$5+1) + INDEX(Starlink!$D:$AC, MATCH("V2 DTC facility CapEx ($mm)", Starlink!$A:$A, 0), G$5+1), 0))} -> 0 | H53: {=IF(H$4 >= INDEX(Assumptions!$B:$B, MATCH("V2 phase-out year (no V2 BB / V2 DTC launches from this year)", Assumptions!$A:$A, 0)), 0, IFERROR(INDEX(Starlink!$D:$AC, MATCH("V2 DTC sat CapEx ($mm)", Starlink!$A:$A, 0), H$5+1) + INDEX(Starlink!$D:$AC, MATCH("V2 DTC facility CapEx ($mm)", Starlink!$A:$A, 0), H$5+1), 0))} -> 0 | I53: {=IF(I$4 >= INDEX(Assumptions!$B:$B, MATCH("V2 phase-out year (no V2 BB / V2 DTC launches from this year)", Assumptions!$A:$A, 0)), 0, IFERROR(INDEX(Starlink!$D:$AC, MATCH("V2 DTC sat CapEx ($mm)", Starlink!$A:$A, 0), I$5+1) + INDEX(Starlink!$D:$AC, MATCH("V2 DTC facility CapEx ($mm)", Starlink!$A:$A, 0), I$5+1), 0))} -> 0 | J53: {=IF(J$4 >= INDEX(Assumptions!$B:$B, MATCH("V2 phase-out year (no V2 BB / V2 DTC launches from this year)", Assumptions!$A:$A, 0)), 0, IFERROR(INDEX(Starlink!$D:$AC, MATCH("V2 DTC sat CapEx ($mm)", Starlink!$A:$A, 0), J$5+1) + INDEX(Starlink!$D:$AC, MATCH("V2 DTC facility CapEx ($mm)", Starlink!$A:$A, 0), J$5+1), 0))} -> 0 | K53: {=IF(K$4 >= INDEX(Assumptions!$B:$B, MATCH("V2 phase-out year (no V2 BB / V2 DTC launches from this year)", Assumptions!$A:$A, 0)), 0, IFERROR(INDEX(Starlink!$D:$AC, MATCH("V2 DTC sat CapEx ($mm)", Starlink!$A:$A, 0), K$5+1) + INDEX(Starlink!$D:$AC, MATCH("V2 DTC facility CapEx ($mm)", Starlink!$A:$A, 0), K$5+1), 0))} -> 0 | ... AC53: {=IF(AC$4 >= INDEX(Assumptions!$B:$B, MATCH("V2 phase-out year (no V2 BB / V2 DTC launches from this year)", Assumptions!$A:$A, 0)), 0, IFERROR(INDEX(Starlink!$D:$AC, MATCH("V2 DTC sat CapEx ($mm)", Starlink!$A:$A, 0), AC$5+1) + INDEX(Starlink!$D:$AC, MATCH("V2 DTC facility CapEx ($mm)", Starlink!$A:$A, 0), AC$5+1), 0))} -> 0
A54: Starlink V2 DTC weight | D54: =MAX(D52, 0)^INDEX(Assumptions!$B:$B, MATCH("Sigmoid IRR-blend exponent k", Assumptions!$A:$A, 0)) * IF(D53 > 0, 1, 0) -> 0.019059393 | E54: =MAX(E52, 0)^INDEX(Assumptions!$B:$B, MATCH("Sigmoid IRR-blend exponent k", Assumptions!$A:$A, 0)) * IF(E53 > 0, 1, 0) -> 0 | F54: =MAX(F52, 0)^INDEX(Assumptions!$B:$B, MATCH("Sigmoid IRR-blend exponent k", Assumptions!$A:$A, 0)) * IF(F53 > 0, 1, 0) -> 0 | G54: =MAX(G52, 0)^INDEX(Assumptions!$B:$B, MATCH("Sigmoid IRR-blend exponent k", Assumptions!$A:$A, 0)) * IF(G53 > 0, 1, 0) -> 0 | H54: =MAX(H52, 0)^INDEX(Assumptions!$B:$B, MATCH("Sigmoid IRR-blend exponent k", Assumptions!$A:$A, 0)) * IF(H53 > 0, 1, 0) -> 0 | I54: =MAX(I52, 0)^INDEX(Assumptions!$B:$B, MATCH("Sigmoid IRR-blend exponent k", Assumptions!$A:$A, 0)) * IF(I53 > 0, 1, 0) -> 0 | J54: =MAX(J52, 0)^INDEX(Assumptions!$B:$B, MATCH("Sigmoid IRR-blend exponent k", Assumptions!$A:$A, 0)) * IF(J53 > 0, 1, 0) -> 0 | K54: =MAX(K52, 0)^INDEX(Assumptions!$B:$B, MATCH("Sigmoid IRR-blend exponent k", Assumptions!$A:$A, 0)) * IF(K53 > 0, 1, 0) -> 0 | ... AC54: =MAX(AC52, 0)^INDEX(Assumptions!$B:$B, MATCH("Sigmoid IRR-blend exponent k", Assumptions!$A:$A, 0)) * IF(AC53 > 0, 1, 0) -> 0
...

Sheet Launch Capacity
D4: 2025 | E4: 2026 | F4: 2027 | G4: 2028 | H4: 2029 | I4: 2030 | J4: 2031 | K4: 2032 | L4: 2033 | M4: 2034 | N4: 2035 | O4: 2036 | P4: 2037 | Q4: 2038 | R4: 2039 | S4: 2040 | T4: 2041 | U4: 2042 | V4: 2043 | W4: 2044 | X4: 2045 | Y4: 2046 | Z4: 2047 | AA4: 2048 | AB4: 2049 | AC4: 2050
D5: 0 | E5: 1 | F5: 2 | G5: 3 | H5: 4 | I5: 5 | J5: 6 | K5: 7 | L5: 8 | M5: 9 | N5: 10 | O5: 11 | P5: 12 | Q5: 13 | R5: 14 | S5: 15 | T5: 16 | U5: 17 | V5: 18 | W5: 19 | X5: 20 | Y5: 21 | Z5: 22 | AA5: 23 | AB5: 24 | AC5: 25
A6: STARSHIP — VEHICLE SUPPLY
A7: ▸ Physical + cost parameters (from Assumptions §3)
A8: Super Heavy manufacturing cost ($mm/unit) | D8: =INDEX(Assumptions!$B:$B, MATCH("Super Heavy manufacturing cost ($mm/unit, base year)", Assumptions!$A:$A, 0)) -> 54 | E8: =$D$8 -> 54 | F8: =$D$8 -> 54 | G8: =$D$8 -> 54 | H8: =$D$8 -> 54 | I8: =$D$8 -> 54 | J8: =$D$8 -> 54 | K8: =$D$8 -> 54 | L8: =$D$8 -> 54 | ... AC8: =$D$8 -> 54
A9: Starship 2nd-stage manufacturing cost ($mm/unit) | D9: =INDEX(Assumptions!$B:$B, MATCH("Starship 2nd-stage manufacturing cost ($mm/unit, base)", Assumptions!$A:$A, 0)) -> 36 | E9: =$D$9 -> 36 | F9: =$D$9 -> 36 | G9: =$D$9 -> 36 | H9: =$D$9 -> 36 | I9: =$D$9 -> 36 | J9: =$D$9 -> 36 | K9: =$D$9 -> 36 | L9: =$D$9 -> 36 | ... AC9: =$D$9 -> 36
A11: Payload — booster-only mode (kg-to-LEO) | D11: =INDEX(Assumptions!$B:$B, MATCH("Payload — booster-only mode (kg-to-LEO)", Assumptions!$A:$A, 0)) -> 150000
A12: Payload — fully reusable mode (kg-to-LEO) | D12: =INDEX(Assumptions!$B:$B, MATCH("Payload — fully reusable mode (kg-to-LEO)", Assumptions!$A:$A, 0)) -> 100000
A13: Lifetime reuses per ship (cap) | D13: =INDEX(Assumptions!$B:$B, MATCH("Lifetime reuses per ship (cap)", Assumptions!$A:$A, 0)) -> 30
A14: Manufacturing learning rate (per doubling of cum units) | D14: =INDEX(Assumptions!$B:$B, MATCH("Manufacturing learning rate (per doubling of cum units)", Assumptions!$A:$A, 0)) -> 0.1
A15: Cadence ceiling (flights/booster/year) | D15: =INDEX(Assumptions!$B:$B, MATCH("Cadence ceiling (flights/booster/year)", Assumptions!$A:$A, 0)) -> 60
A16: WL learning rate — turnaround vs cum upmass doubling | D16: =INDEX(Assumptions!$B:$B, MATCH("WL learning rate — turnaround vs cum upmass doubling", Assumptions!$A:$A, 0)) -> 0.145
A17: Anchor year for cum-upmass Wright's Law | D17: =INDEX(Assumptions!$B:$B, MATCH("Anchor year for cum-upmass Wright's Law", Assumptions!$A:$A, 0)) -> 2025
A19: ▸ Variant mix + booster lifetime reuses (year-rows from Assumptions §3)
A20: Variant mix (% fully reusable) | D20: {=INDEX(Assumptions!$D:$AC,MATCH("Variant mix (% fully reusable)",Assumptions!$A:$A,0),D$5+1)} -> 0 | E20: {=INDEX(Assumptions!$D:$AC,MATCH("Variant mix (% fully reusable)",Assumptions!$A:$A,0),E$5+1)} -> 0 | F20: {=INDEX(Assumptions!$D:$AC,MATCH("Variant mix (% fully reusable)",Assumptions!$A:$A,0),F$5+1)} -> 1 | G20: {=INDEX(Assumptions!$D:$AC,MATCH("Variant mix (% fully reusable)",Assumptions!$A:$A,0),G$5+1)} -> 1 | H20: {=INDEX(Assumptions!$D:$AC,MATCH("Variant mix (% fully reusable)",Assumptions!$A:$A,0),H$5+1)} -> 1 | I20: {=INDEX(Assumptions!$D:$AC,MATCH("Variant mix (% fully reusable)",Assumptions!$A:$A,0),I$5+1)} -> 1 | J20: {=INDEX(Assumptions!$D:$AC,MATCH("Variant mix (% fully reusable)",Assumptions!$A:$A,0),J$5+1)} -> 1 | K20: {=INDEX(Assumptions!$D:$AC,MATCH("Variant mix (% fully reusable)",Assumptions!$A:$A,0),K$5+1)} -> 1 | ... AC20: {=INDEX(Assumptions!$D:$AC,MATCH("Variant mix (% fully reusable)",Assumptions!$A:$A,0),AC$5+1)} -> 1
A21: Lifetime reuses per booster (year cap) | D21: {=INDEX(Assumptions!$D:$AC,MATCH("Lifetime reuses per booster (year cap)",Assumptions!$A:$A,0),D$5+1)} -> 5 | E21: {=INDEX(Assumptions!$D:$AC,MATCH("Lifetime reuses per booster (year cap)",Assumptions!$A:$A,0),E$5+1)} -> 8 | F21: {=INDEX(Assumptions!$D:$AC,MATCH("Lifetime reuses per booster (year cap)",Assumptions!$A:$A,0),F$5+1)} -> 12 | G21: {=INDEX(Assumptions!$D:$AC,MATCH("Lifetime reuses per booster (year cap)",Assumptions!$A:$A,0),G$5+1)} -> 18 | H21: {=INDEX(Assumptions!$D:$AC,MATCH("Lifetime reuses per booster (year cap)",Assumptions!$A:$A,0),H$5+1)} -> 25 | I21: {=INDEX(Assumptions!$D:$AC,MATCH("Lifetime reuses per booster (year cap)",Assumptions!$A:$A,0),I$5+1)} -> 30 | J21: {=INDEX(Assumptions!$D:$AC,MATCH("Lifetime reuses per booster (year cap)",Assumptions!$A:$A,0),J$5+1)} -> 35 | K21: {=INDEX(Assumptions!$D:$AC,MATCH("Lifetime reuses per booster (year cap)",Assumptions!$A:$A,0),K$5+1)} -> 42 | ... AC21: {=INDEX(Assumptions!$D:$AC,MATCH("Lifetime reuses per booster (year cap)",Assumptions!$A:$A,0),AC$5+1)} -> 100
A23: Launches per Starship vehicle per year (cadence) | D23: 1 | E23: =MAX(1,MIN($D$15,(1/INDEX(Assumptions!$B:$B,MATCH("Base turnaround time per booster (years/flight)",Assumptions!$A:$A,0)))*IFERROR((D28/$D$12)^(-LOG(1-$D$16,2)),1))) -> 1 | F23: =MAX(1,MIN($D$15,(1/INDEX(Assumptions!$B:$B,MATCH("Base turnaround time per booster (years/flight)",Assumptions!$A:$A,0)))*IFERROR((E28/$D$12)^(-LOG(1-$D$16,2)),1))) -> 1 | G23: =MAX(1,MIN($D$15,(1/INDEX(Assumptions!$B:$B,MATCH("Base turnaround time per booster (years/flight)",Assumptions!$A:$A,0)))*IFERROR((F28/$D$12)^(-LOG(1-$D$16,2)),1))) -> 1.0756595 | H23: =MAX(1,MIN($D$15,(1/INDEX(Assumptions!$B:$B,MATCH("Base turnaround time per booster (years/flight)",Assumptions!$A:$A,0)))*IFERROR((G28/$D$12)^(-LOG(1-$D$16,2)),1))) -> 1.349285 | I23: =MAX(1,MIN($D$15,(1/INDEX(Assumptions!$B:$B,MATCH("Base turnaround time per booster (years/flight)",Assumptions!$A:$A,0)))*IFERROR((H28/$D$12)^(-LOG(1-$D$16,2)),1))) -> 1.5866001 | J23: =MAX(1,MIN($D$15,(1/INDEX(Assumptions!$B:$B,MATCH("Base turnaround time per booster (years/flight)",Assumptions!$A:$A,0)))*IFERROR((I28/$D$12)^(-LOG(1-$D$16,2)),1))) -> 1.8462295 | K23: =MAX(1,MIN($D$15,(1/INDEX(Assumptions!$B:$B,MATCH("Base turnaround time per booster (years/flight)",Assumptions!$A:$A,0)))*IFERROR((J28/$D$12)^(-LOG(1-$D$16,2)),1))) -> 2.0898185 | L23: =MAX(1,MIN($D$15,(1/INDEX(Assumptions!$B:$B,MATCH("Base turnaround time per booster (years/flight)",Assumptions!$A:$A,0)))*IFERROR((K28/$D$12)^(-LOG(1-$D$16,2)),1))) -> 2.2934155 | ... AC23: =MAX(1,MIN($D$15,(1/INDEX(Assumptions!$B:$B,MATCH("Base turnaround time per booster (years/flight)",Assumptions!$A:$A,0)))*IFERROR((AB28/$D$12)^(-LOG(1-$D$16,2)),1))) -> 5.3151933
A24: Booster fleet beginning-of-year (units) | D24: 0 | E24: =D27 -> 0.001613704 | F24: =E27 -> 0.92271691 | G24: =F27 -> 2.3217287 | H24: =G27 -> 3.9222857 | I24: =H27 -> 4.9470428 | J24: =I27 -> 7.2472479 | K24: =J27 -> 8.5549546 | L24: =K27 -> 7.9459869 | ... AC24: =AB27 -> 17.73153
A25: Boosters built per year (units) | D25: {=IFERROR(INDEX(Allocator!$D:$AC, MATCH("Vehicle build claim ($mm)", Allocator!$A:$A, 0), D$5+1) / (D8 + D9), 0)} -> 0 | E25: {=IFERROR(INDEX(Allocator!$D:$AC, MATCH("Vehicle build claim ($mm)", Allocator!$A:$A, 0), E$5+1) / (E8 + E9), 0)} -> 0.93012223 | F25: {=IFERROR(INDEX(Allocator!$D:$AC, MATCH("Vehicle build claim ($mm)", Allocator!$A:$A, 0), F$5+1) / (F8 + F9), 0)} -> 1.4109562 | G25: {=IFERROR(INDEX(Allocator!$D:$AC, MATCH("Vehicle build claim ($mm)", Allocator!$A:$A, 0), G$5+1) / (G8 + G9), 0)} -> 1.4054275 | H25: {=IFERROR(INDEX(Allocator!$D:$AC, MATCH("Vehicle build claim ($mm)", Allocator!$A:$A, 0), H$5+1) / (H8 + H9), 0)} -> 1.6963785 | I25: {=IFERROR(INDEX(Allocator!$D:$AC, MATCH("Vehicle build claim ($mm)", Allocator!$A:$A, 0), I$5+1) / (I8 + I9), 0)} -> 1.0878853 | J25: {=IFERROR(INDEX(Allocator!$D:$AC, MATCH("Vehicle build claim ($mm)", Allocator!$A:$A, 0), J$5+1) / (J8 + J9), 0)} -> 2.0557771 | K25: {=IFERROR(INDEX(Allocator!$D:$AC, MATCH("Vehicle build claim ($mm)", Allocator!$A:$A, 0), K$5+1) / (K8 + K9), 0)} -> 1.6914837 | ... AC25: {=IFERROR(INDEX(Allocator!$D:$AC, MATCH("Vehicle build claim ($mm)", Allocator!$A:$A, 0), AC$5+1) / (AC8 + AC9), 0)} -> 0
A26: Boosters retired per year (units) | D26: 0
A27: Booster fleet end-of-year (units) | D27: =D24+D25-D26 -> 0 | E27: =E24+E25-E26 -> 0.93173594 | F27: =F24+F25-F26 -> 2.3336731 | G27: =G24+G25-G26 -> 3.7271562 | H27: =H24+H25-H26 -> 5.6186642 | I27: =I24+I25-I26 -> 6.0349281 | J27: =J24+J25-J26 -> 9.3030251 | K27: =K24+K25-K26 -> 10.246438 | ... AC27: =AC24+AC25-AC26 -> 17.73153
A28: Cum upmass to date (kg) | D28: 0 | E28: =D28+D33*D29 -> 242.05561 | F28: =E28+E33*E29 -> 138649.59 | G28: =F28+F33*F29 -> 370822.46 | H28: =G28+G33*G29 -> 793956.74 | I28: =H28+H33*H29 -> 1459006 | J28: =I28+I33*I29 -> 2614026.1 | K28: =J28+J33*J29 -> 4192881.9 | L28: =K28+K33*K29 -> 5837081.3 | ... AC28: =AB28+AB33*AB29 -> 1.8347635e+08
A29: Per-launch upmass (kg) | D29: =D20*$D$12+(1-D20)*$D$11 -> 150000 | E29: =E20*$D$12+(1-E20)*$D$11 -> 150000 | F29: =F20*$D$12+(1-F20)*$D$11 -> 100000 | G29: =G20*$D$12+(1-G20)*$D$11 -> 100000 | H29: =H20*$D$12+(1-H20)*$D$11 -> 100000 | I29: =I20*$D$12+(1-I20)*$D$11 -> 100000 | J29: =J20*$D$12+(1-J20)*$D$11 -> 100000 | K29: =K20*$D$12+(1-K20)*$D$11 -> 100000 | ... AC29: =AC20*$D$12+(1-AC20)*$D$11 -> 100000
A30: Cum Starship stacks manufactured (end-of-year, units) | D30: =INDEX(Assumptions!$B:$B, MATCH("Starship cost WL anchor cum units (= cum stacks at end-2024 baseline)", Assumptions!$A:$A, 0)) -> 4 | E30: =D30 + D25 -> 4 | F30: =E30 + E25 -> 4.9301222 | G30: =F30 + F25 -> 6.3410784 | H30: =G30 + G25 -> 7.746506 | I30: =H30 + H25 -> 9.4428845 | J30: =I30 + I25 -> 10.53077 | K30: =J30 + J25 -> 12.586547 | L30: =K30 + K25 -> 14.278031 | ... AC30: =AB30 + AB25 -> 41.971234
A31: Booster-only launches per year (count) | D31: =D27*D23*(1-D20) -> 0 | E31: =E27*E23*(1-E20) -> 0.93173594 | F31: =F27*F23*(1-F20) -> 0 | G31: =G27*G23*(1-G20) -> 0 | H31: =H27*H23*(1-H20) -> 0 | I31: =I27*I23*(1-I20) -> 0 | J31: =J27*J23*(1-J20) -> 0 | K31: =K27*K23*(1-K20) -> 0 | ... AC31: =AC27*AC23*(1-AC20) -> 0
A32: Fully-reusable launches per year (count) | D32: =D27*D23*D20 -> 0 | E32: =E27*E23*E20 -> 0 | F32: =F27*F23*F20 -> 2.3336731 | G32: =G27*G23*G20 -> 4.009151 | H32: =H27*H23*H20 -> 7.5811796 | I32: =I27*I23*I20 -> 9.5750178 | J32: =J27*J23*J20 -> 17.175519 | K32: =K27*K23*K20 -> 21.413196 | ... AC32: =AC27*AC23*AC20 -> 94.246512
A33: Total Starship launches per year | D33: =D31+D32 -> 0 | E33: =E31+E32 -> 0.93173594 | F33: =F31+F32 -> 2.3336731 | G33: =G31+G32 -> 4.009151 | H33: =H31+H32 -> 7.5811796 | I33: =I31+I32 -> 9.5750178 | J33: =J31+J32 -> 17.175519 | K33: =K31+K32 -> 21.413196 | ... AC33: =AC31+AC32 -> 94.246512
A34: Total Annual Capacity (kg-to-LEO) | D34: =D33*D29 -> 0 | E34: =E33*E29 -> 139760.39 | F34: =F33*F29 -> 233367.31 | G34: =G33*G29 -> 400915.1 | H34: =H33*H29 -> 758117.96 | I34: =I33*I29 -> 957501.78 | J34: =J33*J29 -> 1717551.9 | K34: =K33*K29 -> 2141319.6 | ... AC34: =AC33*AC29 -> 9424651.2
A36: ▸ Starship at-cost transfer rate (Architecture §7.1)
A37: Starship manufacturing cost ($mm/stack, this year) | D37: =INDEX(Assumptions!$B:$B, MATCH("Starship manufacturing cost anchor ($mm/stack, 2024 baseline)", Assumptions!$A:$A, 0)) * (D30 / INDEX(Assumptions!$B:$B, MATCH("Starship cost WL anchor cum units (= cum stacks at end-2024 baseline)", Assumptions!$A:$A, 0)))^(LOG(1 - INDEX(Assumptions!$B:$B, MATCH("Starship manufacturing WL learning rate (% reduction per doubling cum stacks)", Assumptions!$A:$A, 0)), 2)) -> 90 | E37: =INDEX(Assumptions!$B:$B, MATCH("Starship manufacturing cost anchor ($mm/stack, 2024 baseline)", Assumptions!$A:$A, 0)) * (E30 / INDEX(Assumptions!$B:$B, MATCH("Starship cost WL anchor cum units (= cum stacks at end-2024 baseline)", Assumptions!$A:$A, 0)))^(LOG(1 - INDEX(Assumptions!$B:$B, MATCH("Starship manufacturing WL learning rate (% reduction per doubling cum stacks)", Assumptions!$A:$A, 0)), 2)) -> 90 | F37: =INDEX(Assumptions!$B:$B, MATCH("Starship manufacturing cost anchor ($mm/stack, 2024 baseline)", Assumptions!$A:$A, 0)) * (F30 / INDEX(Assumptions!$B:$B, MATCH("Starship cost WL anchor cum units (= cum stacks at end-2024 baseline)", Assumptions!$A:$A, 0)))^(LOG(1 - INDEX(Assumptions!$B:$B, MATCH("Starship manufacturing WL learning rate (% reduction per doubling cum stacks)", Assumptions!$A:$A, 0)), 2)) -> 85.694629 | G37: =INDEX(Assumptions!$B:$B, MATCH("Starship manufacturing cost anchor ($mm/stack, 2024 baseline)", Assumptions!$A:$A, 0)) * (G30 / INDEX(Assumptions!$B:$B, MATCH("Starship cost WL anchor cum units (= cum stacks at end-2024 baseline)", Assumptions!$A:$A, 0)))^(LOG(1 - INDEX(Assumptions!$B:$B, MATCH("Starship manufacturing WL learning rate (% reduction per doubling cum stacks)", Assumptions!$A:$A, 0)), 2)) -> 80.783986 | H37: =INDEX(Assumptions!$B:$B, MATCH("Starship manufacturing cost anchor ($mm/stack, 2024 baseline)", Assumptions!$A:$A, 0)) * (H30 / INDEX(Assumptions!$B:$B, MATCH("Starship cost WL anchor cum units (= cum stacks at end-2024 baseline)", Assumptions!$A:$A, 0)))^(LOG(1 - INDEX(Assumptions!$B:$B, MATCH("Starship manufacturing WL learning rate (% reduction per doubling cum stacks)", Assumptions!$A:$A, 0)), 2)) -> 77.079738 | I37: =INDEX(Assumptions!$B:$B, MATCH("Starship manufacturing cost anchor ($mm/stack, 2024 baseline)", Assumptions!$A:$A, 0)) * (I30 / INDEX(Assumptions!$B:$B, MATCH("Starship cost WL anchor cum units (= cum stacks at end-2024 baseline)", Assumptions!$A:$A, 0)))^(LOG(1 - INDEX(Assumptions!$B:$B, MATCH("Starship manufacturing WL learning rate (% reduction per doubling cum stacks)", Assumptions!$A:$A, 0)), 2)) -> 73.582831 | J37: =INDEX(Assumptions!$B:$B, MATCH("Starship manufacturing cost anchor ($mm/stack, 2024 baseline)", Assumptions!$A:$A, 0)) * (J30 / INDEX(Assumptions!$B:$B, MATCH("Starship cost WL anchor cum units (= cum stacks at end-2024 baseline)", Assumptions!$A:$A, 0)))^(LOG(1 - INDEX(Assumptions!$B:$B, MATCH("Starship manufacturing WL learning rate (% reduction per doubling cum stacks)", Assumptions!$A:$A, 0)), 2)) -> 71.725451 | K37: =INDEX(Assumptions!$B:$B, MATCH("Starship manufacturing cost anchor ($mm/stack, 2024 baseline)", Assumptions!$A:$A, 0)) * (K30 / INDEX(Assumptions!$B:$B, MATCH("Starship cost WL anchor cum units (= cum stacks at end-2024 baseline)", Assumptions!$A:$A, 0)))^(LOG(1 - INDEX(Assumptions!$B:$B, MATCH("Starship manufacturing WL learning rate (% reduction per doubling cum stacks)", Assumptions!$A:$A, 0)), 2)) -> 68.788332 | ... AC37: =INDEX(Assumptions!$B:$B, MATCH("Starship manufacturing cost anchor ($mm/stack, 2024 baseline)", Assumptions!$A:$A, 0)) * (AC30 / INDEX(Assumptions!$B:$B, MATCH("Starship cost WL anchor cum units (= cum stacks at end-2024 baseline)", Assumptions!$A:$A, 0)))^(LOG(1 - INDEX(Assumptions!$B:$B, MATCH("Starship manufacturing WL learning rate (% reduction per doubling cum stacks)", Assumptions!$A:$A, 0)), 2)) -> 51.865536
A38: Starship ops + fuel + refurb cost per launch ($mm, this year) | D38: =INDEX(Assumptions!$B:$B, MATCH("Starship ops + fuel + refurb cost anchor ($mm/launch, 2024 baseline)", Assumptions!$A:$A, 0)) * (D30 / INDEX(Assumptions!$B:$B, MATCH("Starship cost WL anchor cum units (= cum stacks at end-2024 baseline)", Assumptions!$A:$A, 0)))^(LOG(1 - INDEX(Assumptions!$B:$B, MATCH("Starship ops + fuel + refurb WL learning rate (% reduction per doubling cum stacks)", Assumptions!$A:$A, 0)), 2)) -> 12 | E38: =INDEX(Assumptions!$B:$B, MATCH("Starship ops + fuel + refurb cost anchor ($mm/launch, 2024 baseline)", Assumptions!$A:$A, 0)) * (E30 / INDEX(Assumptions!$B:$B, MATCH("Starship cost WL anchor cum units (= cum stacks at end-2024 baseline)", Assumptions!$A:$A, 0)))^(LOG(1 - INDEX(Assumptions!$B:$B, MATCH("Starship ops + fuel + refurb WL learning rate (% reduction per doubling cum stacks)", Assumptions!$A:$A, 0)), 2)) -> 12 | F38: =INDEX(Assumptions!$B:$B, MATCH("Starship ops + fuel + refurb cost anchor ($mm/launch, 2024 baseline)", Assumptions!$A:$A, 0)) * (F30 / INDEX(Assumptions!$B:$B, MATCH("Starship cost WL anchor cum units (= cum stacks at end-2024 baseline)", Assumptions!$A:$A, 0)))^(LOG(1 - INDEX(Assumptions!$B:$B, MATCH("Starship ops + fuel + refurb WL learning rate (% reduction per doubling cum stacks)", Assumptions!$A:$A, 0)), 2)) -> 11.624645 | G38: =INDEX(Assumptions!$B:$B, MATCH("Starship ops + fuel + refurb cost anchor ($mm/launch, 2024 baseline)", Assumptions!$A:$A, 0)) * (G30 / INDEX(Assumptions!$B:$B, MATCH("Starship cost WL anchor cum units (= cum stacks at end-2024 baseline)", Assumptions!$A:$A, 0)))^(LOG(1 - INDEX(Assumptions!$B:$B, MATCH("Starship ops + fuel + refurb WL learning rate (% reduction per doubling cum stacks)", Assumptions!$A:$A, 0)), 2)) -> 11.188322 | H38: =INDEX(Assumptions!$B:$B, MATCH("Starship ops + fuel + refurb cost anchor ($mm/launch, 2024 baseline)", Assumptions!$A:$A, 0)) * (H30 / INDEX(Assumptions!$B:$B, MATCH("Starship cost WL anchor cum units (= cum stacks at end-2024 baseline)", Assumptions!$A:$A, 0)))^(LOG(1 - INDEX(Assumptions!$B:$B, MATCH("Starship ops + fuel + refurb WL learning rate (% reduction per doubling cum stacks)", Assumptions!$A:$A, 0)), 2)) -> 10.85299 | I38: =INDEX(Assumptions!$B:$B, MATCH("Starship ops + fuel + refurb cost anchor ($mm/launch, 2024 baseline)", Assumptions!$A:$A, 0)) * (I30 / INDEX(Assumptions!$B:$B, MATCH("Starship cost WL anchor cum units (= cum stacks at end-2024 baseline)", Assumptions!$A:$A, 0)))^(LOG(1 - INDEX(Assumptions!$B:$B, MATCH("Starship ops + fuel + refurb WL learning rate (% reduction per doubling cum stacks)", Assumptions!$A:$A, 0)), 2)) -> 10.531186 | J38: =INDEX(Assumptions!$B:$B, MATCH("Starship ops + fuel + refurb cost anchor ($mm/launch, 2024 baseline)", Assumptions!$A:$A, 0)) * (J30 / INDEX(Assumptions!$B:$B, MATCH("Starship cost WL anchor cum units (= cum stacks at end-2024 baseline)", Assumptions!$A:$A, 0)))^(LOG(1 - INDEX(Assumptions!$B:$B, MATCH("Starship ops + fuel + refurb WL learning rate (% reduction per doubling cum stacks)", Assumptions!$A:$A, 0)), 2)) -> 10.358077 | K38: =INDEX(Assumptions!$B:$B, MATCH("Starship ops + fuel + refurb cost anchor ($mm/launch, 2024 baseline)", Assumptions!$A:$A, 0)) * (K30 / INDEX(Assumptions!$B:$B, MATCH("Starship cost WL anchor cum units (= cum stacks at end-2024 baseline)", Assumptions!$A:$A, 0)))^(LOG(1 - INDEX(Assumptions!$B:$B, MATCH("Starship ops + fuel + refurb WL learning rate (% reduction per doubling cum stacks)", Assumptions!$A:$A, 0)), 2)) -> 10.081079 | ... AC38: =INDEX(Assumptions!$B:$B, MATCH("Starship ops + fuel + refurb cost anchor ($mm/launch, 2024 baseline)", Assumptions!$A:$A, 0)) * (AC30 / INDEX(Assumptions!$B:$B, MATCH("Starship cost WL anchor cum units (= cum stacks at end-2024 baseline)", Assumptions!$A:$A, 0)))^(LOG(1 - INDEX(Assumptions!$B:$B, MATCH("Starship ops + fuel + refurb WL learning rate (% reduction per doubling cum stacks)", Assumptions!$A:$A, 0)), 2)) -> 8.394649
